Workbook

Sheet DATA PER 111225
A1: 6 | B1: NAMA PRODUK | C1: JENIS | D1: SATUAN CSA | E1: JUMLAH | F1: ALASAN WASTE | G1: USER
A2: B004 | B2: POWDER CHOCOLATE 1KG | C2: BAHAN BAKU LUUCA | D2: GR
A3: B004 | B3: POWDER YOGHURT | C3: BAHAN BAKU LUUCA | D3: GR
A4: B004 | B4: POWDER ICE CREAM YOGHURT | C4: BAHAN BAKU LUUCA | D4: GR
A5: B004 | B5: POWDER ICE CREAM CHOCOLATE | C5: BAHAN BAKU LUUCA | D5: GR
A6: B004 | B6: FRISIAN FLAG UHT FULL CREAM 946ML | C6: BAHAN BAKU LUUCA | D6: ML
A7: B004 | B7: SIMPLE SYRUP 3KG | C7: BAHAN BAKU LUUCA | D7: GR
A8: B004 | B8: GRANOLA | C8: BAHAN BAKU LUUCA | D8: GR
A9: B004 | B9: PEANUT 1 kg | C9: BAHAN BAKU LUUCA | D9: GR
A10: B004 | B10: PEPERO ALMOND 32GR | C10: BAHAN BAKU LUUCA | D10: GR
A11: B004 | B11: CARAMEL CHIP CALLEBAUT GOLD 2.5KG | C11: BAHAN BAKU LUUCA | D11: GR
A12: B004 | B12: CHOCO DIP SAUCE BELLA 1KG | C12: BAHAN BAKU LUUCA | D12: GR
A13: B004 | B13: BUAH LONGAN 565GR | C13: BAHAN BAKU LUUCA | D13: GR
... A120: P006 | B120: WIP CHOCOLATE BASE | C120: PRODUKSI STOK LUUCA | D120: GR

Sheet MASTER DATA
A1: Nama Item | B1: Kode Item | C1: Kelompok | D1: Sat | E1: JENIS
A2: GREENFIELD FRESH MILK (SALAH) | B2: B001-110 | C2: B004 | D2: GR | E2: =IFERROR(VLOOKUP(A2,'DATA PER 111225'!$A$2:$C$120,3),"") -> BAHAN BAKU LUUCA
A3: POWDER CHOCOLATE 1KG | B3: BB-100001 | C3: B004 | D3: GR | E3: =IFERROR(VLOOKUP(A3,'DATA PER 111225'!$A$2:$C$120,3),"") -> PRODUKSI STOK LUUCA
A4: POWDER YOGHURT | B4: BB-100002 | C4: B004 | D4: GR | E4: =IFERROR(VLOOKUP(A4,'DATA PER 111225'!$A$2:$C$120,3),"") -> PRODUKSI STOK LUUCA
A5: POWDER ICE CREAM YOGHURT | B5: BB-100003 | C5: B004 | D5: GR | E5: =IFERROR(VLOOKUP(A5,'DATA PER 111225'!$A$2:$C$120,3),"") -> PRODUKSI STOK LUUCA
A6: POWDER ICE CREAM CHOCOLATE | B6: BB-100004 | C6: B004 | D6: GR | E6: =IFERROR(VLOOKUP(A6,'DATA PER 111225'!$A$2:$C$120,3),"") -> PRODUKSI STOK LUUCA
A7: FRISIAN FLAG UHT FULL CREAM 946ML | B7: BB-100006 | C7: B004 | D7: ML | E7: =IFERROR(VLOOKUP(A7,'DATA PER 111225'!$A$2:$C$120,3),"") -> BAHAN BAKU LUUCA
A8: SIMPLE SYRUP 3KG | B8: BB-100007 | C8: B004 | D8: GR | E8: =IFERROR(VLOOKUP(A8,'DATA PER 111225'!$A$2:$C$120,3),"") -> PRODUKSI STOK LUUCA
A9: GRANOLA Luuca | B9: BB-100012 | C9: B004 | D9: GR | E9: =IFERROR(VLOOKUP(A9,'DATA PER 111225'!$A$2:$C$120,3),"") -> BAHAN BAKU LUUCA
A10: PEANUT 1 kg | B10: BB-100013 | C10: B004 | D10: GR | E10: =IFERROR(VLOOKUP(A10,'DATA PER 111225'!$A$2:$C$120,3),"") -> PRODUKSI STOK LUUCA
A11: PEPERO ALMOND SALAH | B11: BB-100014 | C11: B004 | D11: GR | E11: =IFERROR(VLOOKUP(A11,'DATA PER 111225'!$A$2:$C$120,3),"") -> PRODUKSI STOK LUUCA
A12: CARAMEL CHIP CALLEBAUT GOLD 2.5KG | B12: BB-100020 | C12: B004 | D12: GR | E12: =IFERROR(VLOOKUP(A12,'DATA PER 111225'!$A$2:$C$120,3),"") -> BAHAN BAKU LUUCA
A13: CHOCO DIP SAUCE BELLA 1KG | B13: BB-100021 | C13: B004 | D13: GR | E13: =IFERROR(VLOOKUP(A13,'DATA PER 111225'!$A$2:$C$120,3),"") -> BAHAN BAKU LUUCA
... A57: ES BATU | B57: BB-100504 | C57: B004 | D57: GR | E57: =IFERROR(VLOOKUP(A57,'DATA PER 111225'!$A$2:$C$120,3),"") -> BAHAN BAKU LUUCA
A58: Air Mineral Luuca | B58: BB-100505 | C58: B004 | D58: PCS | E58: BAHAN BAKU LUUCA
A59: KACANG PISTACHIO 500GR | B59: BB-100506 | C59: B004 | D59: GR | E59: =IFERROR(VLOOKUP(A59,'DATA PER 111225'!$A$2:$C$120,3),"") -> BAHAN BAKU LUUCA
A60: PEPERO ALMOND | B60: BB-100507 | C60: B004 | D60: PCS | E60: =IFERROR(VLOOKUP(A60,'DATA PER 111225'!$A$2:$C$120,3),"") -> PRODUKSI STOK LUUCA
A61: POETRI BALI KACANG MEDAN | B61: BB-100508 | C61: B004 | D61: PCS | E61: =IFERROR(VLOOKUP(A61,'DATA PER 111225'!$A$2:$C$120,3),"") -> PRODUKSI STOK LUUCA
A62: POETRI BALI KACANG KAPRI SPICY | B62: BB-100509 | C62: B004 | D62: PCS | E62: =IFERROR(VLOOKUP(A62,'DATA PER 111225'!$A$2:$C$120,3),"") -> PRODUKSI STOK LUUCA
A63: POETRI BALI KACANG KAPRI | B63: BB-100510 | C63: B004 | D63: PCS | E63: =IFERROR(VLOOKUP(A63,'DATA PER 111225'!$A$2:$C$120,3),"") -> PRODUKSI STOK LUUCA
A64: POETRI BALI CASHEW ORI | B64: BB-100511 | C64: B004 | D64: PCS | E64: =IFERROR(VLOOKUP(A64,'DATA PER 111225'!$A$2:$C$120,3),"") -> PRODUKSI STOK LUUCA
A65: POETRI BALI CASHEW CRISPY | B65: BB-100512 | C65: B004 | D65: PCS | E65: =IFERROR(VLOOKUP(A65,'DATA PER 111225'!$A$2:$C$120,3),"") -> PRODUKSI STOK LUUCA
A66: POETRI BALI KACANG MANIS | B66: BB-100513 | C66: B004 | D66: PCS | E66: =IFERROR(VLOOKUP(A66,'DATA PER 111225'!$A$2:$C$120,3),"") -> PRODUKSI STOK LUUCA
A67: POETRI BALI KACANG BALI ASIN | B67: BB-100514 | C67: B004 | D67: PCS | E67: =IFERROR(VLOOKUP(A67,'DATA PER 111225'!$A$2:$C$120,3),"") -> PRODUKSI STOK LUUCA
A68: Pocky Strawberry | B68: BB-100515 | C68: B004 | D68: PCS | E68: =IFERROR(VLOOKUP(A68,'DATA PER 111225'!$A$2:$C$120,3),"") -> PRODUKSI STOK LUUCA
A69: TELUR LUUCA | B69: BB-100517 | C69: B004 | D69: PCS | E69: =IFERROR(VLOOKUP(A69,'DATA PER 111225'!$A$2:$C$120,3),"") -> PRODUKSI STOK LUUCA
A70: WHIPPING CREAM LUUCA | B70: BB-100518 | C70: B004 | D70: GR | E70: =IFERROR(VLOOKUP(A70,'DATA PER 111225'!$A$2:$C$120,3),"") -> PRODUKSI STOK LUUCA
... A79: GREENFIELD | B79: BB-100527 | C79: B004 | D79: ML | E79: =IFERROR(VLOOKUP(A79,'DATA PER 111225'!$A$2:$C$120,3),"") -> BAHAN BAKU LUUCA
E80: =IFERROR(VLOOKUP(A80,'DATA PER 111225'!$A$2:$C$120,3),"")
A81: Cup Luuca Salah | B81: L001 | C81: L001 | D81: PCS | E81: =IFERROR(VLOOKUP(A81,'DATA PER 111225'!$A$2:$C$120,3),"") -> BAHAN BAKU LUUCA
A82: Romeo Chocolate | B82: L001-001 | C82: L001 | D82: PRS | E82: =IFERROR(VLOOKUP(A82,'DATA PER 111225'!$A$2:$C$120,3),"") -> PRODUKSI STOK LUUCA
A83: Pisa Chocolate | B83: L001-002 | C83: L001 | D83: PRS | E83: =IFERROR(VLOOKUP(A83,'DATA PER 111225'!$A$2:$C$120,3),"") -> PRODUKSI STOK LUUCA
A84: Verona Chocolate | B84: L001-003 | C84: L001 | D84: PRS | E84: =IFERROR(VLOOKUP(A84,'DATA PER 111225'!$A$2:$C$120,3),"") -> PRODUKSI STOK LUUCA
A85: Ferrara Chocolate | B85: L001-004 | C85: L001 | D85: PRS | E85: =IFERROR(VLOOKUP(A85,'DATA PER 111225'!$A$2:$C$120,3),"") -> BAHAN BAKU LUUCA
A86: Venesia Chocolate | B86: L001-005 | C86: L001 | D86: PRS | E86: =IFERROR(VLOOKUP(A86,'DATA PER 111225'!$A$2:$C$120,3),"") -> PRODUKSI STOK LUUCA
A87: Sienna Chocolate | B87: L001-006 | C87: L001 | D87: PRS | E87: =IFERROR(VLOOKUP(A87,'DATA PER 111225'!$A$2:$C$120,3),"") -> PRODUKSI STOK LUUCA
A88: Juliet Yogurt | B88: L001-007 | C88: L001 | D88: PRS | E88: =IFERROR(VLOOKUP(A88,'DATA PER 111225'!$A$2:$C$120,3),"") -> BAHAN BAKU LUUCA
A89: Napoli Yogurt | B89: L001-008 | C89: L001 | D89: PRS | E89: =IFERROR(VLOOKUP(A89,'DATA PER 111225'!$A$2:$C$120,3),"") -> BAHAN BAKU LUUCA
A90: Milan Yoghurt | B90: L001-009 | C90: L001 | D90: PRS | E90: =IFERROR(VLOOKUP(A90,'DATA PER 111225'!$A$2:$C$120,3),"") -> BAHAN BAKU LUUCA
A91: Padova Yogurt | B91: L001-010 | C91: L001 | D91: PRS | E91: =IFERROR(VLOOKUP(A91,'DATA PER 111225'!$A$2:$C$120,3),"") -> PRODUKSI STOK LUUCA
...

Sheet DASHBOARD
A1: FORM ADJUSTMENT
A2: PT. KREASI LIMA CAHAYA
A3: LUUCA CILEDUG
A4: BULAN, TAHUN:
A6: TANGGAL | B6: NAMA PRODUK | C6: KODE CSA | D6: JENIS | E6: JUMLAH | F6: SATUAN CSA | G6: ALASAN WASTE | H6: USER | I6: KATEGORI | J6: AUDIT
B7: BUAH KIWI | C7: =IFERROR(VLOOKUP(B7,'MASTER DATA'!$A$1:$E$212,2,FALSE),"") -> BB-100502 | D7: =IFERROR(VLOOKUP(B7,'MASTER DATA'!$A$1:$E$212,5,FALSE),"") -> BAHAN BAKU LUUCA | F7: =IFERROR(VLOOKUP(B7,'MASTER DATA'!$A$1:$E$212,4,FALSE),"") -> GR | J7: FALSE
D8: =IFERROR(VLOOKUP(B8,'MASTER DATA'!$A$1:$E$212,5,FALSE),"") | F8: =IFERROR(VLOOKUP(B8,'MASTER DATA'!$A$1:$E$212,4,FALSE),"") | J8: FALSE
C9: =IFERROR(VLOOKUP(B9,'MASTER DATA'!$A$1:$E$212,2,FALSE),"") | D9: =IFERROR(VLOOKUP(B9,'MASTER DATA'!$A$1:$E$212,5,FALSE),"") | F9: =IFERROR(VLOOKUP(B9,'MASTER DATA'!$A$1:$E$212,4,FALSE),"") | J9: FALSE
C10: =IFERROR(VLOOKUP(B10,'MASTER DATA'!$A$1:$E$212,2,FALSE),"") | D10: =IFERROR(VLOOKUP(B10,'MASTER DATA'!$A$1:$E$212,5,FALSE),"") | F10: =IFERROR(VLOOKUP(B10,'MASTER DATA'!$A$1:$E$212,4,FALSE),"") | J10: FALSE
C11: =IFERROR(VLOOKUP(B11,'MASTER DATA'!$A$1:$E$212,2,FALSE),"") | D11: =IFERROR(VLOOKUP(B11,'MASTER DATA'!$A$1:$E$212,5,FALSE),"") | F11: =IFERROR(VLOOKUP(B11,'MASTER DATA'!$A$1:$E$212,4,FALSE),"") | J11: FALSE
C12: =IFERROR(VLOOKUP(B12,'MASTER DATA'!$A$1:$E$212,2,FALSE),"") | D12: =IFERROR(VLOOKUP(B12,'MASTER DATA'!$A$1:$E$212,5,FALSE),"") | F12: =IFERROR(VLOOKUP(B12,'MASTER DATA'!$A$1:$E$212,4,FALSE),"") | J12: FALSE
C13: =IFERROR(VLOOKUP(B13,'MASTER DATA'!$A$1:$E$212,2,FALSE),"") | D13: =IFERROR(VLOOKUP(B13,'MASTER DATA'!$A$1:$E$212,5,FALSE),"") | F13: =IFERROR(VLOOKUP(B13,'MASTER DATA'!$A$1:$E$212,4,FALSE),"") | J13: FALSE
C14: =IFERROR(VLOOKUP(B14,'MASTER DATA'!$A$1:$E$212,2,FALSE),"") | D14: =IFERROR(VLOOKUP(B14,'MASTER DATA'!$A$1:$E$212,5,FALSE),"") | F14: =IFERROR(VLOOKUP(B14,'MASTER DATA'!$A$1:$E$212,4,FALSE),"") | J14: FALSE
C15: =IFERROR(VLOOKUP(B15,'MASTER DATA'!$A$1:$E$212,2,FALSE),"") | D15: =IFERROR(VLOOKUP(B15,'MASTER DATA'!$A$1:$E$212,5,FALSE),"") | F15: =IFERROR(VLOOKUP(B15,'MASTER DATA'!$A$1:$E$212,4,FALSE),"") | J15: FALSE
C16: =IFERROR(VLOOKUP(B16,'MASTER DATA'!$A$1:$E$212,2,FALSE),"") | D16: =IFERROR(VLOOKUP(B16,'MASTER DATA'!$A$1:$E$212,5,FALSE),"") | F16: =IFERROR(VLOOKUP(B16,'MASTER DATA'!$A$1:$E$212,4,FALSE),"") | J16: FALSE
C17: =IFERROR(VLOOKUP(B17,'MASTER DATA'!$A$1:$E$212,2,FALSE),"") | D17: =IFERROR(VLOOKUP(B17,'MASTER DATA'!$A$1:$E$212,5,FALSE),"") | F17: =IFERROR(VLOOKUP(B17,'MASTER DATA'!$A$1:$E$212,4,FALSE),"") | J17: FALSE
C18: =IFERROR(VLOOKUP(B18,'MASTER DATA'!$A$1:$E$212,2,FALSE),"") | D18: =IFERROR(VLOOKUP(B18,'MASTER DATA'!$A$1:$E$212,5,FALSE),"") | F18: =IFERROR(VLOOKUP(B18,'MASTER DATA'!$A$1:$E$212,4,FALSE),"") | J18: FALSE
C19: =IFERROR(VLOOKUP(B19,'MASTER DATA'!$A$1:$E$212,2,FALSE),"") | D19: =IFERROR(VLOOKUP(B19,'MASTER DATA'!$A$1:$E$212,5,FALSE),"") | F19: =IFERROR(VLOOKUP(B19,'MASTER DATA'!$A$1:$E$212,4,FALSE),"") | J19: FALSE
C20: =IFERROR(VLOOKUP(B20,'MASTER DATA'!$A$1:$E$212,2,FALSE),"") | D20: =IFERROR(VLOOKUP(B20,'MASTER DATA'!$A$1:$E$212,5,FALSE),"") | F20: =IFERROR(VLOOKUP(B20,'MASTER DATA'!$A$1:$E$212,4,FALSE),"") | J20: FALSE
... C1000: =IFERROR(VLOOKUP(B1000,'MASTER DATA'!$A$1:$E$212,2,FALSE),"") | D1000: =IFERROR(VLOOKUP(B1000,'MASTER DATA'!$A$1:$E$212,5,FALSE),"") | F1000: =IFERROR(VLOOKUP(B1000,'MASTER DATA'!$A$1:$E$212,4,FALSE),"") | J1000: FALSE

Sheet Sheet3
A1: TANGGAL | B1: NAMA PRODUK | C1: KODE CSA | D1: JENIS | E1: SATUAN CSA | F1: JUMLAH | G1: ALASAN WASTE | H1: USER
B2: POWDER CHOCOLATE 1KG | C2: B004 | D2: BAHAN BAKU LUUCA | E2: GR
B3: POWDER YOGHURT | C3: B004 | D3: BAHAN BAKU LUUCA | E3: GR
B4: POWDER ICE CREAM YOGHURT | C4: B004 | D4: BAHAN BAKU LUUCA | E4: GR
B5: POWDER ICE CREAM CHOCOLATE | C5: B004 | D5: BAHAN BAKU LUUCA | E5: GR
B6: FRISIAN FLAG UHT FULL CREAM 946ML | C6: B004 | D6: BAHAN BAKU LUUCA | E6: ML
B7: SIMPLE SYRUP 3KG | C7: B004 | D7: BAHAN BAKU LUUCA | E7: GR
B8: GRANOLA | C8: B004 | D8: BAHAN BAKU LUUCA | E8: GR
B9: PEANUT 1 kg | C9: B004 | D9: BAHAN BAKU LUUCA | E9: GR
B10: PEPERO ALMOND 32GR | C10: B004 | D10: BAHAN BAKU LUUCA | E10: GR
B11: CARAMEL CHIP CALLEBAUT GOLD 2.5KG | C11: B004 | D11: BAHAN BAKU LUUCA | E11: GR
B12: CHOCO DIP SAUCE BELLA 1KG | C12: B004 | D12: BAHAN BAKU LUUCA | E12: GR
B13: BUAH LONGAN 565GR | C13: B004 | D13: BAHAN BAKU LUUCA | E13: GR
... B120: WIP CHOCOLATE BASE | C120: P006 | D120: PRODUKSI STOK LUUCA | E120: GR

Sheet ADJUSTMENT DESEMBER JC CILEDUG
A1: TANGGAL | B1: NAMA PRODUK | C1: KODE CSA | D1: JENIS | E1: SATUAN CSA | F1: JUMLAH | G1: ALASAN WASTE | H1: USER
A2: 45994 | B2: WIP BLENDED MILKY | C2: =VLOOKUP(B2,Sheet3!$B$2:$E$311,2,FALSE) -> #N/A | D2: =VLOOKUP(B2,Sheet3!$B$2:$E$311,3,) -> #N/A | E2: =VLOOKUP(B2,Sheet3!$B$2:$E$311,4,) -> #N/A | F2: 419 | G2: Training | H2: Fadli
A3: 45994 | B3: WIP MILK FOAM | C3: =VLOOKUP(B3,Sheet3!$B$2:$E$311,2,FALSE) -> #N/A | D3: =VLOOKUP(B3,Sheet3!$B$2:$E$311,3,) -> #N/A | E3: =VLOOKUP(B3,Sheet3!$B$2:$E$311,4,) -> #N/A | F3: 321 | G3: Training | H3: Fadli
A4: 45992 | B4: SIZZLING FRIED CHICKEN STEAK | C4: =VLOOKUP(B4,Sheet3!$B$2:$E$311,2,FALSE) -> #N/A | D4: =VLOOKUP(B4,Sheet3!$B$2:$E$311,3,) -> #N/A | E4: =VLOOKUP(B4,Sheet3!$B$2:$E$311,4,) -> #N/A | F4: 1 | G4: Training | H4: Fadli
A5: 45992 | B5: BEEF SAUSAGE PIZZA | C5: =VLOOKUP(B5,Sheet3!$B$2:$E$311,2,FALSE) -> #N/A | D5: =VLOOKUP(B5,Sheet3!$B$2:$E$311,3,) -> #N/A | E5: =VLOOKUP(B5,Sheet3!$B$2:$E$311,4,) -> #N/A | F5: 1 | G5: Training | H5: Fadli
A6: 45994 | B6: WIP NASI PUTIH | C6: =VLOOKUP(B6,Sheet3!$B$2:$E$311,2,FALSE) -> #N/A | D6: =VLOOKUP(B6,Sheet3!$B$2:$E$311,3,) -> #N/A | E6: =VLOOKUP(B6,Sheet3!$B$2:$E$311,4,) -> #N/A | F6: 1 | G6: Kering | H6: Dendi
A7: 45994 | B7: WIP NASI PUTIH | C7: =VLOOKUP(B7,Sheet3!$B$2:$E$311,2,FALSE) -> #N/A | D7: =VLOOKUP(B7,Sheet3!$B$2:$E$311,3,) -> #N/A | E7: =VLOOKUP(B7,Sheet3!$B$2:$E$311,4,) -> #N/A | F7: 19 | G7: Discard | H7: Dendi
A8: 45994 | B8: ORIGINAL TURBO CHICKEN | C8: =VLOOKUP(B8,Sheet3!$B$2:$E$311,2,FALSE) -> #N/A | D8: =VLOOKUP(B8,Sheet3!$B$2:$E$311,3,) -> #N/A | E8: =VLOOKUP(B8,Sheet3!$B$2:$E$311,4,) -> #N/A | F8: 2 | G8: Training | H8: Iqbal
A9: 45994 | B9: Paprika Hijau | C9: =VLOOKUP(B9,Sheet3!$B$2:$E$311,2,FALSE) -> #N/A | D9: =VLOOKUP(B9,Sheet3!$B$2:$E$311,3,) -> #N/A | E9: =VLOOKUP(B9,Sheet3!$B$2:$E$311,4,) -> #N/A | F9: 12 | G9: Discard | H9: Tegar
A10: 45994 | B10: Paprika Merah | C10: =VLOOKUP(B10,Sheet3!$B$2:$E$311,2,FALSE) -> #N/A | D10: =VLOOKUP(B10,Sheet3!$B$2:$E$311,3,) -> #N/A | E10: =VLOOKUP(B10,Sheet3!$B$2:$E$311,4,) -> #N/A | F10: 12 | G10: Discard | H10: Tegar
A11: 45994 | B11: WIP NASI PUTIH | C11: =VLOOKUP(B11,Sheet3!$B$2:$E$311,2,FALSE) -> #N/A | D11: =VLOOKUP(B11,Sheet3!$B$2:$E$311,3,) -> #N/A | E11: =VLOOKUP(B11,Sheet3!$B$2:$E$311,4,) -> #N/A | F11: 55 | G11: Discard | H11: Tegar
A12: 45994 | B12: WIP UNSWEERENED TEA BASE | C12: =VLOOKUP(B12,Sheet3!$B$2:$E$311,2,FALSE) -> #N/A | D12: =VLOOKUP(B12,Sheet3!$B$2:$E$311,3,) -> #N/A | E12: =VLOOKUP(B12,Sheet3!$B$2:$E$311,4,) -> #N/A | F12: 3500 | G12: Discard | H12: Fadli
A13: 45994 | B13: WIP RED TEA BASE | C13: =VLOOKUP(B13,Sheet3!$B$2:$E$311,2,FALSE) -> #N/A | D13: =VLOOKUP(B13,Sheet3!$B$2:$E$311,3,) -> #N/A | E13: =VLOOKUP(B13,Sheet3!$B$2:$E$311,4,) -> #N/A | F13: 1100 | G13: Discard | H13: Fadli
... A133: 46009 | B133: ORLEAN MEAT | C133: =VLOOKUP(B133,Sheet3!$B$2:$E$311,2,FALSE) -> #N/A | D133: =VLOOKUP(B133,Sheet3!$B$2:$E$311,3,) -> #N/A | E133: =VLOOKUP(B133,Sheet3!$B$2:$E$311,4,) -> #N/A | F133: 157 | G133: Discard | H133: Tegar
A134: 46009 | B134: Topping ayam sambal bali | C134: =VLOOKUP(B134,Sheet3!$B$2:$E$311,2,FALSE) -> #N/A | D134: =VLOOKUP(B134,Sheet3!$B$2:$E$311,3,) -> #N/A | E134: Gr | F134: 495 | G134: Discard | H134: Tegar
A135: 46009 | B135: WIP NASI PUTIH | C135: =VLOOKUP(B135,Sheet3!$B$2:$E$311,2,FALSE) -> #N/A | D135: =VLOOKUP(B135,Sheet3!$B$2:$E$311,3,) -> #N/A | E135: =VLOOKUP(B135,Sheet3!$B$2:$E$311,4,) -> #N/A | F135: 4 | G135: Discard | H135: Karin
A136: 46009 | B136: AMERICAN FRIES | C136: =VLOOKUP(B136,Sheet3!$B$2:$E$311,2,FALSE) -> #N/A | D136: =VLOOKUP(B136,Sheet3!$B$2:$E$311,3,) -> #N/A | E136: =VLOOKUP(B136,Sheet3!$B$2:$E$311,4,) -> #N/A | F136: 1 | G136: Discard | H136: Karin
A137: 46010 | B137: Sosis Sapi | C137: =VLOOKUP(B137,Sheet3!$B$2:$E$311,2,FALSE) -> #N/A | D137: =VLOOKUP(B137,Sheet3!$B$2:$E$311,3,) -> #N/A | E137: =VLOOKUP(B137,Sheet3!$B$2:$E$311,4,) -> #N/A | F137: 76 | G137: Discard | H137: Rosidin
A138: 46010 | B138: Telur | C138: =VLOOKUP(B138,Sheet3!$B$2:$E$311,2,FALSE) -> #N/A | D138: =VLOOKUP(B138,Sheet3!$B$2:$E$311,3,) -> #N/A | E138: =VLOOKUP(B138,Sheet3!$B$2:$E$311,4,) -> #N/A | F138: 1 | G138: pecah | H138: Rosidin
A139: 46010 | B139: Topping ayam sambal bali | C139: =VLOOKUP(B139,Sheet3!$B$2:$E$311,2,FALSE) -> #N/A | D139: =VLOOKUP(B139,Sheet3!$B$2:$E$311,3,) -> #N/A | E139: Gr | F139: 88 | G139: Discard | H139: Rosidin
A140: 46010 | B140: Telur | C140: =VLOOKUP(B140,Sheet3!$B$2:$E$311,2,FALSE) -> #N/A | D140: =VLOOKUP(B140,Sheet3!$B$2:$E$311,3,) -> #N/A | E140: =VLOOKUP(B140,Sheet3!$B$2:$E$311,4,) -> #N/A | F140: 1 | G140: Discard | H140: Karin
A141: 46010 | B141: WIP TELUR KOCOK | C141: =VLOOKUP(B141,Sheet3!$B$2:$E$311,2,FALSE) -> #N/A | D141: =VLOOKUP(B141,Sheet3!$B$2:$E$311,3,) -> #N/A | E141: =VLOOKUP(B141,Sheet3!$B$2:$E$311,4,) -> #N/A | F141: 186 | G141: Discard | H141: Karin
A142: 46010 | B142: WIP UNSWEERENED TEA BASE | C142: =VLOOKUP(B142,Sheet3!$B$2:$E$311,2,FALSE) -> #N/A | D142: =VLOOKUP(B142,Sheet3!$B$2:$E$311,3,) -> #N/A | E142: =VLOOKUP(B142,Sheet3!$B$2:$E$311,4,) -> #N/A | F142: 3500 | G142: Discard | H142: Neza
A143: 46010 | B143: WIP GREEN TEA BASE | C143: =VLOOKUP(B143,Sheet3!$B$2:$E$311,2,FALSE) -> #N/A | D143: =VLOOKUP(B143,Sheet3!$B$2:$E$311,3,) -> #N/A | E143: =VLOOKUP(B143,Sheet3!$B$2:$E$311,4,) -> #N/A | F143: 2000 | G143: Discard | H143: Neza
A144: 46010 | B144: WIP LEMON TEA BATCH | C144: =VLOOKUP(B144,Sheet3!$B$2:$E$311,2,FALSE) -> #N/A | D144: =VLOOKUP(B144,Sheet3!$B$2:$E$311,3,) -> #N/A | E144: =VLOOKUP(B144,Sheet3!$B$2:$E$311,4,) -> #N/A | F144: 700 | G144: Discard | H144: Neza
A145: 46010 | B145: WIP RED TEA BASE | C145: =VLOOKUP(B145,Sheet3!$B$2:$E$311,2,FALSE) -> #N/A | D145: =VLOOKUP(B145,Sheet3!$B$2:$E$311,3,) -> #N/A | E145: =VLOOKUP(B145,Sheet3!$B$2:$E$311,4,) -> #N/A | F145: 2500 | G145: Discard | H145: Neza
A146: 46010 | B146: SCRAMBLED EGG | C146: =VLOOKUP(B146,Sheet3!$B$2:$E$311,2,FALSE) -> #N/A | D146: =VLOOKUP(B146,Sheet3!$B$2:$E$311,3,) -> #N/A | E146: =VLOOKUP(B146,Sheet3!$B$2:$E$311,4,) -> #N/A | F146: 2 | G146: Discard | H146: Karin
A147: 46010 | B147: WIP NASI PUTIH | C147: =VLOOKUP(B147,Sheet3!$B$2:$E$311,2,FALSE) -> #N/A | D147: =VLOOKUP(B147,Sheet3!$B$2:$E$311,3,) -> #N/A | E147: =VLOOKUP(B147,Sheet3!$B$2:$E$311,4,) -> #N/A | F147: 13 | G147: Discard | H147: Karin
A148: 46010 | B148: WIP NASI PUTIH | C148: =VLOOKUP(B148,Sheet3!$B$2:$E$311,2,FALSE) -> #N/A | D148: =VLOOKUP(B148,Sheet3!$B$2:$E$311,3,) -> #N/A | E148: =VLOOKUP(B148,Sheet3!$B$2:$E$311,4,) -> #N/A | F148: 12 | G148: Discard | H148: Karin
A149: 46010 | B149: WIP NASI PUTIH | C149: =VLOOKUP(B149,Sheet3!$B$2:$E$311,2,FALSE) -> #N/A | D149: =VLOOKUP(B149,Sheet3!$B$2:$E$311,3,) -> #N/A | E149: =VLOOKUP(B149,Sheet3!$B$2:$E$311,4,) -> #N/A | F149: 16 | G149: Discard | H149: Karin
A150: 46011 | B150: WIP MILK FOAM | C150: =VLOOKUP(B150,Sheet3!$B$2:$E$311,2,FALSE) -> #N/A | D150: =VLOOKUP(B150,Sheet3!$B$2:$E$311,3,) -> #N/A | E150: =VLOOKUP(B150,Sheet3!$B$2:$E$311,4,) -> #N/A | F150: 249 | G150: Discard | H150: Neza
A151: 46011 | B151: WIP NASI PUTIH | C151: =VLOOKUP(B151,Sheet3!$B$2:$E$311,2,FALSE) -> #N/A | D151: =VLOOKUP(B151,Sheet3!$B$2:$E$311,3,) -> #N/A | E151: =VLOOKUP(B151,Sheet3!$B$2:$E$311,4,) -> #N/A | F151: 21 | G151: Discard | H151: Nagof
... A175: 46013 | B175: WIP GREEN TEA BASE | C175: =VLOOKUP(B175,Sheet3!$B$2:$E$311,2,FALSE) -> #N/A | D175: =VLOOKUP(B175,Sheet3!$B$2:$E$311,3,) -> #N/A | E175: =VLOOKUP(B175,Sheet3!$B$2:$E$311,4,) -> #N/A | F175: 3500 | G175: Discard | H175: Neza
A176: 46013 | B176: WIP NASI PUTIH | C176: =VLOOKUP(B176,Sheet3!$B$2:$E$311,2,FALSE) -> #N/A | D176: =VLOOKUP(B176,Sheet3!$B$2:$E$311,3,) -> #N/A | E176: =VLOOKUP(B176,Sheet3!$B$2:$E$311,4,) -> #N/A | F176: =4680/130 -> 36 | G176: Discard | H176: Karin
A177: 46013 | B177: WIP NASI PUTIH | C177: =VLOOKUP(B177,Sheet3!$B$2:$E$311,2,FALSE) -> #N/A | D177: =VLOOKUP(B177,Sheet3!$B$2:$E$311,3,) -> #N/A | E177: =VLOOKUP(B177,Sheet3!$B$2:$E$311,4,) -> #N/A | F177: 28 | G177: Discard | H177: Karin
A178: 46013 | B178: WIP TELUR KOCOK | C178: =VLOOKUP(B178,Sheet3!$B$2:$E$311,2,FALSE) -> #N/A | D178: =VLOOKUP(B178,Sheet3!$B$2:$E$311,3,) -> #N/A | E178: =VLOOKUP(B178,Sheet3!$B$2:$E$311,4,) -> #N/A | F178: 285 | G178: Discard | H178: Karin
A179: 46013 | B179: SCRAMBLED EGG | C179: =VLOOKUP(B179,Sheet3!$B$2:$E$311,2,FALSE) -> #N/A | D179: =VLOOKUP(B179,Sheet3!$B$2:$E$311,3,) -> #N/A | E179: =VLOOKUP(B179,Sheet3!$B$2:$E$311,4,) -> #N/A | F179: 3 | G179: Discard | H179: Karin
A180: 46013 | B180: AMERICAN FRIES | C180: =VLOOKUP(B180,Sheet3!$B$2:$E$311,2,FALSE) -> #N/A | D180: =VLOOKUP(B180,Sheet3!$B$2:$E$311,3,) -> #N/A | E180: =VLOOKUP(B180,Sheet3!$B$2:$E$311,4,) -> #N/A | F180: 1 | G180: Discard | H180: Karin
A181: 46014 | B181: WIP TOPPING AYAM SAMBAL BAWANG | C181: =VLOOKUP(B181,Sheet3!$B$2:$E$311,2,FALSE) -> #N/A | D181: =VLOOKUP(B181,Sheet3!$B$2:$E$311,3,) -> #N/A | E181: =VLOOKUP(B181,Sheet3!$B$2:$E$311,4,) -> #N/A | F181: 454 | G181: Discard | H181: Dendi
A182: 46014 | B182: WIP NASI PUTIH | C182: =VLOOKUP(B182,Sheet3!$B$2:$E$311,2,FALSE) -> #N/A | D182: =VLOOKUP(B182,Sheet3!$B$2:$E$311,3,) -> #N/A | E182: =VLOOKUP(B182,Sheet3!$B$2:$E$311,4,) -> #N/A | F182: 22 | G182: Discard | H182: Dendi
...

Sheet PER APRIL TGL 5
A1: h | B1: NAMA PRODUK | C1: KODE CSA | D1: JENIS | E1: SATUAN CSA | F1: JUMLAH | G1: ALASAN WASTE | H1: USER | I1: Koreksi audit
B2: WAFFLE CONE | C2: =VLOOKUP(B2,Sheet3!$B$2:$E$311,2,FALSE) -> B004 | D2: =VLOOKUP(B2,Sheet3!$B$2:$E$311,3,) -> BAHAN BAKU LUUCA | E2: =VLOOKUP(B2,Sheet3!$B$2:$E$311,4,) -> PCS | F2: 20 | G2: Training | H2: Lidia
B3: SLEEVE CONE - LUUCA | C3: =VLOOKUP(B3,Sheet3!$B$2:$E$311,2,FALSE) -> P005 | D3: =VLOOKUP(B3,Sheet3!$B$2:$E$311,3,) -> PACKAGING LUUCA | E3: =VLOOKUP(B3,Sheet3!$B$2:$E$311,4,) -> PCS | F3: 20 | G3: Training | H3: Lidia
B4: SIMPLE SYRUP 3KG | C4: =VLOOKUP(B4,Sheet3!$B$2:$E$311,2,FALSE) -> B004 | D4: =VLOOKUP(B4,Sheet3!$B$2:$E$311,3,) -> BAHAN BAKU LUUCA | E4: =VLOOKUP(B4,Sheet3!$B$2:$E$311,4,) -> GR | F4: 15 | G4: Training
B5: SIMPLE SYRUP 3KG | C5: =VLOOKUP(B5,Sheet3!$B$2:$E$311,2,FALSE) -> B004 | D5: =VLOOKUP(B5,Sheet3!$B$2:$E$311,3,) -> BAHAN BAKU LUUCA | E5: =VLOOKUP(B5,Sheet3!$B$2:$E$311,4,) -> GR | F5: 21 | G5: Training
B6: Latte Amore (HOT) | C6: =VLOOKUP(B6,Sheet3!$B$2:$E$311,2,FALSE) -> L001 | D6: =VLOOKUP(B6,Sheet3!$B$2:$E$311,3,) -> LUCCA MENU | E6: =VLOOKUP(B6,Sheet3!$B$2:$E$311,4,) -> PRS | F6: 1 | G6: Training
B7: Latte Amore (Iced) | C7: =VLOOKUP(B7,Sheet3!$B$2:$E$311,2,FALSE) -> L001 | D7: =VLOOKUP(B7,Sheet3!$B$2:$E$311,3,) -> LUCCA MENU | E7: =VLOOKUP(B7,Sheet3!$B$2:$E$311,4,) -> PRS | F7: 1 | G7: Training
B8: Classico (Iced) | C8: =VLOOKUP(B8,Sheet3!$B$2:$E$311,2,FALSE) -> L001 | D8: =VLOOKUP(B8,Sheet3!$B$2:$E$311,3,) -> LUCCA MENU | E8: =VLOOKUP(B8,Sheet3!$B$2:$E$311,4,) -> PRS | F8: 1 | G8: Training
B9: Classico (HOT) | C9: =VLOOKUP(B9,Sheet3!$B$2:$E$311,2,FALSE) -> L001 | D9: =VLOOKUP(B9,Sheet3!$B$2:$E$311,3,) -> LUCCA MENU | E9: =VLOOKUP(B9,Sheet3!$B$2:$E$311,4,) -> PRS | F9: 1 | G9: Training
B10: CUP PP 16OZ LUUCA | C10: =VLOOKUP(B10,Sheet3!$B$2:$E$311,2,FALSE) -> P005 | D10: =VLOOKUP(B10,Sheet3!$B$2:$E$311,3,) -> PACKAGING LUUCA | E10: =VLOOKUP(B10,Sheet3!$B$2:$E$311,4,) -> PCS | F10: 1 | G10: Training
A11: 46092 | B11: Nutcracker Coffe (Iced) | C11: =VLOOKUP(B11,Sheet3!$B$2:$E$311,2,FALSE) -> L001 | D11: =VLOOKUP(B11,Sheet3!$B$2:$E$311,3,) -> LUCCA MENU | E11: =VLOOKUP(B11,Sheet3!$B$2:$E$311,4,) -> PRS | F11: 1 | G11: Training
A12: 46093 | B12: BUAH STRAWBERRY | D12: =VLOOKUP(B12,Sheet3!$B$2:$E$311,3,) -> BAHAN BAKU LUUCA | E12: =VLOOKUP(B12,Sheet3!$B$2:$E$311,4,) -> GR | F12: 5,2 | G12: Tidak bisa digunakan/Daun
B13: BUAH STRAWBERRY | D13: =VLOOKUP(B13,Sheet3!$B$2:$E$311,3,) -> BAHAN BAKU LUUCA | E13: =VLOOKUP(B13,Sheet3!$B$2:$E$311,4,) -> GR | F13: 11 | G13: Busuk
B14: PEPERO ALMOND 32GR | D14: =VLOOKUP(B14,Sheet3!$B$2:$E$311,3,) -> BAHAN BAKU LUUCA | E14: PCS | F14: 1 | G14: Patah
A15: 46094 | B15: Belgian Choco (Iced) | C15: =VLOOKUP(B15,Sheet3!$B$2:$E$311,2,FALSE) -> L001 | D15: =VLOOKUP(B15,Sheet3!$B$2:$E$311,3,) -> LUCCA MENU | E15: =VLOOKUP(B15,Sheet3!$B$2:$E$311,4,) -> PRS | F15: 1 | G15: Terjatuh
B16: WAFFLE CONE | C16: =VLOOKUP(B16,Sheet3!$B$2:$E$311,2,FALSE) -> B004 | D16: =VLOOKUP(B16,Sheet3!$B$2:$E$311,3,) -> BAHAN BAKU LUUCA | E16: =VLOOKUP(B16,Sheet3!$B$2:$E$311,4,) -> PCS | F16: 1 | G16: Terkontaminasi
B17: POCKY STRAWBERRY 45GR | C17: =VLOOKUP(B17,Sheet3!$B$2:$E$311,2,FALSE) -> B004 | D17: =VLOOKUP(B17,Sheet3!$B$2:$E$311,3,) -> BAHAN BAKU LUUCA | E17: PCS | F17: 1 | G17: Patah
B18: PEPERO ALMOND 32GR | C18: =VLOOKUP(B18,Sheet3!$B$2:$E$311,2,FALSE) -> B004 | D18: =VLOOKUP(B18,Sheet3!$B$2:$E$311,3,) -> BAHAN BAKU LUUCA | E18: =VLOOKUP(B18,Sheet3!$B$2:$E$311,4,) -> GR | F18: 5 | G18: Patah
B19: BUAH STRAWBERRY | C19: =VLOOKUP(B19,Sheet3!$B$2:$E$311,2,FALSE) -> B004 | D19: =VLOOKUP(B19,Sheet3!$B$2:$E$311,3,) -> BAHAN BAKU LUUCA | E19: =VLOOKUP(B19,Sheet3!$B$2:$E$311,4,) -> GR | F19: 10,5 | G19: Tidak bisa digunakan/Daun
A20: 46095 | B20: BUAH KIWI | C20: =VLOOKUP(B20,Sheet3!$B$2:$E$311,2,FALSE) -> B004 | D20: =VLOOKUP(B20,Sheet3!$B$2:$E$311,3,) -> BAHAN BAKU LUUCA | E20: =VLOOKUP(B20,Sheet3!$B$2:$E$311,4,) -> GR | F20: 49,9 | G20: Tidak bisa digunakan/Kulit
B21: BUAH STRAWBERRY | C21: =VLOOKUP(B21,Sheet3!$B$2:$E$311,2,FALSE) -> B004 | D21: =VLOOKUP(B21,Sheet3!$B$2:$E$311,3,) -> BAHAN BAKU LUUCA | E21: =VLOOKUP(B21,Sheet3!$B$2:$E$311,4,) -> GR | F21: 7,7 | G21: Tidak bisa digunakan/Daun
B22: BUAH KIWI | C22: =VLOOKUP(B22,Sheet3!$B$2:$E$311,2,FALSE) -> B004 | D22: =VLOOKUP(B22,Sheet3!$B$2:$E$311,3,) -> BAHAN BAKU LUUCA | E22: =VLOOKUP(B22,Sheet3!$B$2:$E$311,4,) -> GR | F22: 29,5 | G22: Tidak bisa digunakan/Kulit
B23: BUAH KIWI | C23: =VLOOKUP(B23,Sheet3!$B$2:$E$311,2,FALSE) -> B004 | D23: =VLOOKUP(B23,Sheet3!$B$2:$E$311,3,) -> BAHAN BAKU LUUCA | E23: =VLOOKUP(B23,Sheet3!$B$2:$E$311,4,) -> GR | F23: 21 | G23: Tidak Ada biji
B24: CORN FLAKES 150GR | C24: =VLOOKUP(B24,Sheet3!$B$2:$E$311,2,FALSE) -> B004 | D24: =VLOOKUP(B24,Sheet3!$B$2:$E$311,3,) -> BAHAN BAKU LUUCA | E24: =VLOOKUP(B24,Sheet3!$B$2:$E$311,4,) -> GR | F24: 6,1 | G24: Terkontaminasi
B25: PEPERO ALMOND 32GR | C25: =VLOOKUP(B25,Sheet3!$B$2:$E$311,2,FALSE) -> B004 | D25: =VLOOKUP(B25,Sheet3!$B$2:$E$311,3,) -> BAHAN BAKU LUUCA | E25: PCS | F25: 5 | G25: Patah
A26: 46096 | B26: POCKY STRAWBERRY 45GR | C26: =VLOOKUP(B26,Sheet3!$B$2:$E$311,2,FALSE) -> B004 | D26: =VLOOKUP(B26,Sheet3!$B$2:$E$311,3,) -> BAHAN BAKU LUUCA | E26: PCS | F26: 22 | G26: Patah
B27: BUAH STRAWBERRY | C27: =VLOOKUP(B27,Sheet3!$B$2:$E$311,2,FALSE) -> B004 | D27: =VLOOKUP(B27,Sheet3!$B$2:$E$311,3,) -> BAHAN BAKU LUUCA | E27: =VLOOKUP(B27,Sheet3!$B$2:$E$311,4,) -> GR | F27: 1,1 | G27: Tidak bisa digunakan/Daun
B28: BUAH STRAWBERRY | C28: =VLOOKUP(B28,Sheet3!$B$2:$E$311,2,FALSE) -> B004 | D28: =VLOOKUP(B28,Sheet3!$B$2:$E$311,3,) -> BAHAN BAKU LUUCA | E28: =VLOOKUP(B28,Sheet3!$B$2:$E$311,4,) -> GR | F28: 3,7 | G28: Tidak bisa digunakan/Daun
B29: PEPERO ALMOND 32GR | C29: =VLOOKUP(B29,Sheet3!$B$2:$E$311,2,FALSE) -> B004 | D29: =VLOOKUP(B29,Sheet3!$B$2:$E$311,3,) -> BAHAN BAKU LUUCA | E29: PCS | F29: 8 | G29: Patah
B30: COFFEE BEANS - LUUCA | C30: =VLOOKUP(B30,Sheet3!$B$2:$E$311,2,FALSE) -> B004 | D30: =VLOOKUP(B30,Sheet3!$B$2:$E$311,3,) -> BAHAN BAKU LUUCA | E30: =VLOOKUP(B30,Sheet3!$B$2:$E$311,4,) -> GR | F30: 18 | G30: Kalibrasi
B31: BUAH KIWI | C31: =VLOOKUP(B31,Sheet3!$B$2:$E$311,2,FALSE) -> B004 | D31: =VLOOKUP(B31,Sheet3!$B$2:$E$311,3,) -> BAHAN BAKU LUUCA | E31: =VLOOKUP(B31,Sheet3!$B$2:$E$311,4,) -> GR | F31: 24,4 | G31: Tidak bisa digunakan/Kulit
B32: BUAH KIWI | C32: =VLOOKUP(B32,Sheet3!$B$2:$E$311,2,FALSE) -> B004 | D32: =VLOOKUP(B32,Sheet3!$B$2:$E$311,3,) -> BAHAN BAKU LUUCA | E32: =VLOOKUP(B32,Sheet3!$B$2:$E$311,4,) -> GR | F32: 36,6 | G32: Tidak Ada biji
B33: FRISIAN FLAG UHT FULL CREAM 946ML | C33: =VLOOKUP(B33,Sheet3!$B$2:$E$311,2,FALSE) -> B004 | D33: =VLOOKUP(B33,Sheet3!$B$2:$E$311,3,) -> BAHAN BAKU LUUCA | E33: =VLOOKUP(B33,Sheet3!$B$2:$E$311,4,) -> ML | F33: 946 | G33: Basi Dari kiriman
B34: Juliet Yoghurt | C34: =VLOOKUP(B34,Sheet3!$B$2:$E$311,2,FALSE) -> L001 | D34: =VLOOKUP(B34,Sheet3!$B$2:$E$311,3,) -> LUCCA MENU | E34: =VLOOKUP(B34,Sheet3!$B$2:$E$311,4,) -> PRS | F34: 1 | G34: For Crew
B35: Juliet Yoghurt | C35: =VLOOKUP(B35,Sheet3!$B$2:$E$311,2,FALSE) -> L001 | D35: =VLOOKUP(B35,Sheet3!$B$2:$E$311,3,) -> LUCCA MENU | E35: =VLOOKUP(B35,Sheet3!$B$2:$E$311,4,) -> PRS | F35: 1 | G35: For Crew
B36: Juliet Yoghurt | C36: =VLOOKUP(B36,Sheet3!$B$2:$E$311,2,FALSE) -> L001 | D36: =VLOOKUP(B36,Sheet3!$B$2:$E$311,3,) -> LUCCA MENU | E36: =VLOOKUP(B36,Sheet3!$B$2:$E$311,4,) -> PRS | F36: 1 | G36: For Crew
B37: Romeo Chocolate | C37: =VLOOKUP(B37,Sheet3!$B$2:$E$311,2,FALSE) -> L001 | D37: =VLOOKUP(B37,Sheet3!$B$2:$E$311,3,) -> LUCCA MENU | E37: =VLOOKUP(B37,Sheet3!$B$2:$E$311,4,) -> PRS | F37: 1 | G37: For Crew
B38: Iora Strawberry | C38: =VLOOKUP(B38,Sheet3!$B$2:$E$311,2,FALSE) -> L001 | D38: =VLOOKUP(B38,Sheet3!$B$2:$E$311,3,) -> LUCCA MENU | E38: =VLOOKUP(B38,Sheet3!$B$2:$E$311,4,) -> PRS | F38: 1 | G38: For Crew
B39: Romeo Chocolate | C39: =VLOOKUP(B39,Sheet3!$B$2:$E$311,2,FALSE) -> L001 | D39: =VLOOKUP(B39,Sheet3!$B$2:$E$311,3,) -> LUCCA MENU | E39: =VLOOKUP(B39,Sheet3!$B$2:$E$311,4,) -> PRS | F39: 1 | G39: For Crew
A40: 46097 | B40: BUAH STRAWBERRY | C40: =VLOOKUP(B40,Sheet3!$B$2:$E$311,2,FALSE) -> B004 | D40: =VLOOKUP(B40,Sheet3!$B$2:$E$311,3,) -> BAHAN BAKU LUUCA | E40: =VLOOKUP(B40,Sheet3!$B$2:$E$311,4,) -> GR | F40: 2 | G40: Tidak bisa digunakan/Daun
...

Sheet 5 APRIL - 30 APRIL 2026
A1: TANGGAL | B1: NAMA PRODUK | C1: KODE CSA | D1: JENIS | E1: SATUAN CSA | F1: JUMLAH | G1: ALASAN WASTE | H1: USER | I1: koreksi audit
A2: 46117 | B2: BUAH KIWI | C2: =VLOOKUP(B2,Sheet3!$B$2:$E$311,2,FALSE) -> B004 | D2: =VLOOKUP(B2,Sheet3!$B$2:$E$311,3,) -> BAHAN BAKU LUUCA | E2: =VLOOKUP(B2,Sheet3!$B$2:$E$311,4,) -> GR | F2: 101,7 | G2: Tidak bisa digunakan | H2: Nickita
A3: 46117 | B3: BUAH KIWI | C3: =VLOOKUP(B3,Sheet3!$B$2:$E$311,2,FALSE) -> B004 | D3: =VLOOKUP(B3,Sheet3!$B$2:$E$311,3,) -> BAHAN BAKU LUUCA | E3: =VLOOKUP(B3,Sheet3!$B$2:$E$311,4,) -> GR | F3: 78,4 | G3: Tidak bisa digunakan | H3: Nickita
A4: 46117 | B4: BUAH ANGGUR | C4: =VLOOKUP(B4,Sheet3!$B$2:$E$311,2,FALSE) -> B004 | D4: =VLOOKUP(B4,Sheet3!$B$2:$E$311,3,) -> BAHAN BAKU LUUCA | E4: =VLOOKUP(B4,Sheet3!$B$2:$E$311,4,) -> GR | F4: 26,2 | G4: Busuk | H4: Nickita
A5: 04/05/202604/05/202 | B5: BUAH ANGGUR | C5: =VLOOKUP(B5,Sheet3!$B$2:$E$311,2,FALSE) -> B004 | D5: =VLOOKUP(B5,Sheet3!$B$2:$E$311,3,) -> BAHAN BAKU LUUCA | E5: =VLOOKUP(B5,Sheet3!$B$2:$E$311,4,) -> GR | F5: 14,7 | G5: Tidak bisa digunakan | H5: Nickita
A6: 04/05/202604/05/202 | B6: BUAH STRAWBERRY | C6: =VLOOKUP(B6,Sheet3!$B$2:$E$311,2,FALSE) -> B004 | D6: =VLOOKUP(B6,Sheet3!$B$2:$E$311,3,) -> BAHAN BAKU LUUCA | E6: =VLOOKUP(B6,Sheet3!$B$2:$E$311,4,) -> GR | F6: 336,6 | G6: Busuk | H6: Nickita
A7: 04/05/202604/05/202 | B7: BUAH STRAWBERRY | C7: =VLOOKUP(B7,Sheet3!$B$2:$E$311,2,FALSE) -> B004 | D7: =VLOOKUP(B7,Sheet3!$B$2:$E$311,3,) -> BAHAN BAKU LUUCA | E7: =VLOOKUP(B7,Sheet3!$B$2:$E$311,4,) -> GR | F7: 45 | G7: Tidak bisa digunakan | H7: Nickita
A8: 04/05/202604/05/202 | B8: BUAH STRAWBERRY | C8: =VLOOKUP(B8,Sheet3!$B$2:$E$311,2,FALSE) -> B004 | D8: =VLOOKUP(B8,Sheet3!$B$2:$E$311,3,) -> BAHAN BAKU LUUCA | E8: =VLOOKUP(B8,Sheet3!$B$2:$E$311,4,) -> GR | F8: 15 | G8: Tidak bisa digunakan | H8: Tian
A9: 04/05/202604/05/202 | B9: BUAH KIWI | C9: =VLOOKUP(B9,Sheet3!$B$2:$E$311,2,FALSE) -> B004 | D9: =VLOOKUP(B9,Sheet3!$B$2:$E$311,3,) -> BAHAN BAKU LUUCA | E9: =VLOOKUP(B9,Sheet3!$B$2:$E$311,4,) -> GR | F9: 35 | G9: Tidak bisa digunakan | H9: Tian
A10: 04/05/202604/05/202 | B10: PEPERO ALMOND 32GR | C10: =VLOOKUP(B10,Sheet3!$B$2:$E$311,2,FALSE) -> B004 | D10: =VLOOKUP(B10,Sheet3!$B$2:$E$311,3,) -> BAHAN BAKU LUUCA | E10: PCS | F10: 14 | G10: Patah | H10: Tian
A11: 04/05/202604/05/202 | B11: BUAH STRAWBERRY | C11: =VLOOKUP(B11,Sheet3!$B$2:$E$311,2,FALSE) -> B004 | D11: =VLOOKUP(B11,Sheet3!$B$2:$E$311,3,) -> BAHAN BAKU LUUCA | E11: =VLOOKUP(B11,Sheet3!$B$2:$E$311,4,) -> GR | F11: 25 | G11: Busuk | H11: Tian
A12: 46118 | B12: WIP CHOCOLATE BASE | C12: =VLOOKUP(B12,Sheet3!$B$2:$E$311,2,FALSE) -> P006 | D12: =VLOOKUP(B12,Sheet3!$B$2:$E$311,3,) -> PRODUKSI STOK LUUCA | E12: =VLOOKUP(B12,Sheet3!$B$2:$E$311,4,) -> GR | F12: 734 | G12: Basi | H12: Lidia
A13: 46118 | B13: BUAH KIWI | C13: =VLOOKUP(B13,Sheet3!$B$2:$E$311,2,FALSE) -> B004 | D13: =VLOOKUP(B13,Sheet3!$B$2:$E$311,3,) -> BAHAN BAKU LUUCA | E13: =VLOOKUP(B13,Sheet3!$B$2:$E$311,4,) -> GR | F13: 171 | G13: Tidak bisa digunakan | H13: Raka
A14: 46118 | B14: BUAH STRAWBERRY | C14: =VLOOKUP(B14,Sheet3!$B$2:$E$311,2,FALSE) -> B004 | D14: =VLOOKUP(B14,Sheet3!$B$2:$E$311,3,) -> BAHAN BAKU LUUCA | E14: =VLOOKUP(B14,Sheet3!$B$2:$E$311,4,) -> GR | F14: 122 | G14: Tidak bisa digunakan | H14: Raka
A15: 46118 | B15: DOUGH - CLASSIC RIBBON | C15: =VLOOKUP(B15,Sheet3!$B$2:$E$311,2,FALSE) -> B004 | D15: =VLOOKUP(B15,Sheet3!$B$2:$E$311,3,) -> BAHAN BAKU LUUCA | E15: =VLOOKUP(B15,Sheet3!$B$2:$E$311,4,) -> PCS | F15: 1 | G15: Tidak bisa digunakan | H15: Lidia
A16: 46118 | B16: PEPERO ALMOND 32GR | C16: =VLOOKUP(B16,Sheet3!$B$2:$E$311,2,FALSE) -> B004 | D16: =VLOOKUP(B16,Sheet3!$B$2:$E$311,3,) -> BAHAN BAKU LUUCA | E16: PCS | F16: 15 | G16: Patah | H16: Lidia
A17: 46118 | B17: BUAH STRAWBERRY | C17: =VLOOKUP(B17,Sheet3!$B$2:$E$311,2,FALSE) -> B004 | D17: =VLOOKUP(B17,Sheet3!$B$2:$E$311,3,) -> BAHAN BAKU LUUCA | E17: =VLOOKUP(B17,Sheet3!$B$2:$E$311,4,) -> GR | F17: 64 | G17: Busuk | H17: Tian
A18: 46118 | B18: BUAH STRAWBERRY | C18: =VLOOKUP(B18,Sheet3!$B$2:$E$311,2,FALSE) -> B004 | D18: =VLOOKUP(B18,Sheet3!$B$2:$E$311,3,) -> BAHAN BAKU LUUCA | E18: =VLOOKUP(B18,Sheet3!$B$2:$E$311,4,) -> GR | F18: 13 | G18: Tidak bisa digunakan/Daun | H18: Tian
A19: 46118 | B19: NATA DE COCO KARA 1KGX6 | C19: =VLOOKUP(B19,Sheet3!$B$2:$E$311,2,FALSE) -> B004 | D19: =VLOOKUP(B19,Sheet3!$B$2:$E$311,3,) -> BAHAN BAKU LUUCA | E19: =VLOOKUP(B19,Sheet3!$B$2:$E$311,4,) -> GR | F19: 352,6 | G19: Tidak bisa digunakan/Air | H19: Nickita
A20: 46118 | B20: TELUR | C20: =VLOOKUP(B20,Sheet3!$B$2:$E$311,2,FALSE) -> #N/A | D20: =VLOOKUP(B20,Sheet3!$B$2:$E$311,3,) -> #N/A | E20: =VLOOKUP(B20,Sheet3!$B$2:$E$311,4,) -> #N/A | F20: 74,1gr | G20: Putih telur | H20: Nickita
A21: 46119 | B21: BUAH STRAWBERRY | C21: =VLOOKUP(B21,Sheet3!$B$2:$E$311,2,FALSE) -> B004 | D21: =VLOOKUP(B21,Sheet3!$B$2:$E$311,3,) -> BAHAN BAKU LUUCA | E21: =VLOOKUP(B21,Sheet3!$B$2:$E$311,4,) -> GR | F21: 15 | G21: Tidak bisa digunakan/Daun | H21: Raka
A22: 46119 | B22: PEPERO ALMOND 32GR | C22: =VLOOKUP(B22,Sheet3!$B$2:$E$311,2,FALSE) -> B004 | D22: =VLOOKUP(B22,Sheet3!$B$2:$E$311,3,) -> BAHAN BAKU LUUCA | E22: PCS | F22: 4 | G22: Patah | H22: Lidia
A23: 46119 | B23: POCKY STRAWBERRY 45GR | C23: =VLOOKUP(B23,Sheet3!$B$2:$E$311,2,FALSE) -> B004 | D23: =VLOOKUP(B23,Sheet3!$B$2:$E$311,3,) -> BAHAN BAKU LUUCA | E23: PCS | F23: 13 | G23: Patah/Basah | H23: Lidia
A24: 46119 | B24: BUAH STRAWBERRY | C24: =VLOOKUP(B24,Sheet3!$B$2:$E$311,2,FALSE) -> B004 | D24: =VLOOKUP(B24,Sheet3!$B$2:$E$311,3,) -> BAHAN BAKU LUUCA | E24: =VLOOKUP(B24,Sheet3!$B$2:$E$311,4,) -> GR | F24: 63,6 | G24: Tidak bisa digunakan/Daun | H24: Nickita
A25: 46119 | B25: BUAH STRAWBERRY | C25: =VLOOKUP(B25,Sheet3!$B$2:$E$311,2,FALSE) -> B004 | D25: =VLOOKUP(B25,Sheet3!$B$2:$E$311,3,) -> BAHAN BAKU LUUCA | E25: =VLOOKUP(B25,Sheet3!$B$2:$E$311,4,) -> GR | F25: 114 | G25: Busuk | H25: Nickita
A26: 46119 | B26: TELUR | C26: =VLOOKUP(B26,Sheet3!$B$2:$E$311,2,FALSE) -> #N/A | D26: =VLOOKUP(B26,Sheet3!$B$2:$E$311,3,) -> #N/A | E26: =VLOOKUP(B26,Sheet3!$B$2:$E$311,4,) -> #N/A | F26: 111 | G26: Putih telur | H26: Lidia
A27: 46120 | B27: TELUR | C27: =VLOOKUP(B27,Sheet3!$B$2:$E$311,2,FALSE) -> #N/A | D27: =VLOOKUP(B27,Sheet3!$B$2:$E$311,3,) -> #N/A | E27: =VLOOKUP(B27,Sheet3!$B$2:$E$311,4,) -> #N/A | F27: 78,7 | G27: Putih telur | H27: Nickita
A28: 46120 | B28: BUAH KIWI | C28: =VLOOKUP(B28,Sheet3!$B$2:$E$311,2,FALSE) -> B004 | D28: =VLOOKUP(B28,Sheet3!$B$2:$E$311,3,) -> BAHAN BAKU LUUCA | E28: =VLOOKUP(B28,Sheet3!$B$2:$E$311,4,) -> GR | F28: 29,3 | G28: Busuk | H28: Nickita
A29: 46120 | B29: BUAH KIWI | C29: =VLOOKUP(B29,Sheet3!$B$2:$E$311,2,FALSE) -> B004 | D29: =VLOOKUP(B29,Sheet3!$B$2:$E$311,3,) -> BAHAN BAKU LUUCA | E29: =VLOOKUP(B29,Sheet3!$B$2:$E$311,4,) -> GR | F29: 26,8 | G29: Tidak bisa digunakan/ Kulit | H29: Nickita
A30: 46120 | B30: BUAH STRAWBERRY | C30: =VLOOKUP(B30,Sheet3!$B$2:$E$311,2,FALSE) -> B004 | D30: =VLOOKUP(B30,Sheet3!$B$2:$E$311,3,) -> BAHAN BAKU LUUCA | E30: =VLOOKUP(B30,Sheet3!$B$2:$E$311,4,) -> GR | F30: 10,2 | G30: Tidak bisa digunakan/Kulit | H30: Nickita
A31: 46120 | B31: BUAH ANGGUR | C31: =VLOOKUP(B31,Sheet3!$B$2:$E$311,2,FALSE) -> B004 | D31: =VLOOKUP(B31,Sheet3!$B$2:$E$311,3,) -> BAHAN BAKU LUUCA | E31: =VLOOKUP(B31,Sheet3!$B$2:$E$311,4,) -> GR | F31: 43,5 | G31: Busuk | H31: Nickita
A32: 46120 | B32: BUAH ANGGUR | D32: =VLOOKUP(B32,Sheet3!$B$2:$E$311,3,) -> BAHAN BAKU LUUCA | E32: =VLOOKUP(B32,Sheet3!$B$2:$E$311,4,) -> GR | F32: 18 | G32: Tangkai Anggur | H32: Nickita
A33: 46120 | B33: BUAH KIWI | C33: =VLOOKUP(B33,Sheet3!$B$2:$E$311,2,FALSE) -> B004 | D33: =VLOOKUP(B33,Sheet3!$B$2:$E$311,3,) -> BAHAN BAKU LUUCA | E33: =VLOOKUP(B33,Sheet3!$B$2:$E$311,4,) -> GR | F33: 93 | G33: Tidak bisa digunakan/Kulit | H33: Lidia
A34: 46120 | B34: BUAH LONGAN 565GR | C34: =VLOOKUP(B34,Sheet3!$B$2:$E$311,2,FALSE) -> B004 | D34: =VLOOKUP(B34,Sheet3!$B$2:$E$311,3,) -> BAHAN BAKU LUUCA | E34: =VLOOKUP(B34,Sheet3!$B$2:$E$311,4,) -> GR | F34: 358 | G34: Air | H34: Lidia
A35: 46120 | B35: NATA DE COCO KARA 1KGX6 | C35: =VLOOKUP(B35,Sheet3!$B$2:$E$311,2,FALSE) -> B004 | D35: =VLOOKUP(B35,Sheet3!$B$2:$E$311,3,) -> BAHAN BAKU LUUCA | E35: =VLOOKUP(B35,Sheet3!$B$2:$E$311,4,) -> GR | F35: 1103 | G35: Air | H35: Lidia
A36: 46120 | B36: POCKY STRAWBERRY 45GR | C36: =VLOOKUP(B36,Sheet3!$B$2:$E$311,2,FALSE) -> B004 | D36: =VLOOKUP(B36,Sheet3!$B$2:$E$311,3,) -> BAHAN BAKU LUUCA | E36: PCS | F36: 10 | G36: Patah/Basah | H36: Lidia
A37: 46120 | B37: PEPERO ALMOND 32GR | C37: =VLOOKUP(B37,Sheet3!$B$2:$E$311,2,FALSE) -> B004 | D37: =VLOOKUP(B37,Sheet3!$B$2:$E$311,3,) -> BAHAN BAKU LUUCA | E37: PCS | F37: 14 | G37: Patah | H37: Lidia
A38: 46120 | B38: BUAH STRAWBERRY | C38: =VLOOKUP(B38,Sheet3!$B$2:$E$311,2,FALSE) -> B004 | D38: =VLOOKUP(B38,Sheet3!$B$2:$E$311,3,) -> BAHAN BAKU LUUCA | E38: =VLOOKUP(B38,Sheet3!$B$2:$E$311,4,) -> GR | F38: 14 | G38: Tidak bisa digunakan/Daun | H38: Lidia
A39: 46120 | B39: BUAH STRAWBERRY | C39: =VLOOKUP(B39,Sheet3!$B$2:$E$311,2,FALSE) -> B004 | D39: =VLOOKUP(B39,Sheet3!$B$2:$E$311,3,) -> BAHAN BAKU LUUCA | E39: =VLOOKUP(B39,Sheet3!$B$2:$E$311,4,) -> GR | F39: 67 | G39: Busuk | H39: Lidia
A40: 46120 | B40: DOUGH - PAIN AU CHOCOLATE | C40: =VLOOKUP(B40,Sheet3!$B$2:$E$311,2,FALSE) -> B004 | D40: =VLOOKUP(B40,Sheet3!$B$2:$E$311,3,) -> BAHAN BAKU LUUCA | E40: =VLOOKUP(B40,Sheet3!$B$2:$E$311,4,) -> PCS | F40: 1 | G40: Tertimpa barang saat thwing | H40: Alif
...

Sheet 1 MEI - 30 MEI
A1: TANGGAL | B1: NAMA PRODUK | C1: KODE CSA | D1: JENIS | F1: JUMLAH | G1: ALASAN WASTE | H1: USER | I1: koreksi audit
A2: 46027 | B2: NATA DE COCO KARA 1KGX6 | C2: =VLOOKUP(B2,Sheet3!$B$2:$E$311,2,FALSE) -> B004 | D2: =VLOOKUP(B2,Sheet3!$B$2:$E$311,3,) -> BAHAN BAKU LUUCA | E2: =VLOOKUP(B2,Sheet3!$B$2:$E$311,4,) -> GR | F2: 197 | G2: Air | H2: Thia | I2: v | J2: Ilyas
B3: TELUR | C3: =VLOOKUP(B3,Sheet3!$B$2:$E$311,2,FALSE) -> #N/A | D3: BAHAN BAKU LUUCA | E3: PCS/GR | F3: 296,3/3 | G3: Putih telur | H3: Nickita | I3: v | J3: Ilyas
B4: BUAH ANGGUR | C4: =VLOOKUP(B4,Sheet3!$B$2:$E$311,2,FALSE) -> B004 | D4: =VLOOKUP(B4,Sheet3!$B$2:$E$311,3,) -> BAHAN BAKU LUUCA | E4: =VLOOKUP(B4,Sheet3!$B$2:$E$311,4,) -> GR | F4: 251.9 | G4: Busuk | H4: Nickita | I4: v | J4: Ilyas
B5: BUAH STRAWBERRY | C5: =VLOOKUP(B5,Sheet3!$B$2:$E$311,2,FALSE) -> B004 | D5: =VLOOKUP(B5,Sheet3!$B$2:$E$311,3,) -> BAHAN BAKU LUUCA | E5: =VLOOKUP(B5,Sheet3!$B$2:$E$311,4,) -> GR | F5: 11.4 | G5: Daun | H5: Nickita | I5: v | J5: Ilyas
B6: BUAH KIWI | C6: =VLOOKUP(B6,Sheet3!$B$2:$E$311,2,FALSE) -> B004 | D6: =VLOOKUP(B6,Sheet3!$B$2:$E$311,3,) -> BAHAN BAKU LUUCA | E6: =VLOOKUP(B6,Sheet3!$B$2:$E$311,4,) -> GR | F6: 14.1 | G6: Busuk | H6: Nickita | I6: v | J6: Ilyas
B7: BUAH KIWI | C7: =VLOOKUP(B7,Sheet3!$B$2:$E$311,2,FALSE) -> B004 | D7: =VLOOKUP(B7,Sheet3!$B$2:$E$311,3,) -> BAHAN BAKU LUUCA | E7: =VLOOKUP(B7,Sheet3!$B$2:$E$311,4,) -> GR | F7: 63.1 | G7: Kulit | H7: Nickita | I7: v | J7: Ilyas
B8: BUAH ANGGUR | C8: =VLOOKUP(B8,Sheet3!$B$2:$E$311,2,FALSE) -> B004 | D8: =VLOOKUP(B8,Sheet3!$B$2:$E$311,3,) -> BAHAN BAKU LUUCA | E8: =VLOOKUP(B8,Sheet3!$B$2:$E$311,4,) -> GR | F8: 12.9 | G8: Tangkai Anggur | H8: Nickita | I8: v | J8: Ilyas
B9: BUAH KIWI | C9: =VLOOKUP(B9,Sheet3!$B$2:$E$311,2,FALSE) -> B004 | D9: =VLOOKUP(B9,Sheet3!$B$2:$E$311,3,) -> BAHAN BAKU LUUCA | E9: =VLOOKUP(B9,Sheet3!$B$2:$E$311,4,) -> GR | F9: 74.6 | G9: Kulit | H9: Nickita | I9: v | J9: Ilyas
B10: BUAH STRAWBERRY | C10: =VLOOKUP(B10,Sheet3!$B$2:$E$311,2,FALSE) -> B004 | D10: =VLOOKUP(B10,Sheet3!$B$2:$E$311,3,) -> BAHAN BAKU LUUCA | E10: =VLOOKUP(B10,Sheet3!$B$2:$E$311,4,) -> GR | F10: 19.7 | G10: Daun | H10: Lidia | I10: v | J10: Ilyas
B11: BUAH ANGGUR | C11: =VLOOKUP(B11,Sheet3!$B$2:$E$311,2,FALSE) -> B004 | D11: =VLOOKUP(B11,Sheet3!$B$2:$E$311,3,) -> BAHAN BAKU LUUCA | E11: =VLOOKUP(B11,Sheet3!$B$2:$E$311,4,) -> GR | F11: 8.6 | G11: Tangkai Anggur | H11: Lidia | I11: v | J11: Ilyas
B12: BUAH ANGGUR | C12: =VLOOKUP(B12,Sheet3!$B$2:$E$311,2,FALSE) -> B004 | D12: =VLOOKUP(B12,Sheet3!$B$2:$E$311,3,) -> BAHAN BAKU LUUCA | E12: =VLOOKUP(B12,Sheet3!$B$2:$E$311,4,) -> GR | F12: 88.4 | G12: Busuk | H12: Lidia | I12: v | J12: Ilyas
B13: NATA DE COCO KARA 1KGX6 | C13: =VLOOKUP(B13,Sheet3!$B$2:$E$311,2,FALSE) -> B004 | D13: =VLOOKUP(B13,Sheet3!$B$2:$E$311,3,) -> BAHAN BAKU LUUCA | E13: =VLOOKUP(B13,Sheet3!$B$2:$E$311,4,) -> GR | F13: 1219 | G13: Air | H13: Lidia | I13: v | J13: Ilyas
B14: BUAH STRAWBERRY | C14: =VLOOKUP(B14,Sheet3!$B$2:$E$311,2,FALSE) -> B004 | D14: =VLOOKUP(B14,Sheet3!$B$2:$E$311,3,) -> BAHAN BAKU LUUCA | E14: =VLOOKUP(B14,Sheet3!$B$2:$E$311,4,) -> GR | F14: 181.7 | G14: Busuk | H14: Lidia | I14: v | J14: Ilyas
B15: BUAH STRAWBERRY | C15: =VLOOKUP(B15,Sheet3!$B$2:$E$311,2,FALSE) -> B004 | D15: =VLOOKUP(B15,Sheet3!$B$2:$E$311,3,) -> BAHAN BAKU LUUCA | E15: =VLOOKUP(B15,Sheet3!$B$2:$E$311,4,) -> GR | F15: 167.3 | G15: Busuk | H15: Lidia | I15: v | J15: Ilyas
B16: BUAH STRAWBERRY | C16: =VLOOKUP(B16,Sheet3!$B$2:$E$311,2,FALSE) -> B004 | D16: =VLOOKUP(B16,Sheet3!$B$2:$E$311,3,) -> BAHAN BAKU LUUCA | E16: =VLOOKUP(B16,Sheet3!$B$2:$E$311,4,) -> GR | F16: 30.6 | G16: Daun | H16: Lidia | I16: v | J16: Ilyas
A17: 46058 | B17: NATA DE COCO KARA 1KGX6 | C17: =VLOOKUP(B17,Sheet3!$B$2:$E$311,2,FALSE) -> B004 | D17: =VLOOKUP(B17,Sheet3!$B$2:$E$311,3,) -> BAHAN BAKU LUUCA | E17: =VLOOKUP(B17,Sheet3!$B$2:$E$311,4,) -> GR | F17: 483.5 | G17: Air | H17: Nickita | I17: v | J17: Ilyas
B18: BUAH LONGAN 565GR | C18: =VLOOKUP(B18,Sheet3!$B$2:$E$311,2,FALSE) -> B004 | D18: =VLOOKUP(B18,Sheet3!$B$2:$E$311,3,) -> BAHAN BAKU LUUCA | E18: =VLOOKUP(B18,Sheet3!$B$2:$E$311,4,) -> GR | F18: 944 | G18: Air | H18: Nickita | I18: v | J18: Ilyas
B19: TELUR | C19: =VLOOKUP(B19,Sheet3!$B$2:$E$311,2,FALSE) -> #N/A | D19: BAHAN BAKU LUUCA | E19: PCS/GR | F19: 75,5/2 | G19: Putih telur | H19: Thia | I19: v | J19: Ilyas
B20: PEPERO ALMOND 32GR | C20: =VLOOKUP(B20,Sheet3!$B$2:$E$311,2,FALSE) -> B004 | D20: =VLOOKUP(B20,Sheet3!$B$2:$E$311,3,) -> BAHAN BAKU LUUCA | E20: =VLOOKUP(B20,Sheet3!$B$2:$E$311,4,) -> GR | F20: 2 | G20: Terkontaminasi air | H20: Thia | I20: v | J20: Ilyas
B21: BUAH STRAWBERRY | C21: =VLOOKUP(B21,Sheet3!$B$2:$E$311,2,FALSE) -> B004 | D21: =VLOOKUP(B21,Sheet3!$B$2:$E$311,3,) -> BAHAN BAKU LUUCA | E21: =VLOOKUP(B21,Sheet3!$B$2:$E$311,4,) -> GR | F21: 316 | G21: Busuk | H21: Lidia | I21: v | J21: Ilyas
B22: BUAH KIWI | C22: =VLOOKUP(B22,Sheet3!$B$2:$E$311,2,FALSE) -> B004 | D22: =VLOOKUP(B22,Sheet3!$B$2:$E$311,3,) -> BAHAN BAKU LUUCA | E22: =VLOOKUP(B22,Sheet3!$B$2:$E$311,4,) -> GR | F22: 49.5 | G22: Kulit | H22: Thia | I22: v | J22: Ilyas
B23: BUAH STRAWBERRY | C23: =VLOOKUP(B23,Sheet3!$B$2:$E$311,2,FALSE) -> B004 | D23: =VLOOKUP(B23,Sheet3!$B$2:$E$311,3,) -> BAHAN BAKU LUUCA | E23: =VLOOKUP(B23,Sheet3!$B$2:$E$311,4,) -> GR | F23: 13.5 | G23: Daun | H23: Thia | I23: v | J23: Ilyas
B24: NATA DE COCO KARA 1KGX6 | C24: =VLOOKUP(B24,Sheet3!$B$2:$E$311,2,FALSE) -> B004 | D24: =VLOOKUP(B24,Sheet3!$B$2:$E$311,3,) -> BAHAN BAKU LUUCA | E24: =VLOOKUP(B24,Sheet3!$B$2:$E$311,4,) -> GR | F24: 303 | G24: Air | H24: Thia | I24: v | J24: Ilyas
A25: 46145 | B25: BUAH LONGAN 565GR | C25: =VLOOKUP(B25,Sheet3!$B$2:$E$311,2,FALSE) -> B004 | D25: =VLOOKUP(B25,Sheet3!$B$2:$E$311,3,) -> BAHAN BAKU LUUCA | E25: =VLOOKUP(B25,Sheet3!$B$2:$E$311,4,) -> GR | F25: 333 | G25: Air | H25: Thia | I25: V | J25: Tri
B26: BUAH STRAWBERRY | C26: =VLOOKUP(B26,Sheet3!$B$2:$E$311,2,FALSE) -> B004 | D26: =VLOOKUP(B26,Sheet3!$B$2:$E$311,3,) -> BAHAN BAKU LUUCA | E26: =VLOOKUP(B26,Sheet3!$B$2:$E$311,4,) -> GR | F26: 7,3 | G26: Daun | H26: Thia | I26: V | J26: Tri
B27: BUAH KIWI | C27: =VLOOKUP(B27,Sheet3!$B$2:$E$311,2,FALSE) -> B004 | D27: =VLOOKUP(B27,Sheet3!$B$2:$E$311,3,) -> BAHAN BAKU LUUCA | E27: =VLOOKUP(B27,Sheet3!$B$2:$E$311,4,) -> GR | F27: 22,6 | G27: Kulit | H27: Thia | I27: V | J27: Tri
A28: 46146 | B28: BUAH KIWI | C28: =VLOOKUP(B28,Sheet3!$B$2:$E$311,2,FALSE) -> B004 | D28: =VLOOKUP(B28,Sheet3!$B$2:$E$311,3,) -> BAHAN BAKU LUUCA | E28: =VLOOKUP(B28,Sheet3!$B$2:$E$311,4,) -> GR | F28: 19,4 | G28: Busuk | H28: Nickita | I28: V | J28: Tri
B29: NATA DE COCO KARA 1KGX6 | C29: =VLOOKUP(B29,Sheet3!$B$2:$E$311,2,FALSE) -> B004 | D29: =VLOOKUP(B29,Sheet3!$B$2:$E$311,3,) -> BAHAN BAKU LUUCA | E29: =VLOOKUP(B29,Sheet3!$B$2:$E$311,4,) -> GR | F29: 1530 | G29: Air | H29: Lidia | I29: V | J29: Tri
B30: BUAH LONGAN 565GR | C30: =VLOOKUP(B30,Sheet3!$B$2:$E$311,2,FALSE) -> B004 | D30: =VLOOKUP(B30,Sheet3!$B$2:$E$311,3,) -> BAHAN BAKU LUUCA | E30: =VLOOKUP(B30,Sheet3!$B$2:$E$311,4,) -> GR | F30: 1402 | G30: Air | H30: Lidia | I30: V | J30: Tri
B31: SLEEVE CONE - LUUCA | C31: =VLOOKUP(B31,Sheet3!$B$2:$E$311,2,FALSE) -> P005 | D31: =VLOOKUP(B31,Sheet3!$B$2:$E$311,3,) -> PACKAGING LUUCA | E31: =VLOOKUP(B31,Sheet3!$B$2:$E$311,4,) -> PCS | F31: 2 | G31: Rusak | H31: Lidia | I31: V | J31: Tri
A32: 46147 | B32: BUAH ANGGUR | C32: =VLOOKUP(B32,Sheet3!$B$2:$E$311,2,FALSE) -> B004 | D32: =VLOOKUP(B32,Sheet3!$B$2:$E$311,3,) -> BAHAN BAKU LUUCA | E32: =VLOOKUP(B32,Sheet3!$B$2:$E$311,4,) -> GR | F32: 3,6 | G32: Tangkai Anggur | H32: Lidia | I32: V | J32: Tri
B33: Filling biscotti crema | C33: =VLOOKUP(B33,Sheet3!$B$2:$E$311,2,FALSE) -> #N/A | D33: BAHAN BAKU LUUCA | E33: GR | F33: 206,1 | G33: Tidak bisa digunakan | H33: Lidia | I33: V | J33: Tri
B34: Whipping cream | C34: =VLOOKUP(B34,Sheet3!$B$2:$E$311,2,FALSE) -> #N/A | D34: BAHAN BAKU LUUCA | E34: GR | F34: 235,4 | G34: Gagal produksi | H34: Lidia | I34: V | J34: Tri
A35: 45843 | B35: BUAH STRAWBERRY | C35: =VLOOKUP(B35,Sheet3!$B$2:$E$311,2,FALSE) -> B004 | D35: =VLOOKUP(B35,Sheet3!$B$2:$E$311,3,) -> BAHAN BAKU LUUCA | E35: =VLOOKUP(B35,Sheet3!$B$2:$E$311,4,) -> GR | F35: 9,4 | G35: Daun | H35: Faisal | I35: V | J35: Tri
B36: BUAH KIWI | C36: =VLOOKUP(B36,Sheet3!$B$2:$E$311,2,FALSE) -> B004 | D36: =VLOOKUP(B36,Sheet3!$B$2:$E$311,3,) -> BAHAN BAKU LUUCA | E36: =VLOOKUP(B36,Sheet3!$B$2:$E$311,4,) -> GR | F36: 39,4 | G36: Kulit | H36: Raka | I36: V | J36: Tri
B37: NATA DE COCO KARA 1KGX6 | C37: =VLOOKUP(B37,Sheet3!$B$2:$E$311,2,FALSE) -> B004 | D37: =VLOOKUP(B37,Sheet3!$B$2:$E$311,3,) -> BAHAN BAKU LUUCA | E37: =VLOOKUP(B37,Sheet3!$B$2:$E$311,4,) -> GR | F37: 589 | G37: Air | H37: Alif | I37: V | J37: Tri
B38: TELUR | D38: BAHAN BAKU LUUCA | E38: GR/PCS | F38: 27,3/1 | G38: Putih telur | H38: Nickita | I38: V | J38: Tri
B39: BUAH LONGAN 565GR | C39: =VLOOKUP(B39,Sheet3!$B$2:$E$311,2,FALSE) -> B004 | D39: =VLOOKUP(B39,Sheet3!$B$2:$E$311,3,) -> BAHAN BAKU LUUCA | E39: =VLOOKUP(B39,Sheet3!$B$2:$E$311,4,) -> GR | F39: 1162 | G39: Air | H39: Lidia | I39: V | J39: Tri
A40: 46239 | B40: BUAH ANGGUR | C40: =VLOOKUP(B40,Sheet3!$B$2:$E$311,2,FALSE) -> B004 | D40: =VLOOKUP(B40,Sheet3!$B$2:$E$311,3,) -> BAHAN BAKU LUUCA | E40: =VLOOKUP(B40,Sheet3!$B$2:$E$311,4,) -> GR | F40: 26,1 | G40: Busuk | H40: Lidia | I40: V | J40: Tri
...

Sheet JUNI 2026
A1: FORM ADJUSTMENT
A2: PT. KREASI LIMA CAHAYA
A3: LUUCA CILEDUG
A4: BULAN, TAHUN:
A6: TANGGAL | B6: NAMA PRODUK | C6: KODE CSA | D6: JENIS | E6: JUMLAH | F6: SATUAN CSA | G6: ALASAN WASTE | H6: USER | I6: KATEGORI | J6: AUDIT
A7: 46028 | B7: BUAH STRAWBERRY | C7: =IFERROR(VLOOKUP(B7,'MASTER DATA'!$A$1:$E$212,2,FALSE),"") -> BB-100500 | D7: =IFERROR(VLOOKUP(B7,'MASTER DATA'!$A$1:$E$212,5,FALSE),"") -> BAHAN BAKU LUUCA | E7: 89,2 | F7: =IFERROR(VLOOKUP(B7,'MASTER DATA'!$A$1:$E$212,4,FALSE),"") -> GR | G7: Busuk/Berair | H7: Raka | J7: TRUE
B8: BUAH KIWI | C8: =IFERROR(VLOOKUP(B8,'MASTER DATA'!$A$1:$E$212,2,FALSE),"") -> BB-100502 | D8: =IFERROR(VLOOKUP(B8,'MASTER DATA'!$A$1:$E$212,5,FALSE),"") -> BAHAN BAKU LUUCA | E8: 98 | F8: =IFERROR(VLOOKUP(B8,'MASTER DATA'!$A$1:$E$212,4,FALSE),"") -> GR | G8: Kulit | H8: Raka | J8: TRUE
B9: BUAH STRAWBERRY | C9: =IFERROR(VLOOKUP(B9,'MASTER DATA'!$A$1:$E$212,2,FALSE),"") -> BB-100500 | D9: =IFERROR(VLOOKUP(B9,'MASTER DATA'!$A$1:$E$212,5,FALSE),"") -> BAHAN BAKU LUUCA | E9: 36,5 | F9: =IFERROR(VLOOKUP(B9,'MASTER DATA'!$A$1:$E$212,4,FALSE),"") -> GR | G9: Daun | H9: Raka | J9: TRUE
B10: BUAH LONGAN 565GR | C10: =IFERROR(VLOOKUP(B10,'MASTER DATA'!$A$1:$E$212,2,FALSE),"") -> BB-100022 | D10: =IFERROR(VLOOKUP(B10,'MASTER DATA'!$A$1:$E$212,5,FALSE),"") -> BAHAN BAKU LUUCA | E10: 448 | F10: =IFERROR(VLOOKUP(B10,'MASTER DATA'!$A$1:$E$212,4,FALSE),"") -> GR | G10: Air | H10: Raka | J10: TRUE
B11: BUAH STRAWBERRY | C11: =IFERROR(VLOOKUP(B11,'MASTER DATA'!$A$1:$E$212,2,FALSE),"") -> BB-100500 | D11: =IFERROR(VLOOKUP(B11,'MASTER DATA'!$A$1:$E$212,5,FALSE),"") -> BAHAN BAKU LUUCA | E11: 7,3 | F11: =IFERROR(VLOOKUP(B11,'MASTER DATA'!$A$1:$E$212,4,FALSE),"") -> GR | G11: Daun | H11: Nickita | J11: TRUE
B12: BUAH KIWI | C12: =IFERROR(VLOOKUP(B12,'MASTER DATA'!$A$1:$E$212,2,FALSE),"") -> BB-100502 | D12: =IFERROR(VLOOKUP(B12,'MASTER DATA'!$A$1:$E$212,5,FALSE),"") -> BAHAN BAKU LUUCA | E12: 31,2 | F12: =IFERROR(VLOOKUP(B12,'MASTER DATA'!$A$1:$E$212,4,FALSE),"") -> GR | G12: Daun& Ujung kiwi | H12: Nickita | J12: TRUE
A13: 46059 | B13: BUAH STRAWBERRY | C13: =IFERROR(VLOOKUP(B13,'MASTER DATA'!$A$1:$E$212,2,FALSE),"") -> BB-100500 | D13: =IFERROR(VLOOKUP(B13,'MASTER DATA'!$A$1:$E$212,5,FALSE),"") -> BAHAN BAKU LUUCA | E13: 42,7 | F13: =IFERROR(VLOOKUP(B13,'MASTER DATA'!$A$1:$E$212,4,FALSE),"") -> GR | G13: Daun | H13: Lidia | J13: TRUE
B14: BUAH ANGGUR | C14: =IFERROR(VLOOKUP(B14,'MASTER DATA'!$A$1:$E$212,2,FALSE),"") -> BB-100501 | D14: =IFERROR(VLOOKUP(B14,'MASTER DATA'!$A$1:$E$212,5,FALSE),"") -> BAHAN BAKU LUUCA | E14: 10 | F14: =IFERROR(VLOOKUP(B14,'MASTER DATA'!$A$1:$E$212,4,FALSE),"") -> GR | G14: Tangkai Anggur | H14: Lidia | J14: TRUE
B15: BUAH STRAWBERRY | C15: =IFERROR(VLOOKUP(B15,'MASTER DATA'!$A$1:$E$212,2,FALSE),"") -> BB-100500 | D15: =IFERROR(VLOOKUP(B15,'MASTER DATA'!$A$1:$E$212,5,FALSE),"") -> BAHAN BAKU LUUCA | E15: 111,6 | F15: =IFERROR(VLOOKUP(B15,'MASTER DATA'!$A$1:$E$212,4,FALSE),"") -> GR | G15: Busuk/Berair | H15: Lidia | J15: TRUE
B16: BUAH ANGGUR | C16: =IFERROR(VLOOKUP(B16,'MASTER DATA'!$A$1:$E$212,2,FALSE),"") -> BB-100501 | D16: =IFERROR(VLOOKUP(B16,'MASTER DATA'!$A$1:$E$212,5,FALSE),"") -> BAHAN BAKU LUUCA | E16: 59,8 | F16: =IFERROR(VLOOKUP(B16,'MASTER DATA'!$A$1:$E$212,4,FALSE),"") -> GR | G16: Busuk/Berair | H16: Lidia | J16: TRUE
B17: BUAH LONGAN 565GR | C17: =IFERROR(VLOOKUP(B17,'MASTER DATA'!$A$1:$E$212,2,FALSE),"") -> BB-100022 | D17: =IFERROR(VLOOKUP(B17,'MASTER DATA'!$A$1:$E$212,5,FALSE),"") -> BAHAN BAKU LUUCA | E17: 647 | F17: =IFERROR(VLOOKUP(B17,'MASTER DATA'!$A$1:$E$212,4,FALSE),"") -> GR | G17: Air | H17: Lidia | J17: TRUE
B18: WIP MATCHA ICE CREAM | C18: =IFERROR(VLOOKUP(B18,'MASTER DATA'!$A$1:$E$212,2,FALSE),"") -> P006-003 | D18: =IFERROR(VLOOKUP(B18,'MASTER DATA'!$A$1:$E$212,5,FALSE),"") -> PRODUKSI STOK LUUCA | E18: 150 | F18: =IFERROR(VLOOKUP(B18,'MASTER DATA'!$A$1:$E$212,4,FALSE),"") -> GR | G18: Terkontaminasi | H18: Nickita | J18: TRUE
B19: STRAWBERRY JAM 1,2KG | C19: =IFERROR(VLOOKUP(B19,'MASTER DATA'!$A$1:$E$212,2,FALSE),"") -> BB-100345 | D19: =IFERROR(VLOOKUP(B19,'MASTER DATA'!$A$1:$E$212,5,FALSE),"") -> PRODUKSI STOK LUUCA | E19: 27,5 | F19: =IFERROR(VLOOKUP(B19,'MASTER DATA'!$A$1:$E$212,4,FALSE),"") -> GR | G19: Terkontaminasi | H19: Nickita | J19: TRUE
A20: 46087 | B20: WIP MATCHA ICE CREAM | C20: =IFERROR(VLOOKUP(B20,'MASTER DATA'!$A$1:$E$212,2,FALSE),"") -> P006-003 | D20: =IFERROR(VLOOKUP(B20,'MASTER DATA'!$A$1:$E$212,5,FALSE),"") -> PRODUKSI STOK LUUCA | E20: 2129 | F20: =IFERROR(VLOOKUP(B20,'MASTER DATA'!$A$1:$E$212,4,FALSE),"") -> GR | G20: Basi | H20: Lidia | J20: TRUE
B21: NATA DE COCO KARA 1KGX6 | C21: =IFERROR(VLOOKUP(B21,'MASTER DATA'!$A$1:$E$212,2,FALSE),"") -> BB-100023 | D21: =IFERROR(VLOOKUP(B21,'MASTER DATA'!$A$1:$E$212,5,FALSE),"") -> BAHAN BAKU LUUCA | E21: 230 | F21: =IFERROR(VLOOKUP(B21,'MASTER DATA'!$A$1:$E$212,4,FALSE),"") -> GR | G21: Air | H21: Lidia | J21: TRUE
B22: BUAH KIWI | C22: =IFERROR(VLOOKUP(B22,'MASTER DATA'!$A$1:$E$212,2,FALSE),"") -> BB-100502 | D22: =IFERROR(VLOOKUP(B22,'MASTER DATA'!$A$1:$E$212,5,FALSE),"") -> BAHAN BAKU LUUCA | E22: 116,1 | F22: =IFERROR(VLOOKUP(B22,'MASTER DATA'!$A$1:$E$212,4,FALSE),"") -> GR | G22: Kulit | H22: Lidia | J22: TRUE
B23: COFFEE BEANS - LUUCA | C23: =IFERROR(VLOOKUP(B23,'MASTER DATA'!$A$1:$E$212,2,FALSE),"") -> BB-100400 | D23: =IFERROR(VLOOKUP(B23,'MASTER DATA'!$A$1:$E$212,5,FALSE),"") -> BAHAN BAKU LUUCA | E23: 18 | F23: =IFERROR(VLOOKUP(B23,'MASTER DATA'!$A$1:$E$212,4,FALSE),"") -> GR | G23: Kalibrasi | H23: Lidia | J23: TRUE
A24: 46118 | B24: NATA DE COCO KARA 1KGX6 | C24: =IFERROR(VLOOKUP(B24,'MASTER DATA'!$A$1:$E$212,2,FALSE),"") -> BB-100023 | D24: =IFERROR(VLOOKUP(B24,'MASTER DATA'!$A$1:$E$212,5,FALSE),"") -> BAHAN BAKU LUUCA | E24: 555 | F24: =IFERROR(VLOOKUP(B24,'MASTER DATA'!$A$1:$E$212,4,FALSE),"") -> GR | G24: Air | H24: Tian | J24: TRUE
A25: 46148 | B25: WAFFLE CONE | C25: =IFERROR(VLOOKUP(B25,'MASTER DATA'!$A$1:$E$212,2,FALSE),"") -> BB-100024 | D25: =IFERROR(VLOOKUP(B25,'MASTER DATA'!$A$1:$E$212,5,FALSE),"") -> PRODUKSI STOK LUUCA | E25: 1 | F25: =IFERROR(VLOOKUP(B25,'MASTER DATA'!$A$1:$E$212,4,FALSE),"") -> PCS | G25: Cek Gramasi | H25: Lidia | J25: TRUE
B26: CHOCO DIP SAUCE BELLA 1KG | C26: =IFERROR(VLOOKUP(B26,'MASTER DATA'!$A$1:$E$212,2,FALSE),"") -> BB-100021 | D26: =IFERROR(VLOOKUP(B26,'MASTER DATA'!$A$1:$E$212,5,FALSE),"") -> BAHAN BAKU LUUCA | E26: 12 | F26: =IFERROR(VLOOKUP(B26,'MASTER DATA'!$A$1:$E$212,4,FALSE),"") -> GR | G26: Cek Gramasi | H26: Lidia | J26: TRUE
B27: BUAH STRAWBERRY | C27: =IFERROR(VLOOKUP(B27,'MASTER DATA'!$A$1:$E$212,2,FALSE),"") -> BB-100500 | D27: =IFERROR(VLOOKUP(B27,'MASTER DATA'!$A$1:$E$212,5,FALSE),"") -> BAHAN BAKU LUUCA | E27: 156,3 | F27: =IFERROR(VLOOKUP(B27,'MASTER DATA'!$A$1:$E$212,4,FALSE),"") -> GR | G27: Busuk | H27: Lidia | J27: TRUE
B28: BUAH STRAWBERRY | C28: =IFERROR(VLOOKUP(B28,'MASTER DATA'!$A$1:$E$212,2,FALSE),"") -> BB-100500 | D28: =IFERROR(VLOOKUP(B28,'MASTER DATA'!$A$1:$E$212,5,FALSE),"") -> BAHAN BAKU LUUCA | E28: 3 | F28: =IFERROR(VLOOKUP(B28,'MASTER DATA'!$A$1:$E$212,4,FALSE),"") -> GR | G28: Daun | H28: Tian | J28: TRUE
B29: Bologna Yogurt | C29: =IFERROR(VLOOKUP(B29,'MASTER DATA'!$A$1:$E$212,2,FALSE),"") -> L001-013 | D29: =IFERROR(VLOOKUP(B29,'MASTER DATA'!$A$1:$E$212,5,FALSE),"") -> BAHAN BAKU LUUCA | E29: 1 | F29: =IFERROR(VLOOKUP(B29,'MASTER DATA'!$A$1:$E$212,4,FALSE),"") -> PRS | G29: Kompensasi | H29: Lidia | J29: TRUE
B30: BUAH ANGGUR | C30: =IFERROR(VLOOKUP(B30,'MASTER DATA'!$A$1:$E$212,2,FALSE),"") -> BB-100501 | D30: =IFERROR(VLOOKUP(B30,'MASTER DATA'!$A$1:$E$212,5,FALSE),"") -> BAHAN BAKU LUUCA | E30: 37.5 | F30: =IFERROR(VLOOKUP(B30,'MASTER DATA'!$A$1:$E$212,4,FALSE),"") -> GR | G30: Tangkai | H30: Lidia | J30: TRUE
A31: 46179 | B31: BUAH KIWI | C31: =IFERROR(VLOOKUP(B31,'MASTER DATA'!$A$1:$E$212,2,FALSE),"") -> BB-100502 | D31: =IFERROR(VLOOKUP(B31,'MASTER DATA'!$A$1:$E$212,5,FALSE),"") -> BAHAN BAKU LUUCA | E31: 73.2 | F31: =IFERROR(VLOOKUP(B31,'MASTER DATA'!$A$1:$E$212,4,FALSE),"") -> GR | G31: Kulit | H31: Allif | J31: TRUE
B32: BUAH KIWI | C32: =IFERROR(VLOOKUP(B32,'MASTER DATA'!$A$1:$E$212,2,FALSE),"") -> BB-100502 | D32: =IFERROR(VLOOKUP(B32,'MASTER DATA'!$A$1:$E$212,5,FALSE),"") -> BAHAN BAKU LUUCA | E32: 68 | F32: =IFERROR(VLOOKUP(B32,'MASTER DATA'!$A$1:$E$212,4,FALSE),"") -> GR | G32: Busuk | H32: Alif | J32: TRUE
B33: BUAH STRAWBERRY | C33: =IFERROR(VLOOKUP(B33,'MASTER DATA'!$A$1:$E$212,2,FALSE),"") -> BB-100500 | D33: =IFERROR(VLOOKUP(B33,'MASTER DATA'!$A$1:$E$212,5,FALSE),"") -> BAHAN BAKU LUUCA | E33: 12.9 | F33: =IFERROR(VLOOKUP(B33,'MASTER DATA'!$A$1:$E$212,4,FALSE),"") -> GR | G33: Daun | H33: Tian | J33: TRUE
B34: BUAH STRAWBERRY | C34: =IFERROR(VLOOKUP(B34,'MASTER DATA'!$A$1:$E$212,2,FALSE),"") -> BB-100500 | D34: =IFERROR(VLOOKUP(B34,'MASTER DATA'!$A$1:$E$212,5,FALSE),"") -> BAHAN BAKU LUUCA | E34: 39.7 | F34: =IFERROR(VLOOKUP(B34,'MASTER DATA'!$A$1:$E$212,4,FALSE),"") -> GR | G34: Daun | H34: Tian | J34: TRUE
B35: BUAH LONGAN 565GR | C35: =IFERROR(VLOOKUP(B35,'MASTER DATA'!$A$1:$E$212,2,FALSE),"") -> BB-100022 | D35: =IFERROR(VLOOKUP(B35,'MASTER DATA'!$A$1:$E$212,5,FALSE),"") -> BAHAN BAKU LUUCA | E35: 1137 | F35: =IFERROR(VLOOKUP(B35,'MASTER DATA'!$A$1:$E$212,4,FALSE),"") -> GR | G35: Air | H35: Lidia | J35: TRUE
B36: NATA DE COCO KARA 1KGX6 | C36: =IFERROR(VLOOKUP(B36,'MASTER DATA'!$A$1:$E$212,2,FALSE),"") -> BB-100023 | D36: =IFERROR(VLOOKUP(B36,'MASTER DATA'!$A$1:$E$212,5,FALSE),"") -> BAHAN BAKU LUUCA | E36: 1294 | F36: =IFERROR(VLOOKUP(B36,'MASTER DATA'!$A$1:$E$212,4,FALSE),"") -> GR | G36: Air | H36: Tian | J36: TRUE
A37: 46209 | B37: BUAH KIWI | C37: =IFERROR(VLOOKUP(B37,'MASTER DATA'!$A$1:$E$212,2,FALSE),"") -> BB-100502 | D37: =IFERROR(VLOOKUP(B37,'MASTER DATA'!$A$1:$E$212,5,FALSE),"") -> BAHAN BAKU LUUCA | E37: 78.9 | F37: =IFERROR(VLOOKUP(B37,'MASTER DATA'!$A$1:$E$212,4,FALSE),"") -> GR | G37: Kulit | H37: Alif | J37: TRUE
B38: BUAH STRAWBERRY | C38: =IFERROR(VLOOKUP(B38,'MASTER DATA'!$A$1:$E$212,2,FALSE),"") -> BB-100500 | D38: =IFERROR(VLOOKUP(B38,'MASTER DATA'!$A$1:$E$212,5,FALSE),"") -> BAHAN BAKU LUUCA | E38: 15.2 | F38: =IFERROR(VLOOKUP(B38,'MASTER DATA'!$A$1:$E$212,4,FALSE),"") -> GR | G38: Daun | H38: Tian | J38: TRUE
B39: BUAH LONGAN 565GR | C39: =IFERROR(VLOOKUP(B39,'MASTER DATA'!$A$1:$E$212,2,FALSE),"") -> BB-100022 | D39: =IFERROR(VLOOKUP(B39,'MASTER DATA'!$A$1:$E$212,5,FALSE),"") -> BAHAN BAKU LUUCA | E39: 404.7 | F39: =IFERROR(VLOOKUP(B39,'MASTER DATA'!$A$1:$E$212,4,FALSE),"") -> GR | G39: Air | H39: Lidia | J39: TRUE
A40: 46240 | B40: BUAH STRAWBERRY | C40: =IFERROR(VLOOKUP(B40,'MASTER DATA'!$A$1:$E$212,2,FALSE),"") -> BB-100500 | D40: =IFERROR(VLOOKUP(B40,'MASTER DATA'!$A$1:$E$212,5,FALSE),"") -> BAHAN BAKU LUUCA | E40: 5.7 | F40: =IFERROR(VLOOKUP(B40,'MASTER DATA'!$A$1:$E$212,4,FALSE),"") -> GR | G40: Daun | H40: Alif | J40: TRUE
B41: BUAH KIWI | C41: =IFERROR(VLOOKUP(B41,'MASTER DATA'!$A$1:$E$212,2,FALSE),"") -> BB-100502 | D41: =IFERROR(VLOOKUP(B41,'MASTER DATA'!$A$1:$E$212,5,FALSE),"") -> BAHAN BAKU LUUCA | E41: 51,9 | F41: =IFERROR(VLOOKUP(B41,'MASTER DATA'!$A$1:$E$212,4,FALSE),"") -> GR | G41: Kulit | H41: Nickita | J41: TRUE
...

Sheet 1JUNI-31
A1: TANGGAL | B1: NAMA PRODUK | E1: JENIS | G1: JUMLAH | H1: ALASAN WASTE | I1: USER | J1: TRI-AUDIT
A2: 46028 | B2: BUAH STRAWBERRY | C2: =IFERROR(VLOOKUP(B2,'MASTER DATA'!$A$1:$E$212,2),"") -> BB-100503 | E2: =VLOOKUP(B2,Sheet3!$B$2:$E$311,3,) -> BAHAN BAKU LUUCA | F2: =VLOOKUP(B2,Sheet3!$B$2:$E$311,4,) -> GR | G2: 89,2 | H2: Busuk/Berair | I2: Raka | J2: V
B3: BUAH KIWI | E3: =VLOOKUP(B3,Sheet3!$B$2:$E$311,3,) -> BAHAN BAKU LUUCA | F3: =VLOOKUP(B3,Sheet3!$B$2:$E$311,4,) -> GR | G3: 98 | H3: Kulit | I3: Raka | J3: V
B4: BUAH STRAWBERRY | E4: =VLOOKUP(B4,Sheet3!$B$2:$E$311,3,) -> BAHAN BAKU LUUCA | F4: =VLOOKUP(B4,Sheet3!$B$2:$E$311,4,) -> GR | G4: 36,5 | H4: Daun | I4: Raka | J4: V
