Workbook

Sheet DATA PER 111225
B1: NAMA PRODUK | C1: JENIS | D1: SATUAN CSA | E1: JUMLAH | F1: ALASAN WASTE | G1: USER
A2: B001-002 | B2: SHOESTRING FRENCH FRIES | C2: bahan baku | D2: GR
A3: B001-003 | B3: Anchor Mozzarella Cheese | C3: bahan baku | D3: GR
A4: B001-004 | B4: Ayam Original Parting 9 | C4: bahan baku | D4: PCS
A5: B001-005 | B5: Ayam Utuh - Original | C5: bahan baku | D5: PCS
A6: B001-006 | B6: Bawang Bombay | C6: bahan baku | D6: GR
A7: B001-007 | B7: Bawang Putih | C7: bahan baku | D7: GR
A8: B001-008 | B8: Beras 25KG | C8: bahan baku | D8: GR
A9: B001-009 | B9: Biji Kopi | C9: bahan baku | D9: GR
A10: B001-010 | B10: Boba Pearl | C10: bahan baku | D10: GR
A11: B001-011 | B11: Bolognese Sauce 25089E | C11: bahan baku | D11: GR
A12: B001-012 | B12: Brown Sugar Sweet Chili Sauce | C12: bahan baku | D12: GR
A13: B001-013 | B13: Bubuk Es Krim Vanilla - FT1804 | C13: bahan baku | D13: GR
... A311: P003-025 | B311: TOPI ULANG TAHUN | C311: others | D311: PCS
B312: Japanese Curry
B313: Plastik duo cup

Sheet Master data
A1: Nama Item | B1: Kode Item | C1: Unit | D1: Harga pokok | E1: KELOMPOK | F1: JENIS
A2: SHOESTRING FRENCH FRIES | B2: B001-002 | C2: GR | D2: 31,04 | E2: B001 | F2: =IFERROR(VLOOKUP(A2,Sheet3!$B$1:$E$313,3,FALSE),"") -> bahan baku | G2: B001
A3: Anchor Mozzarella Cheese | B3: B001-003 | C3: GR | D3: 151,57 | E3: B001 | F3: =IFERROR(VLOOKUP(A3,Sheet3!$B$1:$E$313,3,FALSE),"") -> bahan baku | G3: B002
A4: Ayam Original Parting 9 | B4: B001-004 | C4: PCS | D4: 5.587,56 | E4: B001 | F4: =IFERROR(VLOOKUP(A4,Sheet3!$B$1:$E$313,3,FALSE),"") -> bahan baku | G4: B003
A5: Ayam Utuh - Original | B5: B001-005 | C5: PCS | D5: 37.521,87 | E5: B001 | F5: =IFERROR(VLOOKUP(A5,Sheet3!$B$1:$E$313,3,FALSE),"") -> bahan baku | G5: D001
A6: Bawang Bombay | B6: B001-006 | C6: GR | D6: 42,20 | E6: B001 | F6: =IFERROR(VLOOKUP(A6,Sheet3!$B$1:$E$313,3,FALSE),"") -> bahan baku | G6: D002
A7: Bawang Putih Kupas | B7: B001-007 | C7: GR | D7: 45,19 | E7: B001 | F7: bahan baku | G7: D003
A8: Beras 25KG | B8: B001-008 | C8: GR | D8: 17,45 | E8: B001 | F8: =IFERROR(VLOOKUP(A8,Sheet3!$B$1:$E$313,3,FALSE),"") -> bahan baku | G8: I001
A9: Biji Kopi | B9: B001-009 | C9: GR | D9: 216,41 | E9: B001 | F9: =IFERROR(VLOOKUP(A9,Sheet3!$B$1:$E$313,3,FALSE),"") -> bahan baku | G9: M001
A10: Boba Pearl | B10: B001-010 | C10: GR | D10: 0 | E10: B001 | F10: =IFERROR(VLOOKUP(A10,Sheet3!$B$1:$E$313,3,FALSE),"") -> bahan baku | G10: P001
A11: Bolognese Sauce 25089E | B11: B001-011 | C11: GR | D11: 50,75 | E11: B001 | F11: =IFERROR(VLOOKUP(A11,Sheet3!$B$1:$E$313,3,FALSE),"") -> bahan baku | G11: P002
A12: Brown Sugar Sweet Chili Sauce | B12: B001-012 | C12: GR | D12: 50,39 | E12: B001 | F12: =IFERROR(VLOOKUP(A12,Sheet3!$B$1:$E$313,3,FALSE),"") -> bahan baku | G12: P003
A13: Bubuk Es Krim Vanilla - T1804 | B13: B001-013 | C13: GR | D13: 58,48 | E13: B001 | F13: bahan baku | G13: P004
A14: Bubuk Kopi | B14: B001-014 | C14: GR | D14: 0 | E14: B001 | F14: bahan baku | G14: S001
A15: Bumbu Bubuk Cabe (Lokal) | B15: B001-015 | C15: GR | D15: 71,80 | E15: B001 | F15: =IFERROR(VLOOKUP(A15,Sheet3!$B$1:$E$313,3,FALSE),"") -> bahan baku | G15: S002
A16: Bumbu Putih | B16: B001-016 | C16: GR | D16: 16,42 | E16: B001 | F16: =IFERROR(VLOOKUP(A16,Sheet3!$B$1:$E$313,3,FALSE),"") -> bahan baku | G16: S003
A17: Cabai Merah Keriting | B17: B001-017 | C17: GR | D17: 70 | E17: B001 | F17: =IFERROR(VLOOKUP(A17,Sheet3!$B$1:$E$313,3,FALSE),"") -> bahan baku | G17: T001
A18: Cabai Rawit Hijau | B18: B001-018 | C18: GR | D18: 74,35 | E18: B001 | F18: =IFERROR(VLOOKUP(A18,Sheet3!$B$1:$E$313,3,FALSE),"") -> bahan baku | G18: T002
A19: Cabai Rawit Merah | B19: B001-019 | C19: GR | D19: 105,83 | E19: B001 | F19: =IFERROR(VLOOKUP(A19,Sheet3!$B$1:$E$313,3,FALSE),"") -> bahan baku
A20: Cheese Cream Seasoning Powder-FLB10285 | B20: B001-020 | C20: GR | D20: 72,82 | E20: B001 | F20: =IFERROR(VLOOKUP(A20,Sheet3!$B$1:$E$313,3,FALSE),"") -> bahan baku
A21: Cheese Mayo Sauce | B21: B001-021 | C21: GR | D21: 0 | E21: B001 | F21: =IFERROR(VLOOKUP(A21,Sheet3!$B$1:$E$313,3,FALSE),"") -> others
A22: Cheese Spread | B22: B001-022 | C22: GR | D22: 67,26 | E22: B001 | F22: =IFERROR(VLOOKUP(A22,Sheet3!$B$1:$E$313,3,FALSE),"") -> bahan baku
A23: Chicken Bacon | B23: B001-023 | C23: GR | D23: 141,59 | E23: B001 | F23: =IFERROR(VLOOKUP(A23,Sheet3!$B$1:$E$313,3,FALSE),"") -> bahan baku
A24: Chicken Nugget | B24: B001-024 | C24: PCS | D24: 1.462,98 | E24: B001 | F24: =IFERROR(VLOOKUP(A24,Sheet3!$B$1:$E$313,3,FALSE),"") -> bahan baku
A25: Chicken Popcorn | B25: B001-025 | C25: GR | D25: 62,44 | E25: B001 | F25: =IFERROR(VLOOKUP(A25,Sheet3!$B$1:$E$313,3,FALSE),"") -> barang jadi
A26: Chicken Skin | B26: B001-026 | C26: GR | D26: 42,12 | E26: B001 | F26: =IFERROR(VLOOKUP(A26,Sheet3!$B$1:$E$313,3,FALSE),"") -> bahan baku
A27: Chicken Steak | B27: B001-027 | C27: GR | D27: 62,44 | E27: B001 | F27: =IFERROR(VLOOKUP(A27,Sheet3!$B$1:$E$313,3,FALSE),"") -> bahan baku
A28: Chili Sauce | B28: B001-028 | C28: GR | D28: 16,72 | E28: B001 | F28: =IFERROR(VLOOKUP(A28,Sheet3!$B$1:$E$313,3,FALSE),"") -> others
A29: Chili Sauce Flint | B29: B001-029 | C29: GR | D29: 0 | E29: B001 | F29: =IFERROR(VLOOKUP(A29,Sheet3!$B$1:$E$313,3,FALSE),"")
A30: Chili Sauce Sachet | B30: B001-030 | C30: SHT | D30: 300,29 | E30: B001 | F30: =IFERROR(VLOOKUP(A30,Sheet3!$B$1:$E$313,3,FALSE),"") -> others
A31: CIRENG BAHAN BAKU | B31: B001-031 | C31: PCS | D31: 588,30 | E31: B001 | F31: =IFERROR(VLOOKUP(A31,Sheet3!$B$1:$E$313,3,FALSE),"") -> bahan baku
A32: Coca-Cola | B32: B001-032 | C32: ML | D32: 12,74 | E32: B001 | F32: =IFERROR(VLOOKUP(A32,Sheet3!$B$1:$E$313,3,FALSE),"") -> bahan baku
A33: Cone Ice Cream Bahan Baku | B33: B001-033 | C33: PCS | D33: 705,96 | E33: B001 | F33: bahan baku
A34: Tepung Maizena | B34: B001-034 | C34: GR | D34: 32,61 | E34: B001 | F34: =IFERROR(VLOOKUP(A34,Sheet3!$B$1:$E$313,3,FALSE),"") -> bahan baku
A35: Cream Cheese | B35: B001-035 | C35: GR | D35: 117,77 | E35: B001 | F35: =IFERROR(VLOOKUP(A35,Sheet3!$B$1:$E$313,3,FALSE),"") -> bahan baku
A36: Daun Mint | B36: B001-036 | C36: GR | D36: 83,72 | E36: B001 | F36: =IFERROR(VLOOKUP(A36,Sheet3!$B$1:$E$313,3,FALSE),"") -> bahan baku
A37: Dome LID Sundae 12Oz | B37: B001-037 | C37: PCS | D37: 334,11 | E37: B001 | F37: bahan baku
A38: Egg Tart | B38: B001-038 | C38: PCS | D38: 6.487,71 | E38: B001 | F38: bahan baku
A39: Fish Steak | B39: B001-039 | C39: PCS | D39: 14.038,72 | E39: B001 | F39: =IFERROR(VLOOKUP(A39,Sheet3!$B$1:$E$313,3,FALSE),"") -> bahan baku
A40: Floor cleaner | B40: B001-040 | C40: PAI | D40: 42.869,05 | E40: B001 | F40: =IFERROR(VLOOKUP(A40,Sheet3!$B$1:$E$313,3,FALSE),"") -> others
...

Sheet DASHBOARD
A1: FORM ADJUSTMENT
A2: PT. KREASI LIMA CAHAYA
A3: JCHICKEN CILEDUG
A4: BULAN, TAHUN:
A6: TANGGAL | B6: NAMA PRODUK | C6: KODE CSA | D6: JENIS | E6: JUMLAH | F6: SATUAN CSA | G6: ALASAN WASTE | H6: USER | I6: SECTION | J6: KATEGORI | L6: AUDIT | N6: Waste
A7: 01 Juni 2026 | C7: =IFERROR(VLOOKUP(B7,'Master data'!$A$1:$F$1000,2,FALSE),"") | D7: =IFERROR(VLOOKUP(B7,'Master data'!$A$1:$F$1000,6,FALSE),"") | F7: =IFERROR(VLOOKUP(B7,'Master data'!$A$1:$F$1000,3,FALSE),"") | K7: FALSE | L7: FALSE | M7: Avoidable food waste | N7: Produksi berlebihan
C8: =IFERROR(VLOOKUP(B8,'Master data'!$A$1:$F$1000,2,FALSE),"") | D8: =IFERROR(VLOOKUP(B8,'Master data'!$A$1:$F$1000,6,FALSE),"") | F8: =IFERROR(VLOOKUP(B8,'Master data'!$A$1:$F$1000,3,FALSE),"") | K8: FALSE | L8: FALSE | N8: Kesalahan produksi
C9: =IFERROR(VLOOKUP(B9,'Master data'!$A$1:$F$1000,2,FALSE),"") | D9: =IFERROR(VLOOKUP(B9,'Master data'!$A$1:$F$1000,6,FALSE),"") | F9: =IFERROR(VLOOKUP(B9,'Master data'!$A$1:$F$1000,3,FALSE),"") | K9: FALSE | L9: FALSE | M9: unavoidable food waste | N9: sampah makanan yang tidak dapat dihindari dan tidak dapat digunakan
C10: =IFERROR(VLOOKUP(B10,'Master data'!$A$1:$F$1000,2,FALSE),"") | D10: =IFERROR(VLOOKUP(B10,'Master data'!$A$1:$F$1000,6,FALSE),"") | F10: =IFERROR(VLOOKUP(B10,'Master data'!$A$1:$F$1000,3,FALSE),"") | K10: FALSE | L10: FALSE
C11: =IFERROR(VLOOKUP(B11,'Master data'!$A$1:$F$1000,2,FALSE),"") | D11: =IFERROR(VLOOKUP(B11,'Master data'!$A$1:$F$1000,6,FALSE),"") | F11: =IFERROR(VLOOKUP(B11,'Master data'!$A$1:$F$1000,3,FALSE),"") | K11: FALSE | L11: FALSE | M11: Preparation Waste
C12: =IFERROR(VLOOKUP(B12,'Master data'!$A$1:$F$1000,2,FALSE),"") | D12: =IFERROR(VLOOKUP(B12,'Master data'!$A$1:$F$1000,6,FALSE),"") | F12: =IFERROR(VLOOKUP(B12,'Master data'!$A$1:$F$1000,3,FALSE),"") | K12: FALSE | L12: FALSE
C13: =IFERROR(VLOOKUP(B13,'Master data'!$A$1:$F$1000,2,FALSE),"") | D13: =IFERROR(VLOOKUP(B13,'Master data'!$A$1:$F$1000,6,FALSE),"") | F13: =IFERROR(VLOOKUP(B13,'Master data'!$A$1:$F$1000,3,FALSE),"") | K13: FALSE | L13: FALSE | M13: Operational/Kitchen Waste
C14: =IFERROR(VLOOKUP(B14,'Master data'!$A$1:$F$1000,2,FALSE),"") | D14: =IFERROR(VLOOKUP(B14,'Master data'!$A$1:$F$1000,6,FALSE),"") | F14: =IFERROR(VLOOKUP(B14,'Master data'!$A$1:$F$1000,3,FALSE),"") | K14: FALSE | L14: FALSE
C15: =IFERROR(VLOOKUP(B15,'Master data'!$A$1:$F$1000,2,FALSE),"") | D15: =IFERROR(VLOOKUP(B15,'Master data'!$A$1:$F$1000,6,FALSE),"") | F15: =IFERROR(VLOOKUP(B15,'Master data'!$A$1:$F$1000,3,FALSE),"") | K15: FALSE | L15: FALSE | M15: Plate waste
C16: =IFERROR(VLOOKUP(B16,'Master data'!$A$1:$F$1000,2,FALSE),"") | D16: =IFERROR(VLOOKUP(B16,'Master data'!$A$1:$F$1000,6,FALSE),"") | F16: =IFERROR(VLOOKUP(B16,'Master data'!$A$1:$F$1000,3,FALSE),"") | K16: FALSE | L16: FALSE
C17: =IFERROR(VLOOKUP(B17,'Master data'!$A$1:$F$1000,2,FALSE),"") | D17: =IFERROR(VLOOKUP(B17,'Master data'!$A$1:$F$1000,6,FALSE),"") | F17: =IFERROR(VLOOKUP(B17,'Master data'!$A$1:$F$1000,3,FALSE),"") | K17: FALSE | L17: FALSE
C18: =IFERROR(VLOOKUP(B18,'Master data'!$A$1:$F$1000,2,FALSE),"") | D18: =IFERROR(VLOOKUP(B18,'Master data'!$A$1:$F$1000,6,FALSE),"") | F18: =IFERROR(VLOOKUP(B18,'Master data'!$A$1:$F$1000,3,FALSE),"") | K18: FALSE | L18: FALSE
C19: =IFERROR(VLOOKUP(B19,'Master data'!$A$1:$F$1000,2,FALSE),"") | D19: =IFERROR(VLOOKUP(B19,'Master data'!$A$1:$F$1000,6,FALSE),"") | F19: =IFERROR(VLOOKUP(B19,'Master data'!$A$1:$F$1000,3,FALSE),"") | K19: FALSE | L19: FALSE
C20: =IFERROR(VLOOKUP(B20,'Master data'!$A$1:$F$1000,2,FALSE),"") | D20: =IFERROR(VLOOKUP(B20,'Master data'!$A$1:$F$1000,6,FALSE),"") | F20: =IFERROR(VLOOKUP(B20,'Master data'!$A$1:$F$1000,3,FALSE),"") | K20: FALSE | L20: FALSE
C21: =IFERROR(VLOOKUP(B21,'Master data'!$A$1:$F$1000,2,FALSE),"") | D21: =IFERROR(VLOOKUP(B21,'Master data'!$A$1:$F$1000,6,FALSE),"") | F21: =IFERROR(VLOOKUP(B21,'Master data'!$A$1:$F$1000,3,FALSE),"") | K21: FALSE | L21: FALSE
C22: =IFERROR(VLOOKUP(B22,'Master data'!$A$1:$F$1000,2,FALSE),"") | D22: =IFERROR(VLOOKUP(B22,'Master data'!$A$1:$F$1000,6,FALSE),"") | F22: =IFERROR(VLOOKUP(B22,'Master data'!$A$1:$F$1000,3,FALSE),"") | K22: FALSE | L22: FALSE
C23: =IFERROR(VLOOKUP(B23,'Master data'!$A$1:$F$1000,2,FALSE),"") | D23: =IFERROR(VLOOKUP(B23,'Master data'!$A$1:$F$1000,6,FALSE),"") | F23: =IFERROR(VLOOKUP(B23,'Master data'!$A$1:$F$1000,3,FALSE),"") | K23: FALSE | L23: FALSE
C24: =IFERROR(VLOOKUP(B24,'Master data'!$A$1:$F$1000,2,FALSE),"") | D24: =IFERROR(VLOOKUP(B24,'Master data'!$A$1:$F$1000,6,FALSE),"") | F24: =IFERROR(VLOOKUP(B24,'Master data'!$A$1:$F$1000,3,FALSE),"") | K24: FALSE | L24: FALSE
C25: =IFERROR(VLOOKUP(B25,'Master data'!$A$1:$F$1000,2,FALSE),"") | D25: =IFERROR(VLOOKUP(B25,'Master data'!$A$1:$F$1000,6,FALSE),"") | F25: =IFERROR(VLOOKUP(B25,'Master data'!$A$1:$F$1000,3,FALSE),"") | K25: FALSE | L25: FALSE
C26: =IFERROR(VLOOKUP(B26,'Master data'!$A$1:$F$1000,2,FALSE),"") | D26: =IFERROR(VLOOKUP(B26,'Master data'!$A$1:$F$1000,6,FALSE),"") | F26: =IFERROR(VLOOKUP(B26,'Master data'!$A$1:$F$1000,3,FALSE),"") | K26: FALSE | L26: FALSE
C27: =IFERROR(VLOOKUP(B27,'Master data'!$A$1:$F$1000,2,FALSE),"") | D27: =IFERROR(VLOOKUP(B27,'Master data'!$A$1:$F$1000,6,FALSE),"") | F27: =IFERROR(VLOOKUP(B27,'Master data'!$A$1:$F$1000,3,FALSE),"") | K27: FALSE | L27: FALSE
... C1001: =IFERROR(VLOOKUP(B1001,'Master data'!$A$1:$F$1000,2,FALSE),"") | D1001: =IFERROR(VLOOKUP(B1001,'Master data'!$A$1:$F$1000,6,FALSE),"") | F1001: =IFERROR(VLOOKUP(B1001,'Master data'!$A$1:$F$1000,3,FALSE),"") | K1001: FALSE | L1001: FALSE

Sheet Sheet3
A1: TANGGAL | B1: NAMA PRODUK | C1: KODE CSA | D1: JENIS | E1: SATUAN CSA | F1: JUMLAH | G1: ALASAN WASTE | H1: USER
B2: SHOESTRING FRENCH FRIES | C2: B001-002 | D2: bahan baku | E2: GR
B3: Anchor Mozzarella Cheese | C3: B001-003 | D3: bahan baku | E3: GR
B4: Ayam Original Parting 9 | C4: B001-004 | D4: bahan baku | E4: PCS
B5: Ayam Utuh - Original | C5: B001-005 | D5: bahan baku | E5: PCS
B6: Bawang Bombay | C6: B001-006 | D6: bahan baku | E6: GR
B7: Bawang Putih | C7: B001-007 | D7: bahan baku | E7: GR
B8: Beras 25KG | C8: B001-008 | D8: bahan baku | E8: GR
B9: Biji Kopi | C9: B001-009 | D9: bahan baku | E9: GR
B10: Boba Pearl | C10: B001-010 | D10: bahan baku | E10: GR
B11: Bolognese Sauce 25089E | C11: B001-011 | D11: bahan baku | E11: GR
B12: Brown Sugar Sweet Chili Sauce | C12: B001-012 | D12: bahan baku | E12: GR
B13: Bubuk Es Krim Vanilla - FT1804 | C13: B001-013 | D13: bahan baku | E13: GR
... B260: WIP UNSWEETENED TEA BATCH | C260: P004-024 | D260: barang jadi & bahan baku | E260: ML
B261: WIP CAMPURAN OREN | D261: barang jadi & bahan baku
B262: WIP LEMON TEA BATCH | C262: P004-025 | D262: barang jadi & bahan baku | E262: ML
B263: WIP TOPING AYAM | C263: P004-026 | D263: barang jadi & bahan baku | E263: GR
B264: WIP PREP. EGG TART | C264: P004-027 | D264: barang jadi & bahan baku | E264: PCS
B265: WIP PREP. PANDAN SRIKAYA | C265: P004-028 | D265: barang jadi & bahan baku | E265: GR
B266: WIP SAOS TERIYAKI | C266: P004-029 | D266: barang jadi & bahan baku | E266: GR
B267: WIP PREP. VANILLA ICE CREAM | C267: P004-031 | D267: barang jadi & bahan baku | E267: GR
B268: WIP PREP. PEACH ICE CREAM | C268: P004-032 | D268: barang jadi & bahan baku | E268: GR
B269: WIP BOBA | C269: P004-033 | D269: barang jadi & bahan baku | E269: GR
B270: WIP TOPPING AYAM SAMBAL BAWANG | C270: P004-034 | D270: barang jadi & bahan baku | E270: GR
B271: WIP SAMBAL BAWANG | C271: P004-035 | D271: barang jadi & bahan baku | E271: GR
B272: WIP MATCHA ICE CREAM | C272: P004-036 | D272: barang jadi & bahan baku | E272: GR
B273: SAMBAL BAWANG TURBO CHICKEN | C273: P004-037 | D273: barang jadi & bahan baku | E273: PORSI
... B312: TOPI ULANG TAHUN | C312: P003-025 | D312: others | E312: PCS
B313: WIP CAMPURAN OREN | D313: barang jadi & bahan baku
B314: Plastik duo cup

Sheet ADJUSTMENT DESEMBER JC CILEDUG
A1: TANGGAL | B1: NAMA PRODUK | C1: KODE CSA | D1: JENIS | E1: SATUAN CSA | F1: JUMLAH | G1: ALASAN WASTE | H1: USER
A2: 45994 | B2: WIP BLENDED MILKY | C2: =VLOOKUP(B2,Sheet3!$B$2:$E$312,2,FALSE) -> P004-018 | D2: =VLOOKUP(B2,Sheet3!$B$2:$E$312,3,) -> barang jadi & bahan baku | E2: =VLOOKUP(B2,Sheet3!$B$2:$E$312,4,) -> GR | F2: 419 | G2: Training | H2: Fadli
A3: 45994 | B3: WIP MILK FOAM | C3: =VLOOKUP(B3,Sheet3!$B$2:$E$312,2,FALSE) -> P004-020 | D3: =VLOOKUP(B3,Sheet3!$B$2:$E$312,3,) -> barang jadi & bahan baku | E3: =VLOOKUP(B3,Sheet3!$B$2:$E$312,4,) -> GR | F3: 321 | G3: Training | H3: Fadli
A4: 45992 | B4: SIZZLING FRIED CHICKEN STEAK | C4: =VLOOKUP(B4,Sheet3!$B$2:$E$312,2,FALSE) -> S003-001 | D4: =VLOOKUP(B4,Sheet3!$B$2:$E$312,3,) -> barang jadi | E4: =VLOOKUP(B4,Sheet3!$B$2:$E$312,4,) -> PORSI | F4: 1 | G4: Training | H4: Fadli
A5: 45992 | B5: BEEF SAUSAGE PIZZA | C5: =VLOOKUP(B5,Sheet3!$B$2:$E$312,2,FALSE) -> P002-004 | D5: =VLOOKUP(B5,Sheet3!$B$2:$E$312,3,) -> barang jadi | E5: =VLOOKUP(B5,Sheet3!$B$2:$E$312,4,) -> PORSI | F5: 1 | G5: Training | H5: Fadli
A6: 45994 | B6: WIP NASI PUTIH | C6: =VLOOKUP(B6,Sheet3!$B$2:$E$312,2,FALSE) -> P004-013 | D6: =VLOOKUP(B6,Sheet3!$B$2:$E$312,3,) -> barang jadi & bahan baku | E6: =VLOOKUP(B6,Sheet3!$B$2:$E$312,4,) -> PCS | F6: 1 | G6: Kering | H6: Dendi
A7: 45994 | B7: WIP NASI PUTIH | C7: =VLOOKUP(B7,Sheet3!$B$2:$E$312,2,FALSE) -> P004-013 | D7: =VLOOKUP(B7,Sheet3!$B$2:$E$312,3,) -> barang jadi & bahan baku | E7: =VLOOKUP(B7,Sheet3!$B$2:$E$312,4,) -> PCS | F7: 19 | G7: Discard | H7: Dendi
A8: 45994 | B8: ORIGINAL TURBO CHICKEN | C8: =VLOOKUP(B8,Sheet3!$B$2:$E$312,2,FALSE) -> P004-001 | D8: =VLOOKUP(B8,Sheet3!$B$2:$E$312,3,) -> barang jadi & bahan baku | E8: =VLOOKUP(B8,Sheet3!$B$2:$E$312,4,) -> PCS | F8: 2 | G8: Training | H8: Iqbal
A9: 45994 | B9: Paprika Hijau | C9: =VLOOKUP(B9,Sheet3!$B$2:$E$312,2,FALSE) -> B001-060 | D9: =VLOOKUP(B9,Sheet3!$B$2:$E$312,3,) -> bahan baku | E9: =VLOOKUP(B9,Sheet3!$B$2:$E$312,4,) -> GR | F9: 12 | G9: Discard | H9: Tegar
A10: 45994 | B10: Paprika Merah | C10: =VLOOKUP(B10,Sheet3!$B$2:$E$312,2,FALSE) -> B001-061 | D10: =VLOOKUP(B10,Sheet3!$B$2:$E$312,3,) -> bahan baku | E10: =VLOOKUP(B10,Sheet3!$B$2:$E$312,4,) -> GR | F10: 12 | G10: Discard | H10: Tegar
A11: 45994 | B11: WIP NASI PUTIH | C11: =VLOOKUP(B11,Sheet3!$B$2:$E$312,2,FALSE) -> P004-013 | D11: =VLOOKUP(B11,Sheet3!$B$2:$E$312,3,) -> barang jadi & bahan baku | E11: =VLOOKUP(B11,Sheet3!$B$2:$E$312,4,) -> PCS | F11: 55 | G11: Discard | H11: Tegar
A12: 45994 | B12: WIP UNSWEERENED TEA BASE | C12: =VLOOKUP(B12,Sheet3!$B$2:$E$312,2,FALSE) -> #N/A | D12: =VLOOKUP(B12,Sheet3!$B$2:$E$312,3,) -> #N/A | E12: =VLOOKUP(B12,Sheet3!$B$2:$E$312,4,) -> #N/A | F12: 3500 | G12: Discard | H12: Fadli
A13: 45994 | B13: WIP RED TEA BASE | C13: =VLOOKUP(B13,Sheet3!$B$2:$E$312,2,FALSE) -> P004-022 | D13: =VLOOKUP(B13,Sheet3!$B$2:$E$312,3,) -> barang jadi & bahan baku | E13: =VLOOKUP(B13,Sheet3!$B$2:$E$312,4,) -> CC | F13: 1100 | G13: Discard | H13: Fadli
... A133: 46009 | B133: ORLEAN MEAT | C133: =VLOOKUP(B133,Sheet3!$B$2:$E$312,2,FALSE) -> B001-112 | D133: =VLOOKUP(B133,Sheet3!$B$2:$E$312,3,) -> bahan baku | E133: =VLOOKUP(B133,Sheet3!$B$2:$E$312,4,) -> GR | F133: 157 | G133: Discard | H133: Tegar
A134: 46009 | B134: Topping ayam sambal bali | C134: =VLOOKUP(B134,Sheet3!$B$2:$E$312,2,FALSE) -> #N/A | D134: =VLOOKUP(B134,Sheet3!$B$2:$E$312,3,) -> #N/A | E134: Gr | F134: 495 | G134: Discard | H134: Tegar
A135: 46009 | B135: WIP NASI PUTIH | C135: =VLOOKUP(B135,Sheet3!$B$2:$E$312,2,FALSE) -> P004-013 | D135: =VLOOKUP(B135,Sheet3!$B$2:$E$312,3,) -> barang jadi & bahan baku | E135: =VLOOKUP(B135,Sheet3!$B$2:$E$312,4,) -> PCS | F135: 4 | G135: Discard | H135: Karin
A136: 46009 | B136: AMERICAN FRIES | C136: =VLOOKUP(B136,Sheet3!$B$2:$E$312,2,FALSE) -> S002-007 | D136: =VLOOKUP(B136,Sheet3!$B$2:$E$312,3,) -> barang jadi | E136: =VLOOKUP(B136,Sheet3!$B$2:$E$312,4,) -> PORSI | F136: 1 | G136: Discard | H136: Karin
A137: 46010 | B137: Sosis Sapi | C137: =VLOOKUP(B137,Sheet3!$B$2:$E$312,2,FALSE) -> B001-078 | D137: =VLOOKUP(B137,Sheet3!$B$2:$E$312,3,) -> bahan baku | E137: =VLOOKUP(B137,Sheet3!$B$2:$E$312,4,) -> GR | F137: 76 | G137: Discard | H137: Rosidin
A138: 46010 | B138: Telur | C138: =VLOOKUP(B138,Sheet3!$B$2:$E$312,2,FALSE) -> B001-087 | D138: =VLOOKUP(B138,Sheet3!$B$2:$E$312,3,) -> bahan baku | E138: =VLOOKUP(B138,Sheet3!$B$2:$E$312,4,) -> PCS | F138: 1 | G138: pecah | H138: Rosidin
A139: 46010 | B139: Topping ayam sambal bali | C139: =VLOOKUP(B139,Sheet3!$B$2:$E$312,2,FALSE) -> #N/A | D139: =VLOOKUP(B139,Sheet3!$B$2:$E$312,3,) -> #N/A | E139: Gr | F139: 88 | G139: Discard | H139: Rosidin
A140: 46010 | B140: Telur | C140: =VLOOKUP(B140,Sheet3!$B$2:$E$312,2,FALSE) -> B001-087 | D140: =VLOOKUP(B140,Sheet3!$B$2:$E$312,3,) -> bahan baku | E140: =VLOOKUP(B140,Sheet3!$B$2:$E$312,4,) -> PCS | F140: 1 | G140: Discard | H140: Karin
A141: 46010 | B141: WIP TELUR KOCOK | C141: =VLOOKUP(B141,Sheet3!$B$2:$E$312,2,FALSE) -> P004-014 | D141: =VLOOKUP(B141,Sheet3!$B$2:$E$312,3,) -> barang jadi & bahan baku | E141: =VLOOKUP(B141,Sheet3!$B$2:$E$312,4,) -> GR | F141: 186 | G141: Discard | H141: Karin
A142: 46010 | B142: WIP UNSWEERENED TEA BASE | C142: =VLOOKUP(B142,Sheet3!$B$2:$E$312,2,FALSE) -> #N/A | D142: =VLOOKUP(B142,Sheet3!$B$2:$E$312,3,) -> #N/A | E142: =VLOOKUP(B142,Sheet3!$B$2:$E$312,4,) -> #N/A | F142: 3500 | G142: Discard | H142: Neza
A143: 46010 | B143: WIP GREEN TEA BASE | C143: =VLOOKUP(B143,Sheet3!$B$2:$E$312,2,FALSE) -> P004-023 | D143: =VLOOKUP(B143,Sheet3!$B$2:$E$312,3,) -> barang jadi & bahan baku | E143: =VLOOKUP(B143,Sheet3!$B$2:$E$312,4,) -> CC | F143: 2000 | G143: Discard | H143: Neza
A144: 46010 | B144: WIP LEMON TEA BATCH | C144: =VLOOKUP(B144,Sheet3!$B$2:$E$312,2,FALSE) -> P004-025 | D144: =VLOOKUP(B144,Sheet3!$B$2:$E$312,3,) -> barang jadi & bahan baku | E144: =VLOOKUP(B144,Sheet3!$B$2:$E$312,4,) -> ML | F144: 700 | G144: Discard | H144: Neza
A145: 46010 | B145: WIP RED TEA BASE | C145: =VLOOKUP(B145,Sheet3!$B$2:$E$312,2,FALSE) -> P004-022 | D145: =VLOOKUP(B145,Sheet3!$B$2:$E$312,3,) -> barang jadi & bahan baku | E145: =VLOOKUP(B145,Sheet3!$B$2:$E$312,4,) -> CC | F145: 2500 | G145: Discard | H145: Neza
A146: 46010 | B146: SCRAMBLED EGG | C146: =VLOOKUP(B146,Sheet3!$B$2:$E$312,2,FALSE) -> S001-002 | D146: =VLOOKUP(B146,Sheet3!$B$2:$E$312,3,) -> barang jadi | E146: =VLOOKUP(B146,Sheet3!$B$2:$E$312,4,) -> PORSI | F146: 2 | G146: Discard | H146: Karin
A147: 46010 | B147: WIP NASI PUTIH | C147: =VLOOKUP(B147,Sheet3!$B$2:$E$312,2,FALSE) -> P004-013 | D147: =VLOOKUP(B147,Sheet3!$B$2:$E$312,3,) -> barang jadi & bahan baku | E147: =VLOOKUP(B147,Sheet3!$B$2:$E$312,4,) -> PCS | F147: 13 | G147: Discard | H147: Karin
A148: 46010 | B148: WIP NASI PUTIH | C148: =VLOOKUP(B148,Sheet3!$B$2:$E$312,2,FALSE) -> P004-013 | D148: =VLOOKUP(B148,Sheet3!$B$2:$E$312,3,) -> barang jadi & bahan baku | E148: =VLOOKUP(B148,Sheet3!$B$2:$E$312,4,) -> PCS | F148: 12 | G148: Discard | H148: Karin
A149: 46010 | B149: WIP NASI PUTIH | C149: =VLOOKUP(B149,Sheet3!$B$2:$E$312,2,FALSE) -> P004-013 | D149: =VLOOKUP(B149,Sheet3!$B$2:$E$312,3,) -> barang jadi & bahan baku | E149: =VLOOKUP(B149,Sheet3!$B$2:$E$312,4,) -> PCS | F149: 16 | G149: Discard | H149: Karin
A150: 46011 | B150: WIP MILK FOAM | C150: =VLOOKUP(B150,Sheet3!$B$2:$E$312,2,FALSE) -> P004-020 | D150: =VLOOKUP(B150,Sheet3!$B$2:$E$312,3,) -> barang jadi & bahan baku | E150: =VLOOKUP(B150,Sheet3!$B$2:$E$312,4,) -> GR | F150: 249 | G150: Discard | H150: Neza
A151: 46011 | B151: WIP NASI PUTIH | C151: =VLOOKUP(B151,Sheet3!$B$2:$E$312,2,FALSE) -> P004-013 | D151: =VLOOKUP(B151,Sheet3!$B$2:$E$312,3,) -> barang jadi & bahan baku | E151: =VLOOKUP(B151,Sheet3!$B$2:$E$312,4,) -> PCS | F151: 21 | G151: Discard | H151: Nagof
... A175: 46013 | B175: WIP GREEN TEA BASE | C175: =VLOOKUP(B175,Sheet3!$B$2:$E$312,2,FALSE) -> P004-023 | D175: =VLOOKUP(B175,Sheet3!$B$2:$E$312,3,) -> barang jadi & bahan baku | E175: =VLOOKUP(B175,Sheet3!$B$2:$E$312,4,) -> CC | F175: 3500 | G175: Discard | H175: Neza
A176: 46013 | B176: WIP NASI PUTIH | C176: =VLOOKUP(B176,Sheet3!$B$2:$E$312,2,FALSE) -> P004-013 | D176: =VLOOKUP(B176,Sheet3!$B$2:$E$312,3,) -> barang jadi & bahan baku | E176: =VLOOKUP(B176,Sheet3!$B$2:$E$312,4,) -> PCS | F176: =4680/130 -> 36 | G176: Discard | H176: Karin
A177: 46013 | B177: WIP NASI PUTIH | C177: =VLOOKUP(B177,Sheet3!$B$2:$E$312,2,FALSE) -> P004-013 | D177: =VLOOKUP(B177,Sheet3!$B$2:$E$312,3,) -> barang jadi & bahan baku | E177: =VLOOKUP(B177,Sheet3!$B$2:$E$312,4,) -> PCS | F177: 28 | G177: Discard | H177: Karin
A178: 46013 | B178: WIP TELUR KOCOK | C178: =VLOOKUP(B178,Sheet3!$B$2:$E$312,2,FALSE) -> P004-014 | D178: =VLOOKUP(B178,Sheet3!$B$2:$E$312,3,) -> barang jadi & bahan baku | E178: =VLOOKUP(B178,Sheet3!$B$2:$E$312,4,) -> GR | F178: 285 | G178: Discard | H178: Karin
A179: 46013 | B179: SCRAMBLED EGG | C179: =VLOOKUP(B179,Sheet3!$B$2:$E$312,2,FALSE) -> S001-002 | D179: =VLOOKUP(B179,Sheet3!$B$2:$E$312,3,) -> barang jadi | E179: =VLOOKUP(B179,Sheet3!$B$2:$E$312,4,) -> PORSI | F179: 3 | G179: Discard | H179: Karin
A180: 46013 | B180: AMERICAN FRIES | C180: =VLOOKUP(B180,Sheet3!$B$2:$E$312,2,FALSE) -> S002-007 | D180: =VLOOKUP(B180,Sheet3!$B$2:$E$312,3,) -> barang jadi | E180: =VLOOKUP(B180,Sheet3!$B$2:$E$312,4,) -> PORSI | F180: 1 | G180: Discard | H180: Karin
A181: 46014 | B181: WIP TOPPING AYAM SAMBAL BAWANG | C181: =VLOOKUP(B181,Sheet3!$B$2:$E$312,2,FALSE) -> P004-034 | D181: =VLOOKUP(B181,Sheet3!$B$2:$E$312,3,) -> barang jadi & bahan baku | E181: =VLOOKUP(B181,Sheet3!$B$2:$E$312,4,) -> GR | F181: 454 | G181: Discard | H181: Dendi
A182: 46014 | B182: WIP NASI PUTIH | C182: =VLOOKUP(B182,Sheet3!$B$2:$E$312,2,FALSE) -> P004-013 | D182: =VLOOKUP(B182,Sheet3!$B$2:$E$312,3,) -> barang jadi & bahan baku | E182: =VLOOKUP(B182,Sheet3!$B$2:$E$312,4,) -> PCS | F182: 22 | G182: Discard | H182: Dendi
...

Sheet MARET 26
A1: TANGGAL | B1: NAMA PRODUK | C1: KODE CSA | D1: JENIS | E1: SATUAN CSA | F1: JUMLAH | G1: ALASAN WASTE | H1: USER | I1: audit
A2: 46025 | B2: Chicken Bacon | C2: =VLOOKUP(B2,Sheet3!$B$2:$E$312,2,FALSE) -> B001-023 | D2: =VLOOKUP(B2,Sheet3!$B$2:$E$312,3,) -> bahan baku | E2: =VLOOKUP(B2,Sheet3!$B$2:$E$312,4,) -> GR | F2: 389 | G2: discard | H2: Tegar | I2: v
B3: Tepung Crispy Breading | C3: =VLOOKUP(B3,Sheet3!$B$2:$E$312,2,FALSE) -> B001-088 | D3: =VLOOKUP(B3,Sheet3!$B$2:$E$312,3,) -> bahan baku | E3: =VLOOKUP(B3,Sheet3!$B$2:$E$312,4,) -> GR | F3: 8145 | G3: Bekas Breading | H3: Dani | I3: v
B4: WIP LEMON TEA BATCH | C4: =VLOOKUP(B4,Sheet3!$B$2:$E$312,2,FALSE) -> P004-025 | D4: =VLOOKUP(B4,Sheet3!$B$2:$E$312,3,) -> barang jadi & bahan baku | E4: =VLOOKUP(B4,Sheet3!$B$2:$E$312,4,) -> ML | F4: 700 | G4: discard | H4: Rosidin | I4: v
B5: WIP UNSWEERENED TEA BASE | C5: =VLOOKUP(B5,Sheet3!$B$2:$E$312,2,FALSE) -> #N/A | D5: =VLOOKUP(B5,Sheet3!$B$2:$E$312,3,) -> #N/A | E5: =VLOOKUP(B5,Sheet3!$B$2:$E$312,4,) -> #N/A | F5: 1000 | G5: discard | H5: rosidin | I5: v
B6: WIP NASI PUTIH | C6: =VLOOKUP(B6,Sheet3!$B$2:$E$312,2,FALSE) -> P004-013 | D6: =VLOOKUP(B6,Sheet3!$B$2:$E$312,3,) -> barang jadi & bahan baku | E6: =VLOOKUP(B6,Sheet3!$B$2:$E$312,4,) -> PCS | F6: 10 | G6: sisa/kering | H6: rosidin | I6: x | J6: seharusnya satuan GRAM (1287gr)
B7: SCRAMBLED EGG | C7: =VLOOKUP(B7,Sheet3!$B$2:$E$312,2,FALSE) -> S001-002 | D7: =VLOOKUP(B7,Sheet3!$B$2:$E$312,3,) -> barang jadi | E7: =VLOOKUP(B7,Sheet3!$B$2:$E$312,4,) -> PORSI | F7: 8 | G7: sisa | H7: rosidin | I7: x | J7: 5porsi
B8: FRENCH FRIES | C8: =VLOOKUP(B8,Sheet3!$B$2:$E$312,2,FALSE) -> S002-002 | D8: =VLOOKUP(B8,Sheet3!$B$2:$E$312,3,) -> barang jadi & bahan baku | E8: =VLOOKUP(B8,Sheet3!$B$2:$E$312,4,) -> PORSI | F8: 4 | G8: sisa | H8: rosidin | I8: x | J8: 2porsi
B9: ORIGINAL WING/DRUM STICK | C9: =VLOOKUP(B9,Sheet3!$B$2:$E$312,2,FALSE) -> J001-002 | D9: =VLOOKUP(B9,Sheet3!$B$2:$E$312,3,) -> barang jadi | E9: =VLOOKUP(B9,Sheet3!$B$2:$E$312,4,) -> PORSI | F9: 1 | G9: sisa | H9: rosidin | I9: v
B10: Pisang | C10: =VLOOKUP(B10,Sheet3!$B$2:$E$312,2,FALSE) -> B001-064 | D10: =VLOOKUP(B10,Sheet3!$B$2:$E$312,3,) -> bahan baku | E10: =VLOOKUP(B10,Sheet3!$B$2:$E$312,4,) -> GR | F10: 265 | G10: busuk | H10: neza | I10: v
A11: 46056 | B11: Jeruk Nipis | C11: =VLOOKUP(B11,Sheet3!$B$2:$E$312,2,FALSE) -> B001-047 | D11: =VLOOKUP(B11,Sheet3!$B$2:$E$312,3,) -> bahan baku | E11: =VLOOKUP(B11,Sheet3!$B$2:$E$312,4,) -> GR | F11: 390 | G11: busuk | H11: rifqi | I11: v
B12: WIP SELAI TOAST | C12: =VLOOKUP(B12,Sheet3!$B$2:$E$312,2,FALSE) -> P004-016 | D12: =VLOOKUP(B12,Sheet3!$B$2:$E$312,3,) -> barang jadi & bahan baku | E12: =VLOOKUP(B12,Sheet3!$B$2:$E$312,4,) -> GR | F12: 38 | G12: discard | H12: neza | I12: v
B13: Cabai Rawit Hijau | C13: =VLOOKUP(B13,Sheet3!$B$2:$E$312,2,FALSE) -> B001-018 | D13: =VLOOKUP(B13,Sheet3!$B$2:$E$312,3,) -> bahan baku | E13: =VLOOKUP(B13,Sheet3!$B$2:$E$312,4,) -> GR | F13: 300 | G13: tidak berguna | H13: neza | I13: v
B14: Tepung Crispy Breading | C14: =VLOOKUP(B14,Sheet3!$B$2:$E$312,2,FALSE) -> B001-088 | D14: =VLOOKUP(B14,Sheet3!$B$2:$E$312,3,) -> bahan baku | E14: =VLOOKUP(B14,Sheet3!$B$2:$E$312,4,) -> GR | F14: 4380 | G14: tidak berguna | H14: Dani | I14: v
B15: WIP NASI PUTIH | C15: =VLOOKUP(B15,Sheet3!$B$2:$E$312,2,FALSE) -> P004-013 | D15: =VLOOKUP(B15,Sheet3!$B$2:$E$312,3,) -> barang jadi & bahan baku | E15: =VLOOKUP(B15,Sheet3!$B$2:$E$312,4,) -> PCS | F15: 22 | G15: sisa | H15: Dendi | I15: x | J15: 2760gr
A16: 46084 | B16: WIP LEMON TEA BATCH | C16: =VLOOKUP(B16,Sheet3!$B$2:$E$312,2,FALSE) -> P004-025 | D16: =VLOOKUP(B16,Sheet3!$B$2:$E$312,3,) -> barang jadi & bahan baku | E16: =VLOOKUP(B16,Sheet3!$B$2:$E$312,4,) -> ML | F16: 500 | G16: sisa | I16: v
B17: WIP GREEN TEA BASE | C17: =VLOOKUP(B17,Sheet3!$B$2:$E$312,2,FALSE) -> P004-023 | D17: =VLOOKUP(B17,Sheet3!$B$2:$E$312,3,) -> barang jadi & bahan baku | E17: =VLOOKUP(B17,Sheet3!$B$2:$E$312,4,) -> CC | F17: 1300 | G17: sisa | I17: v
B18: WIP UNSWEERENED TEA BASE | C18: =VLOOKUP(B18,Sheet3!$B$2:$E$312,2,FALSE) -> #N/A | D18: =VLOOKUP(B18,Sheet3!$B$2:$E$312,3,) -> #N/A | E18: =VLOOKUP(B18,Sheet3!$B$2:$E$312,4,) -> #N/A | F18: 1000 | G18: sisa | I18: v
B19: Bawang Bombay | C19: =VLOOKUP(B19,Sheet3!$B$2:$E$312,2,FALSE) -> B001-006 | D19: =VLOOKUP(B19,Sheet3!$B$2:$E$312,3,) -> bahan baku | E19: =VLOOKUP(B19,Sheet3!$B$2:$E$312,4,) -> GR | F19: 100 | G19: tidak berguna | H19: neza | I19: v
B20: WIP TOPING AYAM | C20: =VLOOKUP(B20,Sheet3!$B$2:$E$312,2,FALSE) -> P004-026 | D20: =VLOOKUP(B20,Sheet3!$B$2:$E$312,3,) -> barang jadi & bahan baku | E20: =VLOOKUP(B20,Sheet3!$B$2:$E$312,4,) -> GR | F20: 76 | G20: basi | H20: neza | I20: v
B21: chili sauce | C21: =VLOOKUP(B21,Sheet3!$B$2:$E$312,2,FALSE) -> B001-028 | D21: =VLOOKUP(B21,Sheet3!$B$2:$E$312,3,) -> others | E21: =VLOOKUP(B21,Sheet3!$B$2:$E$312,4,) -> GR | F21: 175 | G21: Basi | H21: David | I21: v
B22: Tepung Crispy Breading | C22: =VLOOKUP(B22,Sheet3!$B$2:$E$312,2,FALSE) -> B001-088 | D22: =VLOOKUP(B22,Sheet3!$B$2:$E$312,3,) -> bahan baku | E22: =VLOOKUP(B22,Sheet3!$B$2:$E$312,4,) -> GR | F22: 3855 | G22: tidak berguna | H22: Dani | I22: v
B23: SCRAMBLED EGG | C23: =VLOOKUP(B23,Sheet3!$B$2:$E$312,2,FALSE) -> S001-002 | D23: =VLOOKUP(B23,Sheet3!$B$2:$E$312,3,) -> barang jadi | E23: =VLOOKUP(B23,Sheet3!$B$2:$E$312,4,) -> PORSI | F23: 9 | G23: sisa | H23: Dendi | I23: x | J23: 5porsi
B24: WIP NASI PUTIH | C24: =VLOOKUP(B24,Sheet3!$B$2:$E$312,2,FALSE) -> P004-013 | D24: =VLOOKUP(B24,Sheet3!$B$2:$E$312,3,) -> barang jadi & bahan baku | E24: =VLOOKUP(B24,Sheet3!$B$2:$E$312,4,) -> PCS | F24: 17 | G24: sisa | H24: Dendi | I24: x | J24: 2215gr
B25: WIP SAUS GOLDEN | C25: =VLOOKUP(B25,Sheet3!$B$2:$E$312,2,FALSE) -> P004-012 | D25: =VLOOKUP(B25,Sheet3!$B$2:$E$312,3,) -> barang jadi & bahan baku | E25: =VLOOKUP(B25,Sheet3!$B$2:$E$312,4,) -> GR | F25: 31 | G25: Basi | H25: tegar | I25: v
B26: WIP LEMON TEA BATCH | C26: =VLOOKUP(B26,Sheet3!$B$2:$E$312,2,FALSE) -> P004-025 | D26: =VLOOKUP(B26,Sheet3!$B$2:$E$312,3,) -> barang jadi & bahan baku | E26: =VLOOKUP(B26,Sheet3!$B$2:$E$312,4,) -> ML | F26: 1250 | G26: discard | H26: rifqi | I26: v
B27: WIP UNSWEERENED TEA BASE | C27: =VLOOKUP(B27,Sheet3!$B$2:$E$312,2,FALSE) -> #N/A | D27: =VLOOKUP(B27,Sheet3!$B$2:$E$312,3,) -> #N/A | E27: =VLOOKUP(B27,Sheet3!$B$2:$E$312,4,) -> #N/A | F27: 300 | G27: discard | H27: rifqi | I27: v
B28: WIP GREEN TEA BASE | C28: =VLOOKUP(B28,Sheet3!$B$2:$E$312,2,FALSE) -> P004-023 | D28: =VLOOKUP(B28,Sheet3!$B$2:$E$312,3,) -> barang jadi & bahan baku | E28: =VLOOKUP(B28,Sheet3!$B$2:$E$312,4,) -> CC | F28: 250 | G28: discard | H28: rifqi | I28: v
B29: WIP RED TEA BASE | C29: =VLOOKUP(B29,Sheet3!$B$2:$E$312,2,FALSE) -> P004-022 | D29: =VLOOKUP(B29,Sheet3!$B$2:$E$312,3,) -> barang jadi & bahan baku | E29: =VLOOKUP(B29,Sheet3!$B$2:$E$312,4,) -> CC | F29: 575 | G29: discard | H29: rifqi | I29: v
A30: 46115 | B30: Daun Mint | C30: =VLOOKUP(B30,Sheet3!$B$2:$E$312,2,FALSE) -> B001-036 | D30: =VLOOKUP(B30,Sheet3!$B$2:$E$312,3,) -> bahan baku | E30: =VLOOKUP(B30,Sheet3!$B$2:$E$312,4,) -> GR | F30: 4 | G30: busuk | H30: rifqi | I30: v
B31: WIP GREEN TEA BASE | C31: =VLOOKUP(B31,Sheet3!$B$2:$E$312,2,FALSE) -> P004-023 | D31: =VLOOKUP(B31,Sheet3!$B$2:$E$312,3,) -> barang jadi & bahan baku | E31: =VLOOKUP(B31,Sheet3!$B$2:$E$312,4,) -> CC | F31: 350 | G31: discard | H31: rifqi | I31: v
B32: WIP LEMON TEA BATCH | D32: =VLOOKUP(B32,Sheet3!$B$2:$E$312,3,) -> barang jadi & bahan baku | E32: =VLOOKUP(B32,Sheet3!$B$2:$E$312,4,) -> ML | F32: 1700 | G32: discard | H32: rifqi | I32: v
B33: Tepung Crispy Breading | C33: =VLOOKUP(B33,Sheet3!$B$2:$E$312,2,FALSE) -> B001-088 | D33: =VLOOKUP(B33,Sheet3!$B$2:$E$312,3,) -> bahan baku | E33: =VLOOKUP(B33,Sheet3!$B$2:$E$312,4,) -> GR | F33: 3450 | G33: tidak berguna | H33: dendi | I33: v
B34: HONEY SAUCE | C34: =VLOOKUP(B34,Sheet3!$B$2:$E$312,2,FALSE) -> B001-129 | D34: =VLOOKUP(B34,Sheet3!$B$2:$E$312,3,) -> bahan baku | E34: =VLOOKUP(B34,Sheet3!$B$2:$E$312,4,) -> GR | F34: 75 | G34: discard | H34: dendi | I34: v
B35: SCRAMBLED EGG | C35: =VLOOKUP(B35,Sheet3!$B$2:$E$312,2,FALSE) -> S001-002 | D35: =VLOOKUP(B35,Sheet3!$B$2:$E$312,3,) -> barang jadi | E35: =VLOOKUP(B35,Sheet3!$B$2:$E$312,4,) -> PORSI | F35: 5 | G35: sisa | H35: dendi | I35: x | J35: 7porsi
B36: Paprika Merah | C36: =VLOOKUP(B36,Sheet3!$B$2:$E$312,2,FALSE) -> B001-061 | D36: =VLOOKUP(B36,Sheet3!$B$2:$E$312,3,) -> bahan baku | E36: =VLOOKUP(B36,Sheet3!$B$2:$E$312,4,) -> GR | F36: 35 | G36: discard | H36: Tegar | I36: v
B37: WIP SELAI TOAST | C37: =VLOOKUP(B37,Sheet3!$B$2:$E$312,2,FALSE) -> P004-016 | D37: =VLOOKUP(B37,Sheet3!$B$2:$E$312,3,) -> barang jadi & bahan baku | E37: =VLOOKUP(B37,Sheet3!$B$2:$E$312,4,) -> GR | F37: 172 | G37: discard | H37: Tegar | I37: v
B38: Japanese Curry | C38: =VLOOKUP(B38,Sheet3!$B$2:$E$312,2,FALSE) -> #N/A | D38: =VLOOKUP(B38,Sheet3!$B$2:$E$312,3,) -> #N/A | E38: =VLOOKUP(B38,Sheet3!$B$2:$E$312,4,) -> #N/A | F38: 74 | G38: discard | H38: Tegar | I38: v
A39: 46145 | B39: MILAN-STYLE TOMATO MEAT SAUCE SPAGHETTI | C39: =VLOOKUP(B39,Sheet3!$B$2:$E$312,2,FALSE) -> P001-001 | D39: =VLOOKUP(B39,Sheet3!$B$2:$E$312,3,) -> barang jadi | E39: =VLOOKUP(B39,Sheet3!$B$2:$E$312,4,) -> PORSI | F39: 1 | G39: discard | I39: v
B40: Pisang | C40: =VLOOKUP(B40,Sheet3!$B$2:$E$312,2,FALSE) -> B001-064 | D40: =VLOOKUP(B40,Sheet3!$B$2:$E$312,3,) -> bahan baku | E40: =VLOOKUP(B40,Sheet3!$B$2:$E$312,4,) -> GR | F40: 643 | G40: busuk | H40: Rifqi | I40: v
...

Sheet JANUARI 26
A1: TANGGAL | B1: NAMA PRODUK | C1: KODE CSA | D1: JENIS | E1: SATUAN CSA | F1: JUMLAH | G1: ALASAN WASTE | H1: USER
A2: 46023 | B2: WIP MILK FOAM | C2: =VLOOKUP(B2,Sheet3!$B$2:$E$312,2,FALSE) -> P004-020 | D2: =VLOOKUP(B2,Sheet3!$B$2:$E$312,3,) -> barang jadi & bahan baku | E2: =VLOOKUP(B2,Sheet3!$B$2:$E$312,4,) -> GR | F2: 300 | G2: discard | H2: amanda
A3: 46023 | B3: HONEY INFERNO WHOLE CHICKEN | C3: =VLOOKUP(B3,Sheet3!$B$2:$E$312,2,FALSE) -> W001-007 | D3: =VLOOKUP(B3,Sheet3!$B$2:$E$312,3,) -> barang jadi | E3: =VLOOKUP(B3,Sheet3!$B$2:$E$312,4,) -> PORSI | F3: 1 | G3: berdarah | H3: tegar
A4: 46023 | B4: CARAMEL EGG TART | C4: =VLOOKUP(B4,Sheet3!$B$2:$E$312,2,FALSE) -> D001-004 | D4: =VLOOKUP(B4,Sheet3!$B$2:$E$312,3,) -> barang jadi | E4: =VLOOKUP(B4,Sheet3!$B$2:$E$312,4,) -> PORSI | F4: 2 | G4: gosong | H4: tegar
A5: 46023 | B5: Mixed Veggies | C5: =VLOOKUP(B5,Sheet3!$B$2:$E$312,2,FALSE) -> B001-057 | D5: =VLOOKUP(B5,Sheet3!$B$2:$E$312,3,) -> bahan baku | E5: =VLOOKUP(B5,Sheet3!$B$2:$E$312,4,) -> GR | F5: 84 | G5: discard | H5: dendi
A6: 46023 | B6: Pisang | C6: =VLOOKUP(B6,Sheet3!$B$2:$E$312,2,FALSE) -> B001-064 | D6: =VLOOKUP(B6,Sheet3!$B$2:$E$312,3,) -> bahan baku | E6: =VLOOKUP(B6,Sheet3!$B$2:$E$312,4,) -> GR | F6: 4 | G6: busuk | H6: dendi
A7: 46023 | B7: WIP NASI PUTIH | C7: =VLOOKUP(B7,Sheet3!$B$2:$E$312,2,FALSE) -> P004-013 | D7: =VLOOKUP(B7,Sheet3!$B$2:$E$312,3,) -> barang jadi & bahan baku | E7: GR | F7: 8710 | G7: Kering | H7: tegar
A8: 46023 | B8: WIP NASI PUTIH | C8: =VLOOKUP(B8,Sheet3!$B$2:$E$312,2,FALSE) -> P004-013 | D8: =VLOOKUP(B8,Sheet3!$B$2:$E$312,3,) -> barang jadi & bahan baku | E8: GR | F8: 3435 | G8: Kering | H8: tegar
A9: 46023 | B9: HONGKONG ICED LEMON TEA (BIG) | C9: =VLOOKUP(B9,Sheet3!$B$2:$E$312,2,FALSE) -> D003-001 | D9: =VLOOKUP(B9,Sheet3!$B$2:$E$312,3,) -> barang jadi | E9: ML | F9: 2800 | G9: discard | H9: dani
A10: 46024 | B10: Pizza Crust | C10: =VLOOKUP(B10,Sheet3!$B$2:$E$312,2,FALSE) -> B001-066 | D10: =VLOOKUP(B10,Sheet3!$B$2:$E$312,3,) -> bahan baku | E10: PCS | F10: 1 | G10: gagal fermentasi | H10: naufal
A11: 46024 | B11: Pizza Crust | C11: =VLOOKUP(B11,Sheet3!$B$2:$E$312,2,FALSE) -> B001-066 | D11: =VLOOKUP(B11,Sheet3!$B$2:$E$312,3,) -> bahan baku | E11: =VLOOKUP(B11,Sheet3!$B$2:$E$312,4,) -> PCS | F11: 1 | G11: gagal fermentasi | H11: neza
A12: 46024 | B12: HONGKONG ICED LEMON TEA (BIG) | C12: =VLOOKUP(B12,Sheet3!$B$2:$E$312,2,FALSE) -> D003-001 | D12: =VLOOKUP(B12,Sheet3!$B$2:$E$312,3,) -> barang jadi | E12: ML | F12: 2500 | G12: waste | H12: dani
A13: 46024 | B13: WIP NASI PUTIH | C13: =VLOOKUP(B13,Sheet3!$B$2:$E$312,2,FALSE) -> P004-013 | D13: =VLOOKUP(B13,Sheet3!$B$2:$E$312,3,) -> barang jadi & bahan baku | E13: GR | F13: 4195 | G13: discard | H13: tegar
A14: 45659 | B14: WIP NASI PUTIH | C14: =VLOOKUP(B14,Sheet3!$B$2:$E$312,2,FALSE) -> P004-013 | D14: =VLOOKUP(B14,Sheet3!$B$2:$E$312,3,) -> barang jadi & bahan baku | E14: GR | F14: 6050 | G14: sisa | H14: tegar
A15: 46024 | B15: Saus Honey Mustard | C15: =VLOOKUP(B15,Sheet3!$B$2:$E$312,2,FALSE) -> B001-043 | D15: =VLOOKUP(B15,Sheet3!$B$2:$E$312,3,) -> bahan baku | E15: =VLOOKUP(B15,Sheet3!$B$2:$E$312,4,) -> GR | F15: 459 | G15: discard | H15: tegar
A16: 46025 | B16: HONGKONG ICED LEMON TEA (BIG) | C16: =VLOOKUP(B16,Sheet3!$B$2:$E$312,2,FALSE) -> D003-001 | D16: =VLOOKUP(B16,Sheet3!$B$2:$E$312,3,) -> barang jadi | E16: ML | F16: 1800 | G16: waste | H16: dani
A17: 46025 | B17: Mixed Veggies | C17: =VLOOKUP(B17,Sheet3!$B$2:$E$312,2,FALSE) -> B001-057 | D17: =VLOOKUP(B17,Sheet3!$B$2:$E$312,3,) -> bahan baku | E17: =VLOOKUP(B17,Sheet3!$B$2:$E$312,4,) -> GR | F17: 64 | G17: waste | H17: dendi
A18: 46025 | B18: Ayam Original Parting 9 | C18: =VLOOKUP(B18,Sheet3!$B$2:$E$312,2,FALSE) -> B001-004 | D18: =VLOOKUP(B18,Sheet3!$B$2:$E$312,3,) -> bahan baku | E18: =VLOOKUP(B18,Sheet3!$B$2:$E$312,4,) -> PCS | F18: 3 | G18: waste | H18: tegar
A19: 46025 | B19: WIP NASI PUTIH | C19: =VLOOKUP(B19,Sheet3!$B$2:$E$312,2,FALSE) -> P004-013 | D19: =VLOOKUP(B19,Sheet3!$B$2:$E$312,3,) -> barang jadi & bahan baku | E19: GR | F19: 4925 | G19: waste | H19: tegar
A20: 46026 | B20: WIP NASI PUTIH | C20: =VLOOKUP(B20,Sheet3!$B$2:$E$312,2,FALSE) -> P004-013 | D20: =VLOOKUP(B20,Sheet3!$B$2:$E$312,3,) -> barang jadi & bahan baku | E20: GR | F20: 3905 | G20: waste | H20: tegar
A21: 46026 | B21: WIP NASI PUTIH | C21: =VLOOKUP(B21,Sheet3!$B$2:$E$312,2,FALSE) -> P004-013 | D21: =VLOOKUP(B21,Sheet3!$B$2:$E$312,3,) -> barang jadi & bahan baku | E21: GR | F21: 7500 | G21: waste | H21: tegar
A22: 46026 | B22: Ayam Original Parting 9 | C22: =VLOOKUP(B22,Sheet3!$B$2:$E$312,2,FALSE) -> B001-004 | D22: =VLOOKUP(B22,Sheet3!$B$2:$E$312,3,) -> bahan baku | E22: =VLOOKUP(B22,Sheet3!$B$2:$E$312,4,) -> PCS | F22: 2 | G22: waste | H22: tegar
A23: 46027 | B23: Ayam Original Parting 9 | C23: =VLOOKUP(B23,Sheet3!$B$2:$E$312,2,FALSE) -> B001-004 | D23: =VLOOKUP(B23,Sheet3!$B$2:$E$312,3,) -> bahan baku | E23: =VLOOKUP(B23,Sheet3!$B$2:$E$312,4,) -> PCS | F23: 2 | G23: waste | H23: tegar
A24: 46027 | B24: UNSWEETENED TEA | C24: =VLOOKUP(B24,Sheet3!$B$2:$E$312,2,FALSE) -> D003-003 | D24: =VLOOKUP(B24,Sheet3!$B$2:$E$312,3,) -> barang jadi | E24: GR | F24: 649 | G24: double order | H24: rosidin
A25: 46027 | B25: HONGKONG ICED LEMON TEA (BIG) | C25: =VLOOKUP(B25,Sheet3!$B$2:$E$312,2,FALSE) -> D003-001 | D25: =VLOOKUP(B25,Sheet3!$B$2:$E$312,3,) -> barang jadi | E25: ML | F25: 2250 | G25: waste | H25: rosidin
A26: 46027 | B26: WIP RED TEA BASE | C26: =VLOOKUP(B26,Sheet3!$B$2:$E$312,2,FALSE) -> P004-022 | D26: =VLOOKUP(B26,Sheet3!$B$2:$E$312,3,) -> barang jadi & bahan baku | E26: ML | F26: 300 | G26: waste | H26: rosidin
A27: 46027 | B27: UNSWEETENED TEA | C27: =VLOOKUP(B27,Sheet3!$B$2:$E$312,2,FALSE) -> D003-003 | D27: =VLOOKUP(B27,Sheet3!$B$2:$E$312,3,) -> barang jadi | E27: ML | F27: 2000 | G27: waste | H27: rosidin
A28: 46027 | B28: WIP SAUS SUSU | C28: =VLOOKUP(B28,Sheet3!$B$2:$E$312,2,FALSE) -> P004-011 | D28: =VLOOKUP(B28,Sheet3!$B$2:$E$312,3,) -> barang jadi & bahan baku | E28: =VLOOKUP(B28,Sheet3!$B$2:$E$312,4,) -> GR | F28: 76 | G28: discard | H28: nagop
A29: 46027 | B29: WIP TELUR KOCOK | C29: =VLOOKUP(B29,Sheet3!$B$2:$E$312,2,FALSE) -> P004-014 | D29: =VLOOKUP(B29,Sheet3!$B$2:$E$312,3,) -> barang jadi & bahan baku | E29: =VLOOKUP(B29,Sheet3!$B$2:$E$312,4,) -> GR | F29: 138 | G29: discard | H29: nagop
A30: 46027 | B30: WIP GREEN TEA BASE | C30: =VLOOKUP(B30,Sheet3!$B$2:$E$312,2,FALSE) -> P004-023 | D30: =VLOOKUP(B30,Sheet3!$B$2:$E$312,3,) -> barang jadi & bahan baku | E30: ML | F30: 1200 | G30: waste | H30: rosidin
A31: 46027 | B31: CONE ICE CREAM | C31: =VLOOKUP(B31,Sheet3!$B$2:$E$312,2,FALSE) -> I001-001 | D31: =VLOOKUP(B31,Sheet3!$B$2:$E$312,3,) -> barang jadi & bahan baku | E31: =VLOOKUP(B31,Sheet3!$B$2:$E$312,4,) -> PORSI | F31: 3 | G31: rusak | H31: rosidin
A32: 45663 | B32: Fish Steak | D32: =VLOOKUP(B32,Sheet3!$B$2:$E$312,3,) -> bahan baku | E32: =VLOOKUP(B32,Sheet3!$B$2:$E$312,4,) -> PCS | F32: 4 | G32: busuk | H32: putra
A33: 45663 | B33: BURGER BUN | C33: =VLOOKUP(B33,Sheet3!$B$2:$E$312,2,FALSE) -> B001-123 | D33: =VLOOKUP(B33,Sheet3!$B$2:$E$312,3,) -> bahan baku | E33: =VLOOKUP(B33,Sheet3!$B$2:$E$312,4,) -> PCS | F33: 2 | G33: berjamur | H33: neza
A34: 45663 | B34: BURGER BUN | C34: =VLOOKUP(B34,Sheet3!$B$2:$E$312,2,FALSE) -> B001-123 | D34: =VLOOKUP(B34,Sheet3!$B$2:$E$312,3,) -> bahan baku | E34: =VLOOKUP(B34,Sheet3!$B$2:$E$312,4,) -> PCS | F34: 1 | G34: gagal conveyor oven | H34: fadli
A35: 45663 | B35: Daun Mint | C35: =VLOOKUP(B35,Sheet3!$B$2:$E$312,2,FALSE) -> B001-036 | D35: =VLOOKUP(B35,Sheet3!$B$2:$E$312,3,) -> bahan baku | E35: =VLOOKUP(B35,Sheet3!$B$2:$E$312,4,) -> GR | F35: 68 | G35: rusak / kering | H35: rifki
A36: 46028 | B36: Ayam Original Parting 9 | C36: =VLOOKUP(B36,Sheet3!$B$2:$E$312,2,FALSE) -> B001-004 | D36: =VLOOKUP(B36,Sheet3!$B$2:$E$312,3,) -> bahan baku | E36: =VLOOKUP(B36,Sheet3!$B$2:$E$312,4,) -> PCS | F36: 2 | G36: busuk / bau | H36: putra
A37: 46028 | B37: SELADA / LETTUCE | C37: =VLOOKUP(B37,Sheet3!$B$2:$E$312,2,FALSE) -> B001-125 | D37: =VLOOKUP(B37,Sheet3!$B$2:$E$312,3,) -> bahan baku | E37: =VLOOKUP(B37,Sheet3!$B$2:$E$312,4,) -> GR | F37: 31 | G37: busuk | H37: putra
A38: 46028 | B38: Paprika Hijau | C38: =VLOOKUP(B38,Sheet3!$B$2:$E$312,2,FALSE) -> B001-060 | D38: =VLOOKUP(B38,Sheet3!$B$2:$E$312,3,) -> bahan baku | E38: =VLOOKUP(B38,Sheet3!$B$2:$E$312,4,) -> GR | F38: 10 | G38: sudah tidak layak | H38: putra
A39: 46028 | B39: Pizza Crust | C39: =VLOOKUP(B39,Sheet3!$B$2:$E$312,2,FALSE) -> B001-066 | D39: =VLOOKUP(B39,Sheet3!$B$2:$E$312,3,) -> bahan baku | E39: =VLOOKUP(B39,Sheet3!$B$2:$E$312,4,) -> PCS | F39: 1 | G39: gagal fermentasi | H39: putra
A40: 46028 | B40: WIP RED TEA BASE | C40: =VLOOKUP(B40,Sheet3!$B$2:$E$312,2,FALSE) -> P004-022 | D40: =VLOOKUP(B40,Sheet3!$B$2:$E$312,3,) -> barang jadi & bahan baku | E40: ML | F40: 2000 | G40: dibuang | H40: rifki
...

Sheet APRIL 26
B1: NAMA PRODUK | C1: KODE CSA | D1: JENIS | E1: SATUAN CSA | F1: JUMLAH | G1: ALASAN WASTE | H1: USER | I1: AUDIT | J1: KETERANGAN
A2: 46113 | B2: SELADA / LETTUCE | C2: =VLOOKUP(B2,Sheet3!$B$2:$E$312,2,FALSE) -> B001-125 | D2: =VLOOKUP(B2,Sheet3!$B$2:$E$312,3,) -> bahan baku | E2: =VLOOKUP(B2,Sheet3!$B$2:$E$312,4,) -> GR | F2: 62 | G2: tidak digunakan | H2: tegar | I2: V
B3: Tepung Crispy Breading | C3: =VLOOKUP(B3,Sheet3!$B$2:$E$312,2,FALSE) -> B001-088 | D3: =VLOOKUP(B3,Sheet3!$B$2:$E$312,3,) -> bahan baku | E3: =VLOOKUP(B3,Sheet3!$B$2:$E$312,4,) -> GR | F3: 3380 | G3: tidak digunakan | H3: arul | I3: V
B4: WIP RED TEA BASE | C4: =VLOOKUP(B4,Sheet3!$B$2:$E$312,2,FALSE) -> P004-022 | D4: =VLOOKUP(B4,Sheet3!$B$2:$E$312,3,) -> barang jadi & bahan baku | E4: =VLOOKUP(B4,Sheet3!$B$2:$E$312,4,) -> CC | F4: 1900 | G4: sisa | H4: manda | I4: V
B5: WIP GREEN TEA BASE | C5: =VLOOKUP(B5,Sheet3!$B$2:$E$312,2,FALSE) -> P004-023 | D5: =VLOOKUP(B5,Sheet3!$B$2:$E$312,3,) -> barang jadi & bahan baku | E5: =VLOOKUP(B5,Sheet3!$B$2:$E$312,4,) -> CC | F5: 2500 | G5: sisa | H5: manda | I5: V
B6: WIP LEMON TEA BATCH | C6: =VLOOKUP(B6,Sheet3!$B$2:$E$312,2,FALSE) -> P004-025 | D6: =VLOOKUP(B6,Sheet3!$B$2:$E$312,3,) -> barang jadi & bahan baku | E6: =VLOOKUP(B6,Sheet3!$B$2:$E$312,4,) -> ML | F6: 300 | G6: sisa | H6: manda | I6: V
B7: WIP NASI PUTIH | C7: =VLOOKUP(B7,Sheet3!$B$2:$E$312,2,FALSE) -> P004-013 | D7: =VLOOKUP(B7,Sheet3!$B$2:$E$312,3,) -> barang jadi & bahan baku | E7: =VLOOKUP(B7,Sheet3!$B$2:$E$312,4,) -> PCS | F7: 12 | G7: sisa | H7: dendi | I7: X | J7: 12PORSI
A8: 46057 | B8: WIP MATCHA ICE CREAM | C8: =VLOOKUP(B8,Sheet3!$B$2:$E$312,2,FALSE) -> P004-036 | D8: =VLOOKUP(B8,Sheet3!$B$2:$E$312,3,) -> barang jadi & bahan baku | E8: =VLOOKUP(B8,Sheet3!$B$2:$E$312,4,) -> GR | F8: 3700 | G8: discard | H8: syendi | I8: V
B9: WIP PREP. VANILLA ICE CREAM | C9: =VLOOKUP(B9,Sheet3!$B$2:$E$312,2,FALSE) -> P004-031 | D9: =VLOOKUP(B9,Sheet3!$B$2:$E$312,3,) -> barang jadi & bahan baku | E9: =VLOOKUP(B9,Sheet3!$B$2:$E$312,4,) -> GR | F9: 350 | G9: discard | H9: syendi | I9: V
B10: WIP RED TEA BASE | C10: =VLOOKUP(B10,Sheet3!$B$2:$E$312,2,FALSE) -> P004-022 | D10: =VLOOKUP(B10,Sheet3!$B$2:$E$312,3,) -> barang jadi & bahan baku | E10: =VLOOKUP(B10,Sheet3!$B$2:$E$312,4,) -> CC | F10: 1500 | G10: discrad | H10: syendi | I10: V
B11: WIP GREEN TEA BASE | C11: =VLOOKUP(B11,Sheet3!$B$2:$E$312,2,FALSE) -> P004-023 | D11: =VLOOKUP(B11,Sheet3!$B$2:$E$312,3,) -> barang jadi & bahan baku | E11: =VLOOKUP(B11,Sheet3!$B$2:$E$312,4,) -> CC | F11: 1600 | G11: discard | H11: syendi | I11: V
B12: WIP LEMON TEA BATCH | C12: =VLOOKUP(B12,Sheet3!$B$2:$E$312,2,FALSE) -> P004-025 | D12: =VLOOKUP(B12,Sheet3!$B$2:$E$312,3,) -> barang jadi & bahan baku | E12: =VLOOKUP(B12,Sheet3!$B$2:$E$312,4,) -> ML | F12: 2600 | G12: discard | H12: syendi | I12: V
B13: Tepung Crispy Breading | C13: =VLOOKUP(B13,Sheet3!$B$2:$E$312,2,FALSE) -> B001-088 | D13: =VLOOKUP(B13,Sheet3!$B$2:$E$312,3,) -> bahan baku | E13: =VLOOKUP(B13,Sheet3!$B$2:$E$312,4,) -> GR | F13: 5200 | G13: tidak digunakan | H13: david | I13: V
B14: AMERICAN FRIES | C14: =VLOOKUP(B14,Sheet3!$B$2:$E$312,2,FALSE) -> S002-007 | D14: =VLOOKUP(B14,Sheet3!$B$2:$E$312,3,) -> barang jadi | E14: =VLOOKUP(B14,Sheet3!$B$2:$E$312,4,) -> PORSI | F14: 1 | G14: sisa | H14: david | I14: V
B15: WIP NASI PUTIH | C15: =VLOOKUP(B15,Sheet3!$B$2:$E$312,2,FALSE) -> P004-013 | D15: =VLOOKUP(B15,Sheet3!$B$2:$E$312,3,) -> barang jadi & bahan baku | E15: =VLOOKUP(B15,Sheet3!$B$2:$E$312,4,) -> PCS | F15: 17 | G15: sisa | H15: dendi | I15: V | K15: =2220/130 -> 17.076923
B16: Bawang Bombay | C16: =VLOOKUP(B16,Sheet3!$B$2:$E$312,2,FALSE) -> B001-006 | D16: =VLOOKUP(B16,Sheet3!$B$2:$E$312,3,) -> bahan baku | E16: =VLOOKUP(B16,Sheet3!$B$2:$E$312,4,) -> GR | F16: 25 | G16: tidak digunakan | H16: riki | I16: V
B17: Pisang | C17: =VLOOKUP(B17,Sheet3!$B$2:$E$312,2,FALSE) -> B001-064 | D17: =VLOOKUP(B17,Sheet3!$B$2:$E$312,3,) -> bahan baku | E17: =VLOOKUP(B17,Sheet3!$B$2:$E$312,4,) -> GR | F17: 42 | G17: tidak digunakan | H17: riki | I17: V
B18: WIP BURGER BUN | C18: =VLOOKUP(B18,Sheet3!$B$2:$E$312,2,FALSE) -> P004-038 | D18: =VLOOKUP(B18,Sheet3!$B$2:$E$312,3,) -> barang jadi & bahan baku | E18: =VLOOKUP(B18,Sheet3!$B$2:$E$312,4,) -> PCS | F18: 1 | G18: tidak mengembang | H18: riki | I18: V
A19: 46085 | B19: WIP UNSWEERENED TEA BASE | C19: =VLOOKUP(B19,Sheet3!$B$2:$E$312,2,FALSE) -> #N/A | D19: =VLOOKUP(B19,Sheet3!$B$2:$E$312,3,) -> #N/A | E19: =VLOOKUP(B19,Sheet3!$B$2:$E$312,4,) -> #N/A | F19: 3000 | G19: sisa | H19: putra | I19: V
B20: WIP RED TEA BASE | C20: =VLOOKUP(B20,Sheet3!$B$2:$E$312,2,FALSE) -> P004-022 | D20: =VLOOKUP(B20,Sheet3!$B$2:$E$312,3,) -> barang jadi & bahan baku | E20: =VLOOKUP(B20,Sheet3!$B$2:$E$312,4,) -> CC | F20: 1500 | G20: sisa | H20: putra | I20: V
B21: WIP GREEN TEA BASE | C21: =VLOOKUP(B21,Sheet3!$B$2:$E$312,2,FALSE) -> P004-023 | D21: =VLOOKUP(B21,Sheet3!$B$2:$E$312,3,) -> barang jadi & bahan baku | E21: =VLOOKUP(B21,Sheet3!$B$2:$E$312,4,) -> CC | F21: 1500 | G21: sisa | H21: putra | I21: V
B22: WIP LEMON TEA BATCH | C22: =VLOOKUP(B22,Sheet3!$B$2:$E$312,2,FALSE) -> P004-025 | D22: =VLOOKUP(B22,Sheet3!$B$2:$E$312,3,) -> barang jadi & bahan baku | E22: =VLOOKUP(B22,Sheet3!$B$2:$E$312,4,) -> ML | F22: 580 | G22: sisa | H22: putra | I22: V
B23: AMERICAN FRIES | C23: =VLOOKUP(B23,Sheet3!$B$2:$E$312,2,FALSE) -> S002-007 | D23: =VLOOKUP(B23,Sheet3!$B$2:$E$312,3,) -> barang jadi | E23: =VLOOKUP(B23,Sheet3!$B$2:$E$312,4,) -> PORSI | F23: 1 | G23: sisa | H23: neza | I23: X | J23: 1PORSI
B24: SCRAMBLED EGG | C24: =VLOOKUP(B24,Sheet3!$B$2:$E$312,2,FALSE) -> S001-002 | D24: =VLOOKUP(B24,Sheet3!$B$2:$E$312,3,) -> barang jadi | E24: =VLOOKUP(B24,Sheet3!$B$2:$E$312,4,) -> PORSI | F24: 2 | G24: sisa | H24: neza | I24: X | J24: 2PORSI
B25: WIP NASI PUTIH | C25: =VLOOKUP(B25,Sheet3!$B$2:$E$312,2,FALSE) -> P004-013 | D25: =VLOOKUP(B25,Sheet3!$B$2:$E$312,3,) -> barang jadi & bahan baku | E25: =VLOOKUP(B25,Sheet3!$B$2:$E$312,4,) -> PCS | F25: 20 | G25: sisa | H25: neza | I25: V
B26: Mixed Veggies | C26: =VLOOKUP(B26,Sheet3!$B$2:$E$312,2,FALSE) -> B001-057 | D26: =VLOOKUP(B26,Sheet3!$B$2:$E$312,3,) -> bahan baku | E26: =VLOOKUP(B26,Sheet3!$B$2:$E$312,4,) -> GR | F26: 235 | G26: basi | H26: tegar | I26: V
B27: Tepung Crispy Breading | C27: =VLOOKUP(B27,Sheet3!$B$2:$E$312,2,FALSE) -> B001-088 | D27: =VLOOKUP(B27,Sheet3!$B$2:$E$312,3,) -> bahan baku | E27: =VLOOKUP(B27,Sheet3!$B$2:$E$312,4,) -> GR | F27: 7760 | G27: tidak digunakan | H27: david | I27: V
B28: Daun Mint | C28: =VLOOKUP(B28,Sheet3!$B$2:$E$312,2,FALSE) -> B001-036 | D28: =VLOOKUP(B28,Sheet3!$B$2:$E$312,3,) -> bahan baku | E28: =VLOOKUP(B28,Sheet3!$B$2:$E$312,4,) -> GR | F28: 9 | G28: menghitam | H28: manda | I28: V
A29: 46116 | B29: Daun Mint | C29: =VLOOKUP(B29,Sheet3!$B$2:$E$312,2,FALSE) -> B001-036 | D29: =VLOOKUP(B29,Sheet3!$B$2:$E$312,3,) -> bahan baku | E29: =VLOOKUP(B29,Sheet3!$B$2:$E$312,4,) -> GR | F29: 5 | G29: menghitam | H29: manda | I29: V
B30: Jeruk Nipis | C30: =VLOOKUP(B30,Sheet3!$B$2:$E$312,2,FALSE) -> B001-047 | D30: =VLOOKUP(B30,Sheet3!$B$2:$E$312,3,) -> bahan baku | E30: =VLOOKUP(B30,Sheet3!$B$2:$E$312,4,) -> GR | F30: 67 | G30: discard | H30: syendi | I30: V
B31: WIP RED TEA BASE | C31: =VLOOKUP(B31,Sheet3!$B$2:$E$312,2,FALSE) -> P004-022 | D31: =VLOOKUP(B31,Sheet3!$B$2:$E$312,3,) -> barang jadi & bahan baku | E31: =VLOOKUP(B31,Sheet3!$B$2:$E$312,4,) -> CC | F31: 788 | G31: sisa | H31: syendi | I31: V
B32: WIP GREEN TEA BASE | C32: =VLOOKUP(B32,Sheet3!$B$2:$E$312,2,FALSE) -> P004-023 | D32: =VLOOKUP(B32,Sheet3!$B$2:$E$312,3,) -> barang jadi & bahan baku | E32: =VLOOKUP(B32,Sheet3!$B$2:$E$312,4,) -> CC | F32: 2151 | G32: sisa | H32: syendi | I32: V
B33: WIP LEMON TEA BATCH | C33: =VLOOKUP(B33,Sheet3!$B$2:$E$312,2,FALSE) -> P004-025 | D33: =VLOOKUP(B33,Sheet3!$B$2:$E$312,3,) -> barang jadi & bahan baku | E33: =VLOOKUP(B33,Sheet3!$B$2:$E$312,4,) -> ML | F33: 1074 | G33: sisa | H33: syendi | I33: V
B34: WIP UNSWEERENED TEA BASE | C34: =VLOOKUP(B34,Sheet3!$B$2:$E$312,2,FALSE) -> #N/A | D34: =VLOOKUP(B34,Sheet3!$B$2:$E$312,3,) -> #N/A | E34: =VLOOKUP(B34,Sheet3!$B$2:$E$312,4,) -> #N/A | F34: 1545 | G34: sisa | H34: syendi | I34: V
B35: Cone | C35: =VLOOKUP(B35,Sheet3!$B$2:$E$312,2,FALSE) -> B001-033 | D35: =VLOOKUP(B35,Sheet3!$B$2:$E$312,3,) -> bahan baku | E35: =VLOOKUP(B35,Sheet3!$B$2:$E$312,4,) -> PCS | F35: 29 | G35: remuk | H35: syendi | I35: X | J35: 29PCS
B36: Campuran Orange | C36: =VLOOKUP(B36,Sheet3!$B$2:$E$312,2,FALSE) -> #N/A | D36: =VLOOKUP(B36,Sheet3!$B$2:$E$312,3,) -> #N/A | E36: =VLOOKUP(B36,Sheet3!$B$2:$E$312,4,) -> #N/A | F36: 293gr | G36: sisa | H36: syendi | I36: V
B37: WIP NASI PUTIH | C37: =VLOOKUP(B37,Sheet3!$B$2:$E$312,2,FALSE) -> P004-013 | D37: =VLOOKUP(B37,Sheet3!$B$2:$E$312,3,) -> barang jadi & bahan baku | E37: =VLOOKUP(B37,Sheet3!$B$2:$E$312,4,) -> PCS | F37: 15 | G37: sisa | H37: neza | I37: V
B38: SCRAMBLED EGG | C38: =VLOOKUP(B38,Sheet3!$B$2:$E$312,2,FALSE) -> S001-002 | D38: =VLOOKUP(B38,Sheet3!$B$2:$E$312,3,) -> barang jadi | E38: =VLOOKUP(B38,Sheet3!$B$2:$E$312,4,) -> PORSI | F38: 4 | G38: sisa | H38: neza | I38: V
B39: Tepung Crispy Breading | C39: =VLOOKUP(B39,Sheet3!$B$2:$E$312,2,FALSE) -> B001-088 | D39: =VLOOKUP(B39,Sheet3!$B$2:$E$312,3,) -> bahan baku | E39: =VLOOKUP(B39,Sheet3!$B$2:$E$312,4,) -> GR | F39: 12760 | G39: sisa tapisan | H39: tegar | I39: V
A40: 46146 | B40: WIP RED TEA BASE | C40: =VLOOKUP(B40,Sheet3!$B$2:$E$312,2,FALSE) -> P004-022 | D40: =VLOOKUP(B40,Sheet3!$B$2:$E$312,3,) -> barang jadi & bahan baku | E40: =VLOOKUP(B40,Sheet3!$B$2:$E$312,4,) -> CC | F40: 483 | G40: discard | H40: syendi | I40: V
...

Sheet MEI 26
A1: TANGGAL | B1: NAMA PRODUK | C1: KODE CSA | D1: JENIS | E1: SATUAN CSA | F1: JUMLAH | G1: ALASAN WASTE | H1: USER | I1: koreksi audit
A2: 46027 | B2: WIP MILK FOAM | C2: =VLOOKUP(B2,Sheet3!$B$2:$E$312,2,FALSE) -> P004-020 | D2: =VLOOKUP(B2,Sheet3!$B$2:$E$312,3,) -> barang jadi & bahan baku | E2: =VLOOKUP(B2,Sheet3!$B$2:$E$312,4,) -> GR | F2: 300 | G2: discard | H2: david | I2: v
B3: Cabai Rawit Merah | C3: =VLOOKUP(B3,Sheet3!$B$2:$E$312,2,FALSE) -> B001-019 | D3: =VLOOKUP(B3,Sheet3!$B$2:$E$312,3,) -> bahan baku | E3: =VLOOKUP(B3,Sheet3!$B$2:$E$312,4,) -> GR | F3: 100 | G3: tangkai cabe | H3: rina | I3: v
B4: Bawang Bombay | C4: =VLOOKUP(B4,Sheet3!$B$2:$E$312,2,FALSE) -> B001-006 | D4: =VLOOKUP(B4,Sheet3!$B$2:$E$312,3,) -> bahan baku | E4: =VLOOKUP(B4,Sheet3!$B$2:$E$312,4,) -> GR | F4: 23 | G4: kulit bawang | H4: rina | I4: v
B5: Mixed Veggies | C5: =VLOOKUP(B5,Sheet3!$B$2:$E$312,2,FALSE) -> B001-057 | D5: =VLOOKUP(B5,Sheet3!$B$2:$E$312,3,) -> bahan baku | E5: =VLOOKUP(B5,Sheet3!$B$2:$E$312,4,) -> GR | F5: 509 | G5: discard | H5: rina | I5: v
B6: WIP UNSWEERENED TEA BASE | C6: =VLOOKUP(B6,Sheet3!$B$2:$E$312,2,FALSE) -> #N/A | D6: =VLOOKUP(B6,Sheet3!$B$2:$E$312,3,) -> #N/A | E6: =VLOOKUP(B6,Sheet3!$B$2:$E$312,4,) -> #N/A | F6: 2468 | G6: sisa | H6: david | I6: v
B7: WIP LEMON TEA BATCH | C7: =VLOOKUP(B7,Sheet3!$B$2:$E$312,2,FALSE) -> P004-025 | D7: =VLOOKUP(B7,Sheet3!$B$2:$E$312,3,) -> barang jadi & bahan baku | E7: =VLOOKUP(B7,Sheet3!$B$2:$E$312,4,) -> ML | F7: 1021 | G7: sisa | H7: david | I7: v
B8: WIP RED TEA BASE | C8: =VLOOKUP(B8,Sheet3!$B$2:$E$312,2,FALSE) -> P004-022 | D8: =VLOOKUP(B8,Sheet3!$B$2:$E$312,3,) -> barang jadi & bahan baku | E8: =VLOOKUP(B8,Sheet3!$B$2:$E$312,4,) -> CC | F8: 1891 | G8: sisa | H8: david | I8: v
B9: WIP GREEN TEA BASE | C9: =VLOOKUP(B9,Sheet3!$B$2:$E$312,2,FALSE) -> P004-023 | D9: =VLOOKUP(B9,Sheet3!$B$2:$E$312,3,) -> barang jadi & bahan baku | E9: =VLOOKUP(B9,Sheet3!$B$2:$E$312,4,) -> CC | F9: 1992 | G9: sisa | H9: david | I9: v
B10: Gelas Plastik 500ML | C10: =VLOOKUP(B10,Sheet3!$B$2:$E$312,2,FALSE) -> B002-005 | D10: =VLOOKUP(B10,Sheet3!$B$2:$E$312,3,) -> others | E10: =VLOOKUP(B10,Sheet3!$B$2:$E$312,4,) -> PCS | F10: 44 | G10: kurang gelas | H10: david | I10: v
B11: SCRAMBLED EGG | C11: =VLOOKUP(B11,Sheet3!$B$2:$E$312,2,FALSE) -> S001-002 | D11: =VLOOKUP(B11,Sheet3!$B$2:$E$312,3,) -> barang jadi | E11: =VLOOKUP(B11,Sheet3!$B$2:$E$312,4,) -> PORSI | F11: 4 | G11: sisa | H11: neza | I11: v
B12: Beras 25KG | C12: =VLOOKUP(B12,Sheet3!$B$2:$E$312,2,FALSE) -> B001-008 | D12: =VLOOKUP(B12,Sheet3!$B$2:$E$312,3,) -> bahan baku | E12: =VLOOKUP(B12,Sheet3!$B$2:$E$312,4,) -> GR | F12: =1117 -> 1117 | G12: sisa nasi | H12: neza | I12: v
B13: Minyak Makan | C13: =VLOOKUP(B13,Sheet3!$B$2:$E$312,2,FALSE) -> B001-056 | D13: =VLOOKUP(B13,Sheet3!$B$2:$E$312,3,) -> bahan baku | E13: =VLOOKUP(B13,Sheet3!$B$2:$E$312,4,) -> ML | F13: 11 | G13: sisa nasi | H13: neza | I13: v
B14: SHOESTRING FRENCH FRIES | C14: =VLOOKUP(B14,Sheet3!$B$2:$E$312,2,FALSE) -> B001-002 | D14: =VLOOKUP(B14,Sheet3!$B$2:$E$312,3,) -> bahan baku | E14: =VLOOKUP(B14,Sheet3!$B$2:$E$312,4,) -> GR | F14: 209 | G14: sisa | H14: neza | I14: v
A15: 46058 | B15: Beras 25KG | C15: =VLOOKUP(B15,Sheet3!$B$2:$E$312,2,FALSE) -> B001-008 | D15: =VLOOKUP(B15,Sheet3!$B$2:$E$312,3,) -> bahan baku | E15: =VLOOKUP(B15,Sheet3!$B$2:$E$312,4,) -> GR | F15: =1859 -> 1859 | G15: sisa nasi | H15: neza | I15: x (1859)
B16: Minyak Makan | C16: =VLOOKUP(B16,Sheet3!$B$2:$E$312,2,FALSE) -> B001-056 | D16: =VLOOKUP(B16,Sheet3!$B$2:$E$312,3,) -> bahan baku | E16: =VLOOKUP(B16,Sheet3!$B$2:$E$312,4,) -> ML | F16: 19 | G16: sisa nasi | H16: neza | I16: x (19)
B17: SCRAMBLED EGG | C17: =VLOOKUP(B17,Sheet3!$B$2:$E$312,2,FALSE) -> S001-002 | D17: =VLOOKUP(B17,Sheet3!$B$2:$E$312,3,) -> barang jadi | E17: =VLOOKUP(B17,Sheet3!$B$2:$E$312,4,) -> PORSI | F17: 10 | G17: sisa | H17: neza | I17: x ( 9 porsi)
B18: WIP GREEN TEA BASE | C18: =VLOOKUP(B18,Sheet3!$B$2:$E$312,2,FALSE) -> P004-023 | D18: =VLOOKUP(B18,Sheet3!$B$2:$E$312,3,) -> barang jadi & bahan baku | E18: =VLOOKUP(B18,Sheet3!$B$2:$E$312,4,) -> CC | F18: 1372 | G18: sisa | H18: rina | I18: v
B19: Cabai Rawit Hijau | C19: =VLOOKUP(B19,Sheet3!$B$2:$E$312,2,FALSE) -> B001-018 | D19: =VLOOKUP(B19,Sheet3!$B$2:$E$312,3,) -> bahan baku | E19: =VLOOKUP(B19,Sheet3!$B$2:$E$312,4,) -> GR | F19: 63 | G19: sisa | H19: puput | I19: v
B20: Paprika Hijau | C20: =VLOOKUP(B20,Sheet3!$B$2:$E$312,2,FALSE) -> B001-060 | D20: =VLOOKUP(B20,Sheet3!$B$2:$E$312,3,) -> bahan baku | E20: =VLOOKUP(B20,Sheet3!$B$2:$E$312,4,) -> GR | F20: 31 | G20: sisa | H20: puput | I20: v
B21: Chicken Bacon | C21: =VLOOKUP(B21,Sheet3!$B$2:$E$312,2,FALSE) -> B001-023 | D21: =VLOOKUP(B21,Sheet3!$B$2:$E$312,3,) -> bahan baku | E21: =VLOOKUP(B21,Sheet3!$B$2:$E$312,4,) -> GR | F21: 236 | G21: discard | H21: puput | I21: v
A22: 46086 | B22: Bawang Bombay | C22: =VLOOKUP(B22,Sheet3!$B$2:$E$312,2,FALSE) -> B001-006 | D22: =VLOOKUP(B22,Sheet3!$B$2:$E$312,3,) -> bahan baku | E22: =VLOOKUP(B22,Sheet3!$B$2:$E$312,4,) -> GR | F22: 9 | G22: tdk terpakai | H22: dendi | I22: v
B23: Cabai Merah Keriting | C23: =VLOOKUP(B23,Sheet3!$B$2:$E$312,2,FALSE) -> B001-017 | D23: =VLOOKUP(B23,Sheet3!$B$2:$E$312,3,) -> bahan baku | E23: =VLOOKUP(B23,Sheet3!$B$2:$E$312,4,) -> GR | F23: 57 | G23: tdk terpakai | H23: dendi | I23: v
B24: Beras 25KG | C24: =VLOOKUP(B24,Sheet3!$B$2:$E$312,2,FALSE) -> B001-008 | D24: =VLOOKUP(B24,Sheet3!$B$2:$E$312,3,) -> bahan baku | E24: =VLOOKUP(B24,Sheet3!$B$2:$E$312,4,) -> GR | F24: =2187 -> 2187 | G24: sisa nasi | H24: neza | I24: x (2187)
B25: Minyak Makan | C25: =VLOOKUP(B25,Sheet3!$B$2:$E$312,2,FALSE) -> B001-056 | D25: =VLOOKUP(B25,Sheet3!$B$2:$E$312,3,) -> bahan baku | E25: =VLOOKUP(B25,Sheet3!$B$2:$E$312,4,) -> ML | F25: 22 | G25: sisa nasi | H25: neza | I25: v
B26: SCRAMBLED EGG | C26: =VLOOKUP(B26,Sheet3!$B$2:$E$312,2,FALSE) -> S001-002 | D26: =VLOOKUP(B26,Sheet3!$B$2:$E$312,3,) -> barang jadi | E26: =VLOOKUP(B26,Sheet3!$B$2:$E$312,4,) -> PORSI | F26: 3 | G26: sisa | H26: neza | I26: v
B27: Bawang Bombay | C27: =VLOOKUP(B27,Sheet3!$B$2:$E$312,2,FALSE) -> B001-006 | D27: =VLOOKUP(B27,Sheet3!$B$2:$E$312,3,) -> bahan baku | E27: =VLOOKUP(B27,Sheet3!$B$2:$E$312,4,) -> GR | F27: 9 | G27: tdk terpakai | H27: puput | I27: v
B28: Pisang | C28: =VLOOKUP(B28,Sheet3!$B$2:$E$312,2,FALSE) -> B001-064 | D28: =VLOOKUP(B28,Sheet3!$B$2:$E$312,3,) -> bahan baku | E28: =VLOOKUP(B28,Sheet3!$B$2:$E$312,4,) -> GR | F28: 93 | G28: tdk terpakai | H28: puput | I28: v
B29: SELADA / LETTUCE | C29: =VLOOKUP(B29,Sheet3!$B$2:$E$312,2,FALSE) -> B001-125 | D29: =VLOOKUP(B29,Sheet3!$B$2:$E$312,3,) -> bahan baku | E29: =VLOOKUP(B29,Sheet3!$B$2:$E$312,4,) -> GR | F29: 60 | G29: busuk | H29: puput | I29: v
B30: WIP GREEN TEA BASE | C30: =VLOOKUP(B30,Sheet3!$B$2:$E$312,2,FALSE) -> P004-023 | D30: =VLOOKUP(B30,Sheet3!$B$2:$E$312,3,) -> barang jadi & bahan baku | E30: =VLOOKUP(B30,Sheet3!$B$2:$E$312,4,) -> CC | F30: 505 | G30: sisa | H30: manda | I30: v
B31: WIP RED TEA BASE | C31: =VLOOKUP(B31,Sheet3!$B$2:$E$312,2,FALSE) -> P004-022 | D31: =VLOOKUP(B31,Sheet3!$B$2:$E$312,3,) -> barang jadi & bahan baku | E31: =VLOOKUP(B31,Sheet3!$B$2:$E$312,4,) -> CC | F31: 537 | G31: sisa | H31: manda | I31: v
